ERROR 2025-05-19 16:38:21,826 log Internal Server Error: /api/v1/registration/
Traceback (most recent call last):
  File "/Users/sergeizeliabovskii/Documents/python_ptojects/DjangoProject/.venv/lib/python3.13/site-packages/django/db/backends/utils.py", line 103, in _execute
    return self.cursor.execute(sql)
           ~~~~~~~~~~~~~~~~~~~^^^^^
psycopg2.errors.NoActiveSqlTransaction: SAVEPOINT can only be used in transaction blocks


The above exception was the direct cause of the following exception:

Traceback (most recent call last):
  File "/Users/sergeizeliabovskii/Documents/python_ptojects/DjangoProject/.venv/lib/python3.13/site-packages/django/core/handlers/exception.py", line 55, in inner
    response = get_response(request)
  File "/Users/sergeizeliabovskii/Documents/python_ptojects/DjangoProject/.venv/lib/python3.13/site-packages/django/core/handlers/base.py", line 197, in _get_response
    response = wrapped_callback(request, *callback_args, **callback_kwargs)
  File "/Users/sergeizeliabovskii/Documents/python_ptojects/DjangoProject/.venv/lib/python3.13/site-packages/django/views/decorators/csrf.py", line 65, in _view_wrapper
    return view_func(request, *args, **kwargs)
  File "/Users/sergeizeliabovskii/Documents/python_ptojects/DjangoProject/.venv/lib/python3.13/site-packages/django/views/generic/base.py", line 104, in view
    return self.dispatch(request, *args, **kwargs)
           ~~~~~~~~~~~~~^^^^^^^^^^^^^^^^^^^^^^^^^^
  File "/Users/sergeizeliabovskii/Documents/python_ptojects/DjangoProject/.venv/lib/python3.13/site-packages/rest_framework/views.py", line 515, in dispatch
    response = self.handle_exception(exc)
  File "/Users/sergeizeliabovskii/Documents/python_ptojects/DjangoProject/.venv/lib/python3.13/site-packages/rest_framework/views.py", line 475, in handle_exception
    self.raise_uncaught_exception(exc)
    ~~~~~~~~~~~~~~~~~~~~~~~~~~~~~^^^^^
  File "/Users/sergeizeliabovskii/Documents/python_ptojects/DjangoProject/.venv/lib/python3.13/site-packages/rest_framework/views.py", line 486, in raise_uncaught_exception
    raise exc
  File "/Users/sergeizeliabovskii/Documents/python_ptojects/DjangoProject/.venv/lib/python3.13/site-packages/rest_framework/views.py", line 512, in dispatch
    response = handler(request, *args, **kwargs)
  File "/Users/sergeizeliabovskii/Documents/python_ptojects/DjangoProject/.venv/lib/python3.13/site-packages/rest_framework/decorators.py", line 50, in handler
    return func(*args, **kwargs)
  File "/Library/Frameworks/Python.framework/Versions/3.13/lib/python3.13/contextlib.py", line 84, in inner
    with self._recreate_cm():
         ~~~~~~~~~~~~~~~~~^^
  File "/Users/sergeizeliabovskii/Documents/python_ptojects/DjangoProject/.venv/lib/python3.13/site-packages/django/db/transaction.py", line 211, in __enter__
    sid = connection.savepoint()
  File "/Users/sergeizeliabovskii/Documents/python_ptojects/DjangoProject/.venv/lib/python3.13/site-packages/django/utils/asyncio.py", line 26, in inner
    return func(*args, **kwargs)
  File "/Users/sergeizeliabovskii/Documents/python_ptojects/DjangoProject/.venv/lib/python3.13/site-packages/django/db/backends/base/base.py", line 400, in savepoint
    self._savepoint(sid)
    ~~~~~~~~~~~~~~~^^^^^
  File "/Users/sergeizeliabovskii/Documents/python_ptojects/DjangoProject/.venv/lib/python3.13/site-packages/django/db/backends/base/base.py", line 367, in _savepoint
    cursor.execute(self.ops.savepoint_create_sql(sid))
    ~~~~~~~~~~~~~~^^^^^^^^^^^^^^^^^^^^^^^^^^^^^^^^^^^^
  File "/Users/sergeizeliabovskii/Documents/python_ptojects/DjangoProject/.venv/lib/python3.13/site-packages/django/db/backends/utils.py", line 79, in execute
    return self._execute_with_wrappers(
           ~~~~~~~~~~~~~~~~~~~~~~~~~~~^
        sql, params, many=False, executor=self._execute
        ^^^^^^^^^^^^^^^^^^^^^^^^^^^^^^^^^^^^^^^^^^^^^^^
    )
    ^
  File "/Users/sergeizeliabovskii/Documents/python_ptojects/DjangoProject/.venv/lib/python3.13/site-packages/django/db/backends/utils.py", line 92, in _execute_with_wrappers
    return executor(sql, params, many, context)
  File "/Users/sergeizeliabovskii/Documents/python_ptojects/DjangoProject/.venv/lib/python3.13/site-packages/django/db/backends/utils.py", line 100, in _execute
    with self.db.wrap_database_errors:
         ^^^^^^^^^^^^^^^^^^^^^^^^^^^^
  File "/Users/sergeizeliabovskii/Documents/python_ptojects/DjangoProject/.venv/lib/python3.13/site-packages/django/db/utils.py", line 91, in __exit__
    raise dj_exc_value.with_traceback(traceback) from exc_value
  File "/Users/sergeizeliabovskii/Documents/python_ptojects/DjangoProject/.venv/lib/python3.13/site-packages/django/db/backends/utils.py", line 103, in _execute
    return self.cursor.execute(sql)
           ~~~~~~~~~~~~~~~~~~~^^^^^
django.db.utils.InternalError: SAVEPOINT can only be used in transaction blocks

ERROR 2025-05-19 16:38:22,193 log Internal Server Error: /api/v1/registration/
Traceback (most recent call last):
  File "/Users/sergeizeliabovskii/Documents/python_ptojects/DjangoProject/.venv/lib/python3.13/site-packages/django/db/backends/utils.py", line 103, in _execute
    return self.cursor.execute(sql)
           ~~~~~~~~~~~~~~~~~~~^^^^^
psycopg2.errors.NoActiveSqlTransaction: SAVEPOINT can only be used in transaction blocks


The above exception was the direct cause of the following exception:

Traceback (most recent call last):
  File "/Users/sergeizeliabovskii/Documents/python_ptojects/DjangoProject/.venv/lib/python3.13/site-packages/django/core/handlers/exception.py", line 55, in inner
    response = get_response(request)
  File "/Users/sergeizeliabovskii/Documents/python_ptojects/DjangoProject/.venv/lib/python3.13/site-packages/django/core/handlers/base.py", line 197, in _get_response
    response = wrapped_callback(request, *callback_args, **callback_kwargs)
  File "/Users/sergeizeliabovskii/Documents/python_ptojects/DjangoProject/.venv/lib/python3.13/site-packages/django/views/decorators/csrf.py", line 65, in _view_wrapper
    return view_func(request, *args, **kwargs)
  File "/Users/sergeizeliabovskii/Documents/python_ptojects/DjangoProject/.venv/lib/python3.13/site-packages/django/views/generic/base.py", line 104, in view
    return self.dispatch(request, *args, **kwargs)
           ~~~~~~~~~~~~~^^^^^^^^^^^^^^^^^^^^^^^^^^
  File "/Users/sergeizeliabovskii/Documents/python_ptojects/DjangoProject/.venv/lib/python3.13/site-packages/rest_framework/views.py", line 515, in dispatch
    response = self.handle_exception(exc)
  File "/Users/sergeizeliabovskii/Documents/python_ptojects/DjangoProject/.venv/lib/python3.13/site-packages/rest_framework/views.py", line 475, in handle_exception
    self.raise_uncaught_exception(exc)
    ~~~~~~~~~~~~~~~~~~~~~~~~~~~~~^^^^^
  File "/Users/sergeizeliabovskii/Documents/python_ptojects/DjangoProject/.venv/lib/python3.13/site-packages/rest_framework/views.py", line 486, in raise_uncaught_exception
    raise exc
  File "/Users/sergeizeliabovskii/Documents/python_ptojects/DjangoProject/.venv/lib/python3.13/site-packages/rest_framework/views.py", line 512, in dispatch
    response = handler(request, *args, **kwargs)
  File "/Users/sergeizeliabovskii/Documents/python_ptojects/DjangoProject/.venv/lib/python3.13/site-packages/rest_framework/decorators.py", line 50, in handler
    return func(*args, **kwargs)
  File "/Library/Frameworks/Python.framework/Versions/3.13/lib/python3.13/contextlib.py", line 84, in inner
    with self._recreate_cm():
         ~~~~~~~~~~~~~~~~~^^
  File "/Users/sergeizeliabovskii/Documents/python_ptojects/DjangoProject/.venv/lib/python3.13/site-packages/django/db/transaction.py", line 211, in __enter__
    sid = connection.savepoint()
  File "/Users/sergeizeliabovskii/Documents/python_ptojects/DjangoProject/.venv/lib/python3.13/site-packages/django/utils/asyncio.py", line 26, in inner
    return func(*args, **kwargs)
  File "/Users/sergeizeliabovskii/Documents/python_ptojects/DjangoProject/.venv/lib/python3.13/site-packages/django/db/backends/base/base.py", line 400, in savepoint
    self._savepoint(sid)
    ~~~~~~~~~~~~~~~^^^^^
  File "/Users/sergeizeliabovskii/Documents/python_ptojects/DjangoProject/.venv/lib/python3.13/site-packages/django/db/backends/base/base.py", line 367, in _savepoint
    cursor.execute(self.ops.savepoint_create_sql(sid))
    ~~~~~~~~~~~~~~^^^^^^^^^^^^^^^^^^^^^^^^^^^^^^^^^^^^
  File "/Users/sergeizeliabovskii/Documents/python_ptojects/DjangoProject/.venv/lib/python3.13/site-packages/django/db/backends/utils.py", line 79, in execute
    return self._execute_with_wrappers(
           ~~~~~~~~~~~~~~~~~~~~~~~~~~~^
        sql, params, many=False, executor=self._execute
        ^^^^^^^^^^^^^^^^^^^^^^^^^^^^^^^^^^^^^^^^^^^^^^^
    )
    ^
  File "/Users/sergeizeliabovskii/Documents/python_ptojects/DjangoProject/.venv/lib/python3.13/site-packages/django/db/backends/utils.py", line 92, in _execute_with_wrappers
    return executor(sql, params, many, context)
  File "/Users/sergeizeliabovskii/Documents/python_ptojects/DjangoProject/.venv/lib/python3.13/site-packages/django/db/backends/utils.py", line 100, in _execute
    with self.db.wrap_database_errors:
         ^^^^^^^^^^^^^^^^^^^^^^^^^^^^
  File "/Users/sergeizeliabovskii/Documents/python_ptojects/DjangoProject/.venv/lib/python3.13/site-packages/django/db/utils.py", line 91, in __exit__
    raise dj_exc_value.with_traceback(traceback) from exc_value
  File "/Users/sergeizeliabovskii/Documents/python_ptojects/DjangoProject/.venv/lib/python3.13/site-packages/django/db/backends/utils.py", line 103, in _execute
    return self.cursor.execute(sql)
           ~~~~~~~~~~~~~~~~~~~^^^^^
django.db.utils.InternalError: SAVEPOINT can only be used in transaction blocks

ERROR 2025-05-19 17:17:27,917 log Internal Server Error: /api/v1/edit_userinfo/1/
Traceback (most recent call last):
  File "/Users/sergeizeliabovskii/Documents/python_ptojects/DjangoProject/.venv/lib/python3.13/site-packages/django/core/handlers/exception.py", line 55, in inner
    response = get_response(request)
  File "/Users/sergeizeliabovskii/Documents/python_ptojects/DjangoProject/.venv/lib/python3.13/site-packages/django/core/handlers/base.py", line 197, in _get_response
    response = wrapped_callback(request, *callback_args, **callback_kwargs)
  File "/Users/sergeizeliabovskii/Documents/python_ptojects/DjangoProject/.venv/lib/python3.13/site-packages/django/views/decorators/csrf.py", line 65, in _view_wrapper
    return view_func(request, *args, **kwargs)
  File "/Users/sergeizeliabovskii/Documents/python_ptojects/DjangoProject/.venv/lib/python3.13/site-packages/django/views/generic/base.py", line 104, in view
    return self.dispatch(request, *args, **kwargs)
           ~~~~~~~~~~~~~^^^^^^^^^^^^^^^^^^^^^^^^^^
  File "/Users/sergeizeliabovskii/Documents/python_ptojects/DjangoProject/.venv/lib/python3.13/site-packages/rest_framework/views.py", line 515, in dispatch
    response = self.handle_exception(exc)
  File "/Users/sergeizeliabovskii/Documents/python_ptojects/DjangoProject/.venv/lib/python3.13/site-packages/rest_framework/views.py", line 475, in handle_exception
    self.raise_uncaught_exception(exc)
    ~~~~~~~~~~~~~~~~~~~~~~~~~~~~~^^^^^
  File "/Users/sergeizeliabovskii/Documents/python_ptojects/DjangoProject/.venv/lib/python3.13/site-packages/rest_framework/views.py", line 486, in raise_uncaught_exception
    raise exc
  File "/Users/sergeizeliabovskii/Documents/python_ptojects/DjangoProject/.venv/lib/python3.13/site-packages/rest_framework/views.py", line 512, in dispatch
    response = handler(request, *args, **kwargs)
  File "/Users/sergeizeliabovskii/Documents/python_ptojects/DjangoProject/.venv/lib/python3.13/site-packages/rest_framework/decorators.py", line 50, in handler
    return func(*args, **kwargs)
  File "/Library/Frameworks/Python.framework/Versions/3.13/lib/python3.13/contextlib.py", line 85, in inner
    return func(*args, **kwds)
TypeError: edit_userinfo() got an unexpected keyword argument 'user_id'
ERROR 2025-05-20 17:24:20,253 log Internal Server Error: /api/v1/login
Traceback (most recent call last):
  File "/Users/sergeizeliabovskii/Documents/python_ptojects/DjangoProject/.venv/lib/python3.13/site-packages/django/core/handlers/exception.py", line 55, in inner
    response = get_response(request)
  File "/Users/sergeizeliabovskii/Documents/python_ptojects/DjangoProject/.venv/lib/python3.13/site-packages/django/utils/deprecation.py", line 122, in __call__
    response = self.process_response(request, response)
  File "/Users/sergeizeliabovskii/Documents/python_ptojects/DjangoProject/.venv/lib/python3.13/site-packages/django/middleware/common.py", line 108, in process_response
    return self.response_redirect_class(self.get_full_path_with_slash(request))
                                        ~~~~~~~~~~~~~~~~~~~~~~~~~~~~~^^^^^^^^^
  File "/Users/sergeizeliabovskii/Documents/python_ptojects/DjangoProject/.venv/lib/python3.13/site-packages/django/middleware/common.py", line 87, in get_full_path_with_slash
    raise RuntimeError(
    ...<9 lines>...
    )
RuntimeError: You called this URL via POST, but the URL doesn't end in a slash and you have APPEND_SLASH set. Django can't redirect to the slash URL while maintaining POST data. Change your form to point to 127.0.0.1:8000/api/v1/login/ (note the trailing slash), or set APPEND_SLASH=False in your Django settings.
ERROR 2025-05-20 17:24:20,258 basehttp "POST /api/v1/login HTTP/1.1" 500 65622
ERROR 2025-05-20 23:14:52,225 log Internal Server Error: /api/v1/edit/user/1
Traceback (most recent call last):
  File "/Users/sergeizeliabovskii/Documents/python_ptojects/DjangoProject/.venv/lib/python3.13/site-packages/django/core/handlers/exception.py", line 55, in inner
    response = get_response(request)
  File "/Users/sergeizeliabovskii/Documents/python_ptojects/DjangoProject/.venv/lib/python3.13/site-packages/django/utils/deprecation.py", line 122, in __call__
    response = self.process_response(request, response)
  File "/Users/sergeizeliabovskii/Documents/python_ptojects/DjangoProject/.venv/lib/python3.13/site-packages/django/middleware/common.py", line 108, in process_response
    return self.response_redirect_class(self.get_full_path_with_slash(request))
                                        ~~~~~~~~~~~~~~~~~~~~~~~~~~~~~^^^^^^^^^
  File "/Users/sergeizeliabovskii/Documents/python_ptojects/DjangoProject/.venv/lib/python3.13/site-packages/django/middleware/common.py", line 87, in get_full_path_with_slash
    raise RuntimeError(
    ...<9 lines>...
    )
RuntimeError: You called this URL via POST, but the URL doesn't end in a slash and you have APPEND_SLASH set. Django can't redirect to the slash URL while maintaining POST data. Change your form to point to 127.0.0.1:8000/api/v1/edit/user/1/ (note the trailing slash), or set APPEND_SLASH=False in your Django settings.
ERROR 2025-05-20 23:14:52,228 basehttp "POST /api/v1/edit/user/1 HTTP/1.1" 500 66315
ERROR 2025-05-21 01:15:02,602 log Internal Server Error: /api/v1/user/edit/1
Traceback (most recent call last):
  File "/Users/sergeizeliabovskii/Documents/python_ptojects/DjangoProject/.venv/lib/python3.13/site-packages/django/core/handlers/exception.py", line 55, in inner
    response = get_response(request)
  File "/Users/sergeizeliabovskii/Documents/python_ptojects/DjangoProject/.venv/lib/python3.13/site-packages/django/utils/deprecation.py", line 122, in __call__
    response = self.process_response(request, response)
  File "/Users/sergeizeliabovskii/Documents/python_ptojects/DjangoProject/.venv/lib/python3.13/site-packages/django/middleware/common.py", line 108, in process_response
    return self.response_redirect_class(self.get_full_path_with_slash(request))
                                        ~~~~~~~~~~~~~~~~~~~~~~~~~~~~~^^^^^^^^^
  File "/Users/sergeizeliabovskii/Documents/python_ptojects/DjangoProject/.venv/lib/python3.13/site-packages/django/middleware/common.py", line 87, in get_full_path_with_slash
    raise RuntimeError(
    ...<9 lines>...
    )
RuntimeError: You called this URL via PATCH, but the URL doesn't end in a slash and you have APPEND_SLASH set. Django can't redirect to the slash URL while maintaining PATCH data. Change your form to point to 127.0.0.1:8000/api/v1/user/edit/1/ (note the trailing slash), or set APPEND_SLASH=False in your Django settings.
ERROR 2025-05-21 01:15:02,606 basehttp "PATCH /api/v1/user/edit/1 HTTP/1.1" 500 66330
ERROR 2025-05-21 01:19:36,643 log Internal Server Error: /api/v1/user/edit/1/
ERROR 2025-05-21 01:19:36,644 basehttp "PATCH /api/v1/user/edit/1/ HTTP/1.1" 500 92
ERROR 2025-05-21 02:22:59,733 log Internal Server Error: /api/v1/registration/
Traceback (most recent call last):
  File "/Users/sergeizeliabovskii/Documents/python_ptojects/DjangoProject/.venv/lib/python3.13/site-packages/django/core/handlers/exception.py", line 55, in inner
    response = get_response(request)
  File "/Users/sergeizeliabovskii/Documents/python_ptojects/DjangoProject/.venv/lib/python3.13/site-packages/django/core/handlers/base.py", line 197, in _get_response
    response = wrapped_callback(request, *callback_args, **callback_kwargs)
  File "/Users/sergeizeliabovskii/Documents/python_ptojects/DjangoProject/.venv/lib/python3.13/site-packages/django/views/decorators/csrf.py", line 65, in _view_wrapper
    return view_func(request, *args, **kwargs)
  File "/Users/sergeizeliabovskii/Documents/python_ptojects/DjangoProject/.venv/lib/python3.13/site-packages/django/views/generic/base.py", line 104, in view
    return self.dispatch(request, *args, **kwargs)
           ~~~~~~~~~~~~~^^^^^^^^^^^^^^^^^^^^^^^^^^
  File "/Users/sergeizeliabovskii/Documents/python_ptojects/DjangoProject/.venv/lib/python3.13/site-packages/rest_framework/views.py", line 515, in dispatch
    response = self.handle_exception(exc)
  File "/Users/sergeizeliabovskii/Documents/python_ptojects/DjangoProject/.venv/lib/python3.13/site-packages/rest_framework/views.py", line 475, in handle_exception
    self.raise_uncaught_exception(exc)
    ~~~~~~~~~~~~~~~~~~~~~~~~~~~~~^^^^^
  File "/Users/sergeizeliabovskii/Documents/python_ptojects/DjangoProject/.venv/lib/python3.13/site-packages/rest_framework/views.py", line 486, in raise_uncaught_exception
    raise exc
  File "/Users/sergeizeliabovskii/Documents/python_ptojects/DjangoProject/.venv/lib/python3.13/site-packages/rest_framework/views.py", line 512, in dispatch
    response = handler(request, *args, **kwargs)
  File "/Users/sergeizeliabovskii/Documents/python_ptojects/DjangoProject/.venv/lib/python3.13/site-packages/rest_framework/decorators.py", line 50, in handler
    return func(*args, **kwargs)
  File "/Library/Frameworks/Python.framework/Versions/3.13/lib/python3.13/contextlib.py", line 85, in inner
    return func(*args, **kwds)
  File "/Users/sergeizeliabovskii/Documents/python_ptojects/DjangoProject/main/views.py", line 21, in registration
    serializer.save()
    ~~~~~~~~~~~~~~~^^
  File "/Users/sergeizeliabovskii/Documents/python_ptojects/DjangoProject/.venv/lib/python3.13/site-packages/rest_framework/serializers.py", line 210, in save
    self.instance = self.create(validated_data)
                    ~~~~~~~~~~~^^^^^^^^^^^^^^^^
  File "/Users/sergeizeliabovskii/Documents/python_ptojects/DjangoProject/main/serializers.py", line 16, in create
    user = User.objects.create_user(
        username=validated_data['username'],
        email=validated_data.get('email'),
        password=validated_data['password']
    )
  File "/Users/sergeizeliabovskii/Documents/python_ptojects/DjangoProject/.venv/lib/python3.13/site-packages/django/contrib/auth/models.py", line 175, in create_user
    return self._create_user(username, email, password, **extra_fields)
           ~~~~~~~~~~~~~~~~~^^^^^^^^^^^^^^^^^^^^^^^^^^^^^^^^^^^^^^^^^^^
  File "/Users/sergeizeliabovskii/Documents/python_ptojects/DjangoProject/.venv/lib/python3.13/site-packages/django/contrib/auth/models.py", line 163, in _create_user
    user.save(using=self._db)
    ~~~~~~~~~^^^^^^^^^^^^^^^^
  File "/Users/sergeizeliabovskii/Documents/python_ptojects/DjangoProject/.venv/lib/python3.13/site-packages/django/contrib/auth/base_user.py", line 65, in save
    super().save(*args, **kwargs)
    ~~~~~~~~~~~~^^^^^^^^^^^^^^^^^
  File "/Users/sergeizeliabovskii/Documents/python_ptojects/DjangoProject/.venv/lib/python3.13/site-packages/django/db/models/base.py", line 902, in save
    self.save_base(
    ~~~~~~~~~~~~~~^
        using=using,
        ^^^^^^^^^^^^
    ...<2 lines>...
        update_fields=update_fields,
        ^^^^^^^^^^^^^^^^^^^^^^^^^^^^
    )
    ^
  File "/Users/sergeizeliabovskii/Documents/python_ptojects/DjangoProject/.venv/lib/python3.13/site-packages/django/db/models/base.py", line 1023, in save_base
    post_save.send(
    ~~~~~~~~~~~~~~^
        sender=origin,
        ^^^^^^^^^^^^^^
    ...<4 lines>...
        using=using,
        ^^^^^^^^^^^^
    )
    ^
  File "/Users/sergeizeliabovskii/Documents/python_ptojects/DjangoProject/.venv/lib/python3.13/site-packages/django/dispatch/dispatcher.py", line 189, in send
    response = receiver(signal=self, sender=sender, **named)
  File "/Users/sergeizeliabovskii/Documents/python_ptojects/DjangoProject/main/signals.py", line 33, in create_contact_card
    emergency_contact = EmergencyContact.objects.create(user_id=instance.id)
  File "/Users/sergeizeliabovskii/Documents/python_ptojects/DjangoProject/.venv/lib/python3.13/site-packages/django/db/models/manager.py", line 87, in manager_method
    return getattr(self.get_queryset(), name)(*args, **kwargs)
           ~~~~~~~~~~~~~~~~~~~~~~~~~~~~~~~~~~^^^^^^^^^^^^^^^^^
  File "/Users/sergeizeliabovskii/Documents/python_ptojects/DjangoProject/.venv/lib/python3.13/site-packages/django/db/models/query.py", line 661, in create
    obj = self.model(**kwargs)
  File "/Users/sergeizeliabovskii/Documents/python_ptojects/DjangoProject/.venv/lib/python3.13/site-packages/django/db/models/base.py", line 569, in __init__
    raise TypeError(
    ...<2 lines>...
    )
TypeError: EmergencyContact() got unexpected keyword arguments: 'user_id'
ERROR 2025-05-21 02:22:59,800 basehttp "POST /api/v1/registration/ HTTP/1.1" 500 154183
ERROR 2025-05-21 02:25:29,230 log Internal Server Error: /api/v1/registration/
Traceback (most recent call last):
  File "/Users/sergeizeliabovskii/Documents/python_ptojects/DjangoProject/.venv/lib/python3.13/site-packages/django/core/handlers/exception.py", line 55, in inner
    response = get_response(request)
  File "/Users/sergeizeliabovskii/Documents/python_ptojects/DjangoProject/.venv/lib/python3.13/site-packages/django/core/handlers/base.py", line 197, in _get_response
    response = wrapped_callback(request, *callback_args, **callback_kwargs)
  File "/Users/sergeizeliabovskii/Documents/python_ptojects/DjangoProject/.venv/lib/python3.13/site-packages/django/views/decorators/csrf.py", line 65, in _view_wrapper
    return view_func(request, *args, **kwargs)
  File "/Users/sergeizeliabovskii/Documents/python_ptojects/DjangoProject/.venv/lib/python3.13/site-packages/django/views/generic/base.py", line 104, in view
    return self.dispatch(request, *args, **kwargs)
           ~~~~~~~~~~~~~^^^^^^^^^^^^^^^^^^^^^^^^^^
  File "/Users/sergeizeliabovskii/Documents/python_ptojects/DjangoProject/.venv/lib/python3.13/site-packages/rest_framework/views.py", line 515, in dispatch
    response = self.handle_exception(exc)
  File "/Users/sergeizeliabovskii/Documents/python_ptojects/DjangoProject/.venv/lib/python3.13/site-packages/rest_framework/views.py", line 475, in handle_exception
    self.raise_uncaught_exception(exc)
    ~~~~~~~~~~~~~~~~~~~~~~~~~~~~~^^^^^
  File "/Users/sergeizeliabovskii/Documents/python_ptojects/DjangoProject/.venv/lib/python3.13/site-packages/rest_framework/views.py", line 486, in raise_uncaught_exception
    raise exc
  File "/Users/sergeizeliabovskii/Documents/python_ptojects/DjangoProject/.venv/lib/python3.13/site-packages/rest_framework/views.py", line 512, in dispatch
    response = handler(request, *args, **kwargs)
  File "/Users/sergeizeliabovskii/Documents/python_ptojects/DjangoProject/.venv/lib/python3.13/site-packages/rest_framework/decorators.py", line 50, in handler
    return func(*args, **kwargs)
  File "/Library/Frameworks/Python.framework/Versions/3.13/lib/python3.13/contextlib.py", line 85, in inner
    return func(*args, **kwds)
  File "/Users/sergeizeliabovskii/Documents/python_ptojects/DjangoProject/main/views.py", line 21, in registration
    serializer.save()
    ~~~~~~~~~~~~~~~^^
  File "/Users/sergeizeliabovskii/Documents/python_ptojects/DjangoProject/.venv/lib/python3.13/site-packages/rest_framework/serializers.py", line 210, in save
    self.instance = self.create(validated_data)
                    ~~~~~~~~~~~^^^^^^^^^^^^^^^^
  File "/Users/sergeizeliabovskii/Documents/python_ptojects/DjangoProject/main/serializers.py", line 16, in create
    user = User.objects.create_user(
        username=validated_data['username'],
        email=validated_data.get('email'),
        password=validated_data['password']
    )
  File "/Users/sergeizeliabovskii/Documents/python_ptojects/DjangoProject/.venv/lib/python3.13/site-packages/django/contrib/auth/models.py", line 175, in create_user
    return self._create_user(username, email, password, **extra_fields)
           ~~~~~~~~~~~~~~~~~^^^^^^^^^^^^^^^^^^^^^^^^^^^^^^^^^^^^^^^^^^^
  File "/Users/sergeizeliabovskii/Documents/python_ptojects/DjangoProject/.venv/lib/python3.13/site-packages/django/contrib/auth/models.py", line 163, in _create_user
    user.save(using=self._db)
    ~~~~~~~~~^^^^^^^^^^^^^^^^
  File "/Users/sergeizeliabovskii/Documents/python_ptojects/DjangoProject/.venv/lib/python3.13/site-packages/django/contrib/auth/base_user.py", line 65, in save
    super().save(*args, **kwargs)
    ~~~~~~~~~~~~^^^^^^^^^^^^^^^^^
  File "/Users/sergeizeliabovskii/Documents/python_ptojects/DjangoProject/.venv/lib/python3.13/site-packages/django/db/models/base.py", line 902, in save
    self.save_base(
    ~~~~~~~~~~~~~~^
        using=using,
        ^^^^^^^^^^^^
    ...<2 lines>...
        update_fields=update_fields,
        ^^^^^^^^^^^^^^^^^^^^^^^^^^^^
    )
    ^
  File "/Users/sergeizeliabovskii/Documents/python_ptojects/DjangoProject/.venv/lib/python3.13/site-packages/django/db/models/base.py", line 1023, in save_base
    post_save.send(
    ~~~~~~~~~~~~~~^
        sender=origin,
        ^^^^^^^^^^^^^^
    ...<4 lines>...
        using=using,
        ^^^^^^^^^^^^
    )
    ^
  File "/Users/sergeizeliabovskii/Documents/python_ptojects/DjangoProject/.venv/lib/python3.13/site-packages/django/dispatch/dispatcher.py", line 189, in send
    response = receiver(signal=self, sender=sender, **named)
  File "/Users/sergeizeliabovskii/Documents/python_ptojects/DjangoProject/main/signals.py", line 33, in create_contact_card
    emergency_contact = EmergencyContact.objects.create(user_id=instance.id)
  File "/Users/sergeizeliabovskii/Documents/python_ptojects/DjangoProject/.venv/lib/python3.13/site-packages/django/db/models/manager.py", line 87, in manager_method
    return getattr(self.get_queryset(), name)(*args, **kwargs)
           ~~~~~~~~~~~~~~~~~~~~~~~~~~~~~~~~~~^^^^^^^^^^^^^^^^^
  File "/Users/sergeizeliabovskii/Documents/python_ptojects/DjangoProject/.venv/lib/python3.13/site-packages/django/db/models/query.py", line 661, in create
    obj = self.model(**kwargs)
  File "/Users/sergeizeliabovskii/Documents/python_ptojects/DjangoProject/.venv/lib/python3.13/site-packages/django/db/models/base.py", line 569, in __init__
    raise TypeError(
    ...<2 lines>...
    )
TypeError: EmergencyContact() got unexpected keyword arguments: 'user_id'
ERROR 2025-05-21 02:25:29,250 basehttp "POST /api/v1/registration/ HTTP/1.1" 500 154180
ERROR 2025-05-21 02:26:38,558 log Internal Server Error: /api/v1/registration/
Traceback (most recent call last):
  File "/Users/sergeizeliabovskii/Documents/python_ptojects/DjangoProject/.venv/lib/python3.13/site-packages/django/core/handlers/exception.py", line 55, in inner
    response = get_response(request)
  File "/Users/sergeizeliabovskii/Documents/python_ptojects/DjangoProject/.venv/lib/python3.13/site-packages/django/core/handlers/base.py", line 197, in _get_response
    response = wrapped_callback(request, *callback_args, **callback_kwargs)
  File "/Users/sergeizeliabovskii/Documents/python_ptojects/DjangoProject/.venv/lib/python3.13/site-packages/django/views/decorators/csrf.py", line 65, in _view_wrapper
    return view_func(request, *args, **kwargs)
  File "/Users/sergeizeliabovskii/Documents/python_ptojects/DjangoProject/.venv/lib/python3.13/site-packages/django/views/generic/base.py", line 104, in view
    return self.dispatch(request, *args, **kwargs)
           ~~~~~~~~~~~~~^^^^^^^^^^^^^^^^^^^^^^^^^^
  File "/Users/sergeizeliabovskii/Documents/python_ptojects/DjangoProject/.venv/lib/python3.13/site-packages/rest_framework/views.py", line 515, in dispatch
    response = self.handle_exception(exc)
  File "/Users/sergeizeliabovskii/Documents/python_ptojects/DjangoProject/.venv/lib/python3.13/site-packages/rest_framework/views.py", line 475, in handle_exception
    self.raise_uncaught_exception(exc)
    ~~~~~~~~~~~~~~~~~~~~~~~~~~~~~^^^^^
  File "/Users/sergeizeliabovskii/Documents/python_ptojects/DjangoProject/.venv/lib/python3.13/site-packages/rest_framework/views.py", line 486, in raise_uncaught_exception
    raise exc
  File "/Users/sergeizeliabovskii/Documents/python_ptojects/DjangoProject/.venv/lib/python3.13/site-packages/rest_framework/views.py", line 512, in dispatch
    response = handler(request, *args, **kwargs)
  File "/Users/sergeizeliabovskii/Documents/python_ptojects/DjangoProject/.venv/lib/python3.13/site-packages/rest_framework/decorators.py", line 50, in handler
    return func(*args, **kwargs)
  File "/Library/Frameworks/Python.framework/Versions/3.13/lib/python3.13/contextlib.py", line 85, in inner
    return func(*args, **kwds)
  File "/Users/sergeizeliabovskii/Documents/python_ptojects/DjangoProject/main/views.py", line 21, in registration
    serializer.save()
    ~~~~~~~~~~~~~~~^^
  File "/Users/sergeizeliabovskii/Documents/python_ptojects/DjangoProject/.venv/lib/python3.13/site-packages/rest_framework/serializers.py", line 210, in save
    self.instance = self.create(validated_data)
                    ~~~~~~~~~~~^^^^^^^^^^^^^^^^
  File "/Users/sergeizeliabovskii/Documents/python_ptojects/DjangoProject/main/serializers.py", line 16, in create
    user = User.objects.create_user(
        username=validated_data['username'],
        email=validated_data.get('email'),
        password=validated_data['password']
    )
  File "/Users/sergeizeliabovskii/Documents/python_ptojects/DjangoProject/.venv/lib/python3.13/site-packages/django/contrib/auth/models.py", line 175, in create_user
    return self._create_user(username, email, password, **extra_fields)
           ~~~~~~~~~~~~~~~~~^^^^^^^^^^^^^^^^^^^^^^^^^^^^^^^^^^^^^^^^^^^
  File "/Users/sergeizeliabovskii/Documents/python_ptojects/DjangoProject/.venv/lib/python3.13/site-packages/django/contrib/auth/models.py", line 163, in _create_user
    user.save(using=self._db)
    ~~~~~~~~~^^^^^^^^^^^^^^^^
  File "/Users/sergeizeliabovskii/Documents/python_ptojects/DjangoProject/.venv/lib/python3.13/site-packages/django/contrib/auth/base_user.py", line 65, in save
    super().save(*args, **kwargs)
    ~~~~~~~~~~~~^^^^^^^^^^^^^^^^^
  File "/Users/sergeizeliabovskii/Documents/python_ptojects/DjangoProject/.venv/lib/python3.13/site-packages/django/db/models/base.py", line 902, in save
    self.save_base(
    ~~~~~~~~~~~~~~^
        using=using,
        ^^^^^^^^^^^^
    ...<2 lines>...
        update_fields=update_fields,
        ^^^^^^^^^^^^^^^^^^^^^^^^^^^^
    )
    ^
  File "/Users/sergeizeliabovskii/Documents/python_ptojects/DjangoProject/.venv/lib/python3.13/site-packages/django/db/models/base.py", line 1023, in save_base
    post_save.send(
    ~~~~~~~~~~~~~~^
        sender=origin,
        ^^^^^^^^^^^^^^
    ...<4 lines>...
        using=using,
        ^^^^^^^^^^^^
    )
    ^
  File "/Users/sergeizeliabovskii/Documents/python_ptojects/DjangoProject/.venv/lib/python3.13/site-packages/django/dispatch/dispatcher.py", line 189, in send
    response = receiver(signal=self, sender=sender, **named)
  File "/Users/sergeizeliabovskii/Documents/python_ptojects/DjangoProject/main/signals.py", line 33, in create_contact_card
    emergency_contact = EmergencyContact.objects.create(user=instance.id)
  File "/Users/sergeizeliabovskii/Documents/python_ptojects/DjangoProject/.venv/lib/python3.13/site-packages/django/db/models/manager.py", line 87, in manager_method
    return getattr(self.get_queryset(), name)(*args, **kwargs)
           ~~~~~~~~~~~~~~~~~~~~~~~~~~~~~~~~~~^^^^^^^^^^^^^^^^^
  File "/Users/sergeizeliabovskii/Documents/python_ptojects/DjangoProject/.venv/lib/python3.13/site-packages/django/db/models/query.py", line 661, in create
    obj = self.model(**kwargs)
  File "/Users/sergeizeliabovskii/Documents/python_ptojects/DjangoProject/.venv/lib/python3.13/site-packages/django/db/models/base.py", line 569, in __init__
    raise TypeError(
    ...<2 lines>...
    )
TypeError: EmergencyContact() got unexpected keyword arguments: 'user'
ERROR 2025-05-21 02:26:38,586 basehttp "POST /api/v1/registration/ HTTP/1.1" 500 154132
ERROR 2025-05-21 02:28:36,833 log Internal Server Error: /api/v1/registration/
Traceback (most recent call last):
  File "/Users/sergeizeliabovskii/Documents/python_ptojects/DjangoProject/.venv/lib/python3.13/site-packages/django/core/handlers/exception.py", line 55, in inner
    response = get_response(request)
  File "/Users/sergeizeliabovskii/Documents/python_ptojects/DjangoProject/.venv/lib/python3.13/site-packages/django/core/handlers/base.py", line 197, in _get_response
    response = wrapped_callback(request, *callback_args, **callback_kwargs)
  File "/Users/sergeizeliabovskii/Documents/python_ptojects/DjangoProject/.venv/lib/python3.13/site-packages/django/views/decorators/csrf.py", line 65, in _view_wrapper
    return view_func(request, *args, **kwargs)
  File "/Users/sergeizeliabovskii/Documents/python_ptojects/DjangoProject/.venv/lib/python3.13/site-packages/django/views/generic/base.py", line 104, in view
    return self.dispatch(request, *args, **kwargs)
           ~~~~~~~~~~~~~^^^^^^^^^^^^^^^^^^^^^^^^^^
  File "/Users/sergeizeliabovskii/Documents/python_ptojects/DjangoProject/.venv/lib/python3.13/site-packages/rest_framework/views.py", line 515, in dispatch
    response = self.handle_exception(exc)
  File "/Users/sergeizeliabovskii/Documents/python_ptojects/DjangoProject/.venv/lib/python3.13/site-packages/rest_framework/views.py", line 475, in handle_exception
    self.raise_uncaught_exception(exc)
    ~~~~~~~~~~~~~~~~~~~~~~~~~~~~~^^^^^
  File "/Users/sergeizeliabovskii/Documents/python_ptojects/DjangoProject/.venv/lib/python3.13/site-packages/rest_framework/views.py", line 486, in raise_uncaught_exception
    raise exc
  File "/Users/sergeizeliabovskii/Documents/python_ptojects/DjangoProject/.venv/lib/python3.13/site-packages/rest_framework/views.py", line 512, in dispatch
    response = handler(request, *args, **kwargs)
  File "/Users/sergeizeliabovskii/Documents/python_ptojects/DjangoProject/.venv/lib/python3.13/site-packages/rest_framework/decorators.py", line 50, in handler
    return func(*args, **kwargs)
  File "/Library/Frameworks/Python.framework/Versions/3.13/lib/python3.13/contextlib.py", line 85, in inner
    return func(*args, **kwds)
  File "/Users/sergeizeliabovskii/Documents/python_ptojects/DjangoProject/main/views.py", line 21, in registration
    serializer.save()
    ~~~~~~~~~~~~~~~^^
  File "/Users/sergeizeliabovskii/Documents/python_ptojects/DjangoProject/.venv/lib/python3.13/site-packages/rest_framework/serializers.py", line 210, in save
    self.instance = self.create(validated_data)
                    ~~~~~~~~~~~^^^^^^^^^^^^^^^^
  File "/Users/sergeizeliabovskii/Documents/python_ptojects/DjangoProject/main/serializers.py", line 16, in create
    user = User.objects.create_user(
        username=validated_data['username'],
        email=validated_data.get('email'),
        password=validated_data['password']
    )
  File "/Users/sergeizeliabovskii/Documents/python_ptojects/DjangoProject/.venv/lib/python3.13/site-packages/django/contrib/auth/models.py", line 175, in create_user
    return self._create_user(username, email, password, **extra_fields)
           ~~~~~~~~~~~~~~~~~^^^^^^^^^^^^^^^^^^^^^^^^^^^^^^^^^^^^^^^^^^^
  File "/Users/sergeizeliabovskii/Documents/python_ptojects/DjangoProject/.venv/lib/python3.13/site-packages/django/contrib/auth/models.py", line 163, in _create_user
    user.save(using=self._db)
    ~~~~~~~~~^^^^^^^^^^^^^^^^
  File "/Users/sergeizeliabovskii/Documents/python_ptojects/DjangoProject/.venv/lib/python3.13/site-packages/django/contrib/auth/base_user.py", line 65, in save
    super().save(*args, **kwargs)
    ~~~~~~~~~~~~^^^^^^^^^^^^^^^^^
  File "/Users/sergeizeliabovskii/Documents/python_ptojects/DjangoProject/.venv/lib/python3.13/site-packages/django/db/models/base.py", line 902, in save
    self.save_base(
    ~~~~~~~~~~~~~~^
        using=using,
        ^^^^^^^^^^^^
    ...<2 lines>...
        update_fields=update_fields,
        ^^^^^^^^^^^^^^^^^^^^^^^^^^^^
    )
    ^
  File "/Users/sergeizeliabovskii/Documents/python_ptojects/DjangoProject/.venv/lib/python3.13/site-packages/django/db/models/base.py", line 1023, in save_base
    post_save.send(
    ~~~~~~~~~~~~~~^
        sender=origin,
        ^^^^^^^^^^^^^^
    ...<4 lines>...
        using=using,
        ^^^^^^^^^^^^
    )
    ^
  File "/Users/sergeizeliabovskii/Documents/python_ptojects/DjangoProject/.venv/lib/python3.13/site-packages/django/dispatch/dispatcher.py", line 189, in send
    response = receiver(signal=self, sender=sender, **named)
  File "/Users/sergeizeliabovskii/Documents/python_ptojects/DjangoProject/main/signals.py", line 33, in create_contact_card
    emergency_contact = EmergencyContact.objects.create(user=instance.id)
  File "/Users/sergeizeliabovskii/Documents/python_ptojects/DjangoProject/.venv/lib/python3.13/site-packages/django/db/models/manager.py", line 87, in manager_method
    return getattr(self.get_queryset(), name)(*args, **kwargs)
           ~~~~~~~~~~~~~~~~~~~~~~~~~~~~~~~~~~^^^^^^^^^^^^^^^^^
  File "/Users/sergeizeliabovskii/Documents/python_ptojects/DjangoProject/.venv/lib/python3.13/site-packages/django/db/models/query.py", line 661, in create
    obj = self.model(**kwargs)
  File "/Users/sergeizeliabovskii/Documents/python_ptojects/DjangoProject/.venv/lib/python3.13/site-packages/django/db/models/base.py", line 545, in __init__
    _setattr(self, field.name, rel_obj)
    ~~~~~~~~^^^^^^^^^^^^^^^^^^^^^^^^^^^
  File "/Users/sergeizeliabovskii/Documents/python_ptojects/DjangoProject/.venv/lib/python3.13/site-packages/django/db/models/fields/related_descriptors.py", line 391, in __set__
    super().__set__(instance, value)
    ~~~~~~~~~~~~~~~^^^^^^^^^^^^^^^^^
  File "/Users/sergeizeliabovskii/Documents/python_ptojects/DjangoProject/.venv/lib/python3.13/site-packages/django/db/models/fields/related_descriptors.py", line 288, in __set__
    raise ValueError(
    ...<7 lines>...
    )
ValueError: Cannot assign "5": "EmergencyContact.user" must be a "User" instance.
ERROR 2025-05-21 02:28:36,842 basehttp "POST /api/v1/registration/ HTTP/1.1" 500 162626
ERROR 2025-05-21 21:10:00,176 log Internal Server Error: /api/v1/user/edit/6/
ERROR 2025-05-21 21:10:00,177 basehttp "PATCH /api/v1/user/edit/6/ HTTP/1.1" 500 96
ERROR 2025-05-21 22:45:21,907 log Internal Server Error: /api/v1/user/edit/contact/6/
Traceback (most recent call last):
  File "/Users/sergeizeliabovskii/Documents/python_ptojects/DjangoProject/.venv/lib/python3.13/site-packages/django/core/handlers/exception.py", line 55, in inner
    response = get_response(request)
  File "/Users/sergeizeliabovskii/Documents/python_ptojects/DjangoProject/.venv/lib/python3.13/site-packages/django/core/handlers/base.py", line 197, in _get_response
    response = wrapped_callback(request, *callback_args, **callback_kwargs)
  File "/Users/sergeizeliabovskii/Documents/python_ptojects/DjangoProject/.venv/lib/python3.13/site-packages/django/views/decorators/csrf.py", line 65, in _view_wrapper
    return view_func(request, *args, **kwargs)
  File "/Users/sergeizeliabovskii/Documents/python_ptojects/DjangoProject/.venv/lib/python3.13/site-packages/django/views/generic/base.py", line 104, in view
    return self.dispatch(request, *args, **kwargs)
           ~~~~~~~~~~~~~^^^^^^^^^^^^^^^^^^^^^^^^^^
  File "/Users/sergeizeliabovskii/Documents/python_ptojects/DjangoProject/.venv/lib/python3.13/site-packages/rest_framework/views.py", line 515, in dispatch
    response = self.handle_exception(exc)
  File "/Users/sergeizeliabovskii/Documents/python_ptojects/DjangoProject/.venv/lib/python3.13/site-packages/rest_framework/views.py", line 475, in handle_exception
    self.raise_uncaught_exception(exc)
    ~~~~~~~~~~~~~~~~~~~~~~~~~~~~~^^^^^
  File "/Users/sergeizeliabovskii/Documents/python_ptojects/DjangoProject/.venv/lib/python3.13/site-packages/rest_framework/views.py", line 486, in raise_uncaught_exception
    raise exc
  File "/Users/sergeizeliabovskii/Documents/python_ptojects/DjangoProject/.venv/lib/python3.13/site-packages/rest_framework/views.py", line 512, in dispatch
    response = handler(request, *args, **kwargs)
  File "/Users/sergeizeliabovskii/Documents/python_ptojects/DjangoProject/.venv/lib/python3.13/site-packages/rest_framework/decorators.py", line 50, in handler
    return func(*args, **kwargs)
TypeError: edit_emergency_contact() got an unexpected keyword argument 'user_id'
ERROR 2025-05-21 22:45:21,911 basehttp "PATCH /api/v1/user/edit/contact/6/ HTTP/1.1" 500 89185
ERROR 2025-05-22 01:15:56,085 log Internal Server Error: /api/v1/event/trigger/2/
Traceback (most recent call last):
  File "/Users/sergeizeliabovskii/Documents/python_ptojects/DjangoProject/.venv/lib/python3.13/site-packages/django/core/handlers/exception.py", line 55, in inner
    response = get_response(request)
  File "/Users/sergeizeliabovskii/Documents/python_ptojects/DjangoProject/.venv/lib/python3.13/site-packages/django/core/handlers/base.py", line 197, in _get_response
    response = wrapped_callback(request, *callback_args, **callback_kwargs)
  File "/Users/sergeizeliabovskii/Documents/python_ptojects/DjangoProject/.venv/lib/python3.13/site-packages/django/views/decorators/csrf.py", line 65, in _view_wrapper
    return view_func(request, *args, **kwargs)
  File "/Users/sergeizeliabovskii/Documents/python_ptojects/DjangoProject/.venv/lib/python3.13/site-packages/django/views/generic/base.py", line 104, in view
    return self.dispatch(request, *args, **kwargs)
           ~~~~~~~~~~~~~^^^^^^^^^^^^^^^^^^^^^^^^^^
  File "/Users/sergeizeliabovskii/Documents/python_ptojects/DjangoProject/.venv/lib/python3.13/site-packages/rest_framework/views.py", line 515, in dispatch
    response = self.handle_exception(exc)
  File "/Users/sergeizeliabovskii/Documents/python_ptojects/DjangoProject/.venv/lib/python3.13/site-packages/rest_framework/views.py", line 475, in handle_exception
    self.raise_uncaught_exception(exc)
    ~~~~~~~~~~~~~~~~~~~~~~~~~~~~~^^^^^
  File "/Users/sergeizeliabovskii/Documents/python_ptojects/DjangoProject/.venv/lib/python3.13/site-packages/rest_framework/views.py", line 486, in raise_uncaught_exception
    raise exc
  File "/Users/sergeizeliabovskii/Documents/python_ptojects/DjangoProject/.venv/lib/python3.13/site-packages/rest_framework/views.py", line 512, in dispatch
    response = handler(request, *args, **kwargs)
  File "/Users/sergeizeliabovskii/Documents/python_ptojects/DjangoProject/.venv/lib/python3.13/site-packages/rest_framework/decorators.py", line 50, in handler
    return func(*args, **kwargs)
  File "/Users/sergeizeliabovskii/Documents/python_ptojects/DjangoProject/event/views.py", line 46, in trigger
    if scenario.notify_contact and user_info.emergency_contacts.exists():
                                   ^^^^^^^^^^^^^^^^^^^^^^^^^^^^
AttributeError: 'UserInfo' object has no attribute 'emergency_contacts'
ERROR 2025-05-22 01:15:56,097 basehttp "GET /api/v1/event/trigger/2/ HTTP/1.1" 500 93912
ERROR 2025-05-22 01:19:10,500 log Internal Server Error: /api/v1/event/trigger/2/
Traceback (most recent call last):
  File "/Users/sergeizeliabovskii/Documents/python_ptojects/DjangoProject/.venv/lib/python3.13/site-packages/django/core/handlers/exception.py", line 55, in inner
    response = get_response(request)
  File "/Users/sergeizeliabovskii/Documents/python_ptojects/DjangoProject/.venv/lib/python3.13/site-packages/django/core/handlers/base.py", line 197, in _get_response
    response = wrapped_callback(request, *callback_args, **callback_kwargs)
  File "/Users/sergeizeliabovskii/Documents/python_ptojects/DjangoProject/.venv/lib/python3.13/site-packages/django/views/decorators/csrf.py", line 65, in _view_wrapper
    return view_func(request, *args, **kwargs)
  File "/Users/sergeizeliabovskii/Documents/python_ptojects/DjangoProject/.venv/lib/python3.13/site-packages/django/views/generic/base.py", line 104, in view
    return self.dispatch(request, *args, **kwargs)
           ~~~~~~~~~~~~~^^^^^^^^^^^^^^^^^^^^^^^^^^
  File "/Users/sergeizeliabovskii/Documents/python_ptojects/DjangoProject/.venv/lib/python3.13/site-packages/rest_framework/views.py", line 515, in dispatch
    response = self.handle_exception(exc)
  File "/Users/sergeizeliabovskii/Documents/python_ptojects/DjangoProject/.venv/lib/python3.13/site-packages/rest_framework/views.py", line 475, in handle_exception
    self.raise_uncaught_exception(exc)
    ~~~~~~~~~~~~~~~~~~~~~~~~~~~~~^^^^^
  File "/Users/sergeizeliabovskii/Documents/python_ptojects/DjangoProject/.venv/lib/python3.13/site-packages/rest_framework/views.py", line 486, in raise_uncaught_exception
    raise exc
  File "/Users/sergeizeliabovskii/Documents/python_ptojects/DjangoProject/.venv/lib/python3.13/site-packages/rest_framework/views.py", line 512, in dispatch
    response = handler(request, *args, **kwargs)
  File "/Users/sergeizeliabovskii/Documents/python_ptojects/DjangoProject/.venv/lib/python3.13/site-packages/rest_framework/decorators.py", line 50, in handler
    return func(*args, **kwargs)
  File "/Users/sergeizeliabovskii/Documents/python_ptojects/DjangoProject/event/views.py", line 61, in trigger
    notification.send_notification()
    ^^^^^^^^^^^^^^^^^^^^^^^^^^^^^^
AttributeError: 'Notification' object has no attribute 'send_notification'
ERROR 2025-05-22 01:19:10,504 basehttp "GET /api/v1/event/trigger/2/ HTTP/1.1" 500 95481
