ERROR 2025-05-19 16:38:21,826 log Internal Server Error: /api/v1/registration/
Traceback (most recent call last):
  File "/Users/sergeizeliabovskii/Documents/python_ptojects/DjangoProject/.venv/lib/python3.13/site-packages/django/db/backends/utils.py", line 103, in _execute
    return self.cursor.execute(sql)
           ~~~~~~~~~~~~~~~~~~~^^^^^
psycopg2.errors.NoActiveSqlTransaction: SAVEPOINT can only be used in transaction blocks


The above exception was the direct cause of the following exception:

Traceback (most recent call last):
  File "/Users/sergeizeliabovskii/Documents/python_ptojects/DjangoProject/.venv/lib/python3.13/site-packages/django/core/handlers/exception.py", line 55, in inner
    response = get_response(request)
  File "/Users/sergeizeliabovskii/Documents/python_ptojects/DjangoProject/.venv/lib/python3.13/site-packages/django/core/handlers/base.py", line 197, in _get_response
    response = wrapped_callback(request, *callback_args, **callback_kwargs)
  File "/Users/sergeizeliabovskii/Documents/python_ptojects/DjangoProject/.venv/lib/python3.13/site-packages/django/views/decorators/csrf.py", line 65, in _view_wrapper
    return view_func(request, *args, **kwargs)
  File "/Users/sergeizeliabovskii/Documents/python_ptojects/DjangoProject/.venv/lib/python3.13/site-packages/django/views/generic/base.py", line 104, in view
    return self.dispatch(request, *args, **kwargs)
           ~~~~~~~~~~~~~^^^^^^^^^^^^^^^^^^^^^^^^^^
  File "/Users/sergeizeliabovskii/Documents/python_ptojects/DjangoProject/.venv/lib/python3.13/site-packages/rest_framework/views.py", line 515, in dispatch
    response = self.handle_exception(exc)
  File "/Users/sergeizeliabovskii/Documents/python_ptojects/DjangoProject/.venv/lib/python3.13/site-packages/rest_framework/views.py", line 475, in handle_exception
    self.raise_uncaught_exception(exc)
    ~~~~~~~~~~~~~~~~~~~~~~~~~~~~~^^^^^
  File "/Users/sergeizeliabovskii/Documents/python_ptojects/DjangoProject/.venv/lib/python3.13/site-packages/rest_framework/views.py", line 486, in raise_uncaught_exception
    raise exc
  File "/Users/sergeizeliabovskii/Documents/python_ptojects/DjangoProject/.venv/lib/python3.13/site-packages/rest_framework/views.py", line 512, in dispatch
    response = handler(request, *args, **kwargs)
  File "/Users/sergeizeliabovskii/Documents/python_ptojects/DjangoProject/.venv/lib/python3.13/site-packages/rest_framework/decorators.py", line 50, in handler
    return func(*args, **kwargs)
  File "/Library/Frameworks/Python.framework/Versions/3.13/lib/python3.13/contextlib.py", line 84, in inner
    with self._recreate_cm():
         ~~~~~~~~~~~~~~~~~^^
  File "/Users/sergeizeliabovskii/Documents/python_ptojects/DjangoProject/.venv/lib/python3.13/site-packages/django/db/transaction.py", line 211, in __enter__
    sid = connection.savepoint()
  File "/Users/sergeizeliabovskii/Documents/python_ptojects/DjangoProject/.venv/lib/python3.13/site-packages/django/utils/asyncio.py", line 26, in inner
    return func(*args, **kwargs)
  File "/Users/sergeizeliabovskii/Documents/python_ptojects/DjangoProject/.venv/lib/python3.13/site-packages/django/db/backends/base/base.py", line 400, in savepoint
    self._savepoint(sid)
    ~~~~~~~~~~~~~~~^^^^^
  File "/Users/sergeizeliabovskii/Documents/python_ptojects/DjangoProject/.venv/lib/python3.13/site-packages/django/db/backends/base/base.py", line 367, in _savepoint
    cursor.execute(self.ops.savepoint_create_sql(sid))
    ~~~~~~~~~~~~~~^^^^^^^^^^^^^^^^^^^^^^^^^^^^^^^^^^^^
  File "/Users/sergeizeliabovskii/Documents/python_ptojects/DjangoProject/.venv/lib/python3.13/site-packages/django/db/backends/utils.py", line 79, in execute
    return self._execute_with_wrappers(
           ~~~~~~~~~~~~~~~~~~~~~~~~~~~^
        sql, params, many=False, executor=self._execute
        ^^^^^^^^^^^^^^^^^^^^^^^^^^^^^^^^^^^^^^^^^^^^^^^
    )
    ^
  File "/Users/sergeizeliabovskii/Documents/python_ptojects/DjangoProject/.venv/lib/python3.13/site-packages/django/db/backends/utils.py", line 92, in _execute_with_wrappers
    return executor(sql, params, many, context)
  File "/Users/sergeizeliabovskii/Documents/python_ptojects/DjangoProject/.venv/lib/python3.13/site-packages/django/db/backends/utils.py", line 100, in _execute
    with self.db.wrap_database_errors:
         ^^^^^^^^^^^^^^^^^^^^^^^^^^^^
  File "/Users/sergeizeliabovskii/Documents/python_ptojects/DjangoProject/.venv/lib/python3.13/site-packages/django/db/utils.py", line 91, in __exit__
    raise dj_exc_value.with_traceback(traceback) from exc_value
  File "/Users/sergeizeliabovskii/Documents/python_ptojects/DjangoProject/.venv/lib/python3.13/site-packages/django/db/backends/utils.py", line 103, in _execute
    return self.cursor.execute(sql)
           ~~~~~~~~~~~~~~~~~~~^^^^^
django.db.utils.InternalError: SAVEPOINT can only be used in transaction blocks

ERROR 2025-05-19 16:38:22,193 log Internal Server Error: /api/v1/registration/
Traceback (most recent call last):
  File "/Users/sergeizeliabovskii/Documents/python_ptojects/DjangoProject/.venv/lib/python3.13/site-packages/django/db/backends/utils.py", line 103, in _execute
    return self.cursor.execute(sql)
           ~~~~~~~~~~~~~~~~~~~^^^^^
psycopg2.errors.NoActiveSqlTransaction: SAVEPOINT can only be used in transaction blocks


The above exception was the direct cause of the following exception:

Traceback (most recent call last):
  File "/Users/sergeizeliabovskii/Documents/python_ptojects/DjangoProject/.venv/lib/python3.13/site-packages/django/core/handlers/exception.py", line 55, in inner
    response = get_response(request)
  File "/Users/sergeizeliabovskii/Documents/python_ptojects/DjangoProject/.venv/lib/python3.13/site-packages/django/core/handlers/base.py", line 197, in _get_response
    response = wrapped_callback(request, *callback_args, **callback_kwargs)
  File "/Users/sergeizeliabovskii/Documents/python_ptojects/DjangoProject/.venv/lib/python3.13/site-packages/django/views/decorators/csrf.py", line 65, in _view_wrapper
    return view_func(request, *args, **kwargs)
  File "/Users/sergeizeliabovskii/Documents/python_ptojects/DjangoProject/.venv/lib/python3.13/site-packages/django/views/generic/base.py", line 104, in view
    return self.dispatch(request, *args, **kwargs)
           ~~~~~~~~~~~~~^^^^^^^^^^^^^^^^^^^^^^^^^^
  File "/Users/sergeizeliabovskii/Documents/python_ptojects/DjangoProject/.venv/lib/python3.13/site-packages/rest_framework/views.py", line 515, in dispatch
    response = self.handle_exception(exc)
  File "/Users/sergeizeliabovskii/Documents/python_ptojects/DjangoProject/.venv/lib/python3.13/site-packages/rest_framework/views.py", line 475, in handle_exception
    self.raise_uncaught_exception(exc)
    ~~~~~~~~~~~~~~~~~~~~~~~~~~~~~^^^^^
  File "/Users/sergeizeliabovskii/Documents/python_ptojects/DjangoProject/.venv/lib/python3.13/site-packages/rest_framework/views.py", line 486, in raise_uncaught_exception
    raise exc
  File "/Users/sergeizeliabovskii/Documents/python_ptojects/DjangoProject/.venv/lib/python3.13/site-packages/rest_framework/views.py", line 512, in dispatch
    response = handler(request, *args, **kwargs)
  File "/Users/sergeizeliabovskii/Documents/python_ptojects/DjangoProject/.venv/lib/python3.13/site-packages/rest_framework/decorators.py", line 50, in handler
    return func(*args, **kwargs)
  File "/Library/Frameworks/Python.framework/Versions/3.13/lib/python3.13/contextlib.py", line 84, in inner
    with self._recreate_cm():
         ~~~~~~~~~~~~~~~~~^^
  File "/Users/sergeizeliabovskii/Documents/python_ptojects/DjangoProject/.venv/lib/python3.13/site-packages/django/db/transaction.py", line 211, in __enter__
    sid = connection.savepoint()
  File "/Users/sergeizeliabovskii/Documents/python_ptojects/DjangoProject/.venv/lib/python3.13/site-packages/django/utils/asyncio.py", line 26, in inner
    return func(*args, **kwargs)
  File "/Users/sergeizeliabovskii/Documents/python_ptojects/DjangoProject/.venv/lib/python3.13/site-packages/django/db/backends/base/base.py", line 400, in savepoint
    self._savepoint(sid)
    ~~~~~~~~~~~~~~~^^^^^
  File "/Users/sergeizeliabovskii/Documents/python_ptojects/DjangoProject/.venv/lib/python3.13/site-packages/django/db/backends/base/base.py", line 367, in _savepoint
    cursor.execute(self.ops.savepoint_create_sql(sid))
    ~~~~~~~~~~~~~~^^^^^^^^^^^^^^^^^^^^^^^^^^^^^^^^^^^^
  File "/Users/sergeizeliabovskii/Documents/python_ptojects/DjangoProject/.venv/lib/python3.13/site-packages/django/db/backends/utils.py", line 79, in execute
    return self._execute_with_wrappers(
           ~~~~~~~~~~~~~~~~~~~~~~~~~~~^
        sql, params, many=False, executor=self._execute
        ^^^^^^^^^^^^^^^^^^^^^^^^^^^^^^^^^^^^^^^^^^^^^^^
    )
    ^
  File "/Users/sergeizeliabovskii/Documents/python_ptojects/DjangoProject/.venv/lib/python3.13/site-packages/django/db/backends/utils.py", line 92, in _execute_with_wrappers
    return executor(sql, params, many, context)
  File "/Users/sergeizeliabovskii/Documents/python_ptojects/DjangoProject/.venv/lib/python3.13/site-packages/django/db/backends/utils.py", line 100, in _execute
    with self.db.wrap_database_errors:
         ^^^^^^^^^^^^^^^^^^^^^^^^^^^^
  File "/Users/sergeizeliabovskii/Documents/python_ptojects/DjangoProject/.venv/lib/python3.13/site-packages/django/db/utils.py", line 91, in __exit__
    raise dj_exc_value.with_traceback(traceback) from exc_value
  File "/Users/sergeizeliabovskii/Documents/python_ptojects/DjangoProject/.venv/lib/python3.13/site-packages/django/db/backends/utils.py", line 103, in _execute
    return self.cursor.execute(sql)
           ~~~~~~~~~~~~~~~~~~~^^^^^
django.db.utils.InternalError: SAVEPOINT can only be used in transaction blocks

ERROR 2025-05-19 17:17:27,917 log Internal Server Error: /api/v1/edit_userinfo/1/
Traceback (most recent call last):
  File "/Users/sergeizeliabovskii/Documents/python_ptojects/DjangoProject/.venv/lib/python3.13/site-packages/django/core/handlers/exception.py", line 55, in inner
    response = get_response(request)
  File "/Users/sergeizeliabovskii/Documents/python_ptojects/DjangoProject/.venv/lib/python3.13/site-packages/django/core/handlers/base.py", line 197, in _get_response
    response = wrapped_callback(request, *callback_args, **callback_kwargs)
  File "/Users/sergeizeliabovskii/Documents/python_ptojects/DjangoProject/.venv/lib/python3.13/site-packages/django/views/decorators/csrf.py", line 65, in _view_wrapper
    return view_func(request, *args, **kwargs)
  File "/Users/sergeizeliabovskii/Documents/python_ptojects/DjangoProject/.venv/lib/python3.13/site-packages/django/views/generic/base.py", line 104, in view
    return self.dispatch(request, *args, **kwargs)
           ~~~~~~~~~~~~~^^^^^^^^^^^^^^^^^^^^^^^^^^
  File "/Users/sergeizeliabovskii/Documents/python_ptojects/DjangoProject/.venv/lib/python3.13/site-packages/rest_framework/views.py", line 515, in dispatch
    response = self.handle_exception(exc)
  File "/Users/sergeizeliabovskii/Documents/python_ptojects/DjangoProject/.venv/lib/python3.13/site-packages/rest_framework/views.py", line 475, in handle_exception
    self.raise_uncaught_exception(exc)
    ~~~~~~~~~~~~~~~~~~~~~~~~~~~~~^^^^^
  File "/Users/sergeizeliabovskii/Documents/python_ptojects/DjangoProject/.venv/lib/python3.13/site-packages/rest_framework/views.py", line 486, in raise_uncaught_exception
    raise exc
  File "/Users/sergeizeliabovskii/Documents/python_ptojects/DjangoProject/.venv/lib/python3.13/site-packages/rest_framework/views.py", line 512, in dispatch
    response = handler(request, *args, **kwargs)
  File "/Users/sergeizeliabovskii/Documents/python_ptojects/DjangoProject/.venv/lib/python3.13/site-packages/rest_framework/decorators.py", line 50, in handler
    return func(*args, **kwargs)
  File "/Library/Frameworks/Python.framework/Versions/3.13/lib/python3.13/contextlib.py", line 85, in inner
    return func(*args, **kwds)
TypeError: edit_userinfo() got an unexpected keyword argument 'user_id'
ERROR 2025-05-20 17:24:20,253 log Internal Server Error: /api/v1/login
Traceback (most recent call last):
  File "/Users/sergeizeliabovskii/Documents/python_ptojects/DjangoProject/.venv/lib/python3.13/site-packages/django/core/handlers/exception.py", line 55, in inner
    response = get_response(request)
  File "/Users/sergeizeliabovskii/Documents/python_ptojects/DjangoProject/.venv/lib/python3.13/site-packages/django/utils/deprecation.py", line 122, in __call__
    response = self.process_response(request, response)
  File "/Users/sergeizeliabovskii/Documents/python_ptojects/DjangoProject/.venv/lib/python3.13/site-packages/django/middleware/common.py", line 108, in process_response
    return self.response_redirect_class(self.get_full_path_with_slash(request))
                                        ~~~~~~~~~~~~~~~~~~~~~~~~~~~~~^^^^^^^^^
  File "/Users/sergeizeliabovskii/Documents/python_ptojects/DjangoProject/.venv/lib/python3.13/site-packages/django/middleware/common.py", line 87, in get_full_path_with_slash
    raise RuntimeError(
    ...<9 lines>...
    )
RuntimeError: You called this URL via POST, but the URL doesn't end in a slash and you have APPEND_SLASH set. Django can't redirect to the slash URL while maintaining POST data. Change your form to point to 127.0.0.1:8000/api/v1/login/ (note the trailing slash), or set APPEND_SLASH=False in your Django settings.
ERROR 2025-05-20 17:24:20,258 basehttp "POST /api/v1/login HTTP/1.1" 500 65622
ERROR 2025-05-20 23:14:52,225 log Internal Server Error: /api/v1/edit/user/1
Traceback (most recent call last):
  File "/Users/sergeizeliabovskii/Documents/python_ptojects/DjangoProject/.venv/lib/python3.13/site-packages/django/core/handlers/exception.py", line 55, in inner
    response = get_response(request)
  File "/Users/sergeizeliabovskii/Documents/python_ptojects/DjangoProject/.venv/lib/python3.13/site-packages/django/utils/deprecation.py", line 122, in __call__
    response = self.process_response(request, response)
  File "/Users/sergeizeliabovskii/Documents/python_ptojects/DjangoProject/.venv/lib/python3.13/site-packages/django/middleware/common.py", line 108, in process_response
    return self.response_redirect_class(self.get_full_path_with_slash(request))
                                        ~~~~~~~~~~~~~~~~~~~~~~~~~~~~~^^^^^^^^^
  File "/Users/sergeizeliabovskii/Documents/python_ptojects/DjangoProject/.venv/lib/python3.13/site-packages/django/middleware/common.py", line 87, in get_full_path_with_slash
    raise RuntimeError(
    ...<9 lines>...
    )
RuntimeError: You called this URL via POST, but the URL doesn't end in a slash and you have APPEND_SLASH set. Django can't redirect to the slash URL while maintaining POST data. Change your form to point to 127.0.0.1:8000/api/v1/edit/user/1/ (note the trailing slash), or set APPEND_SLASH=False in your Django settings.
ERROR 2025-05-20 23:14:52,228 basehttp "POST /api/v1/edit/user/1 HTTP/1.1" 500 66315
ERROR 2025-05-21 01:15:02,602 log Internal Server Error: /api/v1/user/edit/1
Traceback (most recent call last):
  File "/Users/sergeizeliabovskii/Documents/python_ptojects/DjangoProject/.venv/lib/python3.13/site-packages/django/core/handlers/exception.py", line 55, in inner
    response = get_response(request)
  File "/Users/sergeizeliabovskii/Documents/python_ptojects/DjangoProject/.venv/lib/python3.13/site-packages/django/utils/deprecation.py", line 122, in __call__
    response = self.process_response(request, response)
  File "/Users/sergeizeliabovskii/Documents/python_ptojects/DjangoProject/.venv/lib/python3.13/site-packages/django/middleware/common.py", line 108, in process_response
    return self.response_redirect_class(self.get_full_path_with_slash(request))
                                        ~~~~~~~~~~~~~~~~~~~~~~~~~~~~~^^^^^^^^^
  File "/Users/sergeizeliabovskii/Documents/python_ptojects/DjangoProject/.venv/lib/python3.13/site-packages/django/middleware/common.py", line 87, in get_full_path_with_slash
    raise RuntimeError(
    ...<9 lines>...
    )
RuntimeError: You called this URL via PATCH, but the URL doesn't end in a slash and you have APPEND_SLASH set. Django can't redirect to the slash URL while maintaining PATCH data. Change your form to point to 127.0.0.1:8000/api/v1/user/edit/1/ (note the trailing slash), or set APPEND_SLASH=False in your Django settings.
ERROR 2025-05-21 01:15:02,606 basehttp "PATCH /api/v1/user/edit/1 HTTP/1.1" 500 66330
ERROR 2025-05-21 01:19:36,643 log Internal Server Error: /api/v1/user/edit/1/
ERROR 2025-05-21 01:19:36,644 basehttp "PATCH /api/v1/user/edit/1/ HTTP/1.1" 500 92
ERROR 2025-05-21 02:22:59,733 log Internal Server Error: /api/v1/registration/
Traceback (most recent call last):
  File "/Users/sergeizeliabovskii/Documents/python_ptojects/DjangoProject/.venv/lib/python3.13/site-packages/django/core/handlers/exception.py", line 55, in inner
    response = get_response(request)
  File "/Users/sergeizeliabovskii/Documents/python_ptojects/DjangoProject/.venv/lib/python3.13/site-packages/django/core/handlers/base.py", line 197, in _get_response
    response = wrapped_callback(request, *callback_args, **callback_kwargs)
  File "/Users/sergeizeliabovskii/Documents/python_ptojects/DjangoProject/.venv/lib/python3.13/site-packages/django/views/decorators/csrf.py", line 65, in _view_wrapper
    return view_func(request, *args, **kwargs)
  File "/Users/sergeizeliabovskii/Documents/python_ptojects/DjangoProject/.venv/lib/python3.13/site-packages/django/views/generic/base.py", line 104, in view
    return self.dispatch(request, *args, **kwargs)
           ~~~~~~~~~~~~~^^^^^^^^^^^^^^^^^^^^^^^^^^
  File "/Users/sergeizeliabovskii/Documents/python_ptojects/DjangoProject/.venv/lib/python3.13/site-packages/rest_framework/views.py", line 515, in dispatch
    response = self.handle_exception(exc)
  File "/Users/sergeizeliabovskii/Documents/python_ptojects/DjangoProject/.venv/lib/python3.13/site-packages/rest_framework/views.py", line 475, in handle_exception
    self.raise_uncaught_exception(exc)
    ~~~~~~~~~~~~~~~~~~~~~~~~~~~~~^^^^^
  File "/Users/sergeizeliabovskii/Documents/python_ptojects/DjangoProject/.venv/lib/python3.13/site-packages/rest_framework/views.py", line 486, in raise_uncaught_exception
    raise exc
  File "/Users/sergeizeliabovskii/Documents/python_ptojects/DjangoProject/.venv/lib/python3.13/site-packages/rest_framework/views.py", line 512, in dispatch
    response = handler(request, *args, **kwargs)
  File "/Users/sergeizeliabovskii/Documents/python_ptojects/DjangoProject/.venv/lib/python3.13/site-packages/rest_framework/decorators.py", line 50, in handler
    return func(*args, **kwargs)
  File "/Library/Frameworks/Python.framework/Versions/3.13/lib/python3.13/contextlib.py", line 85, in inner
    return func(*args, **kwds)
  File "/Users/sergeizeliabovskii/Documents/python_ptojects/DjangoProject/main/views.py", line 21, in registration
    serializer.save()
    ~~~~~~~~~~~~~~~^^
  File "/Users/sergeizeliabovskii/Documents/python_ptojects/DjangoProject/.venv/lib/python3.13/site-packages/rest_framework/serializers.py", line 210, in save
    self.instance = self.create(validated_data)
                    ~~~~~~~~~~~^^^^^^^^^^^^^^^^
  File "/Users/sergeizeliabovskii/Documents/python_ptojects/DjangoProject/main/serializers.py", line 16, in create
    user = User.objects.create_user(
        username=validated_data['username'],
        email=validated_data.get('email'),
        password=validated_data['password']
    )
  File "/Users/sergeizeliabovskii/Documents/python_ptojects/DjangoProject/.venv/lib/python3.13/site-packages/django/contrib/auth/models.py", line 175, in create_user
    return self._create_user(username, email, password, **extra_fields)
           ~~~~~~~~~~~~~~~~~^^^^^^^^^^^^^^^^^^^^^^^^^^^^^^^^^^^^^^^^^^^
  File "/Users/sergeizeliabovskii/Documents/python_ptojects/DjangoProject/.venv/lib/python3.13/site-packages/django/contrib/auth/models.py", line 163, in _create_user
    user.save(using=self._db)
    ~~~~~~~~~^^^^^^^^^^^^^^^^
  File "/Users/sergeizeliabovskii/Documents/python_ptojects/DjangoProject/.venv/lib/python3.13/site-packages/django/contrib/auth/base_user.py", line 65, in save
    super().save(*args, **kwargs)
    ~~~~~~~~~~~~^^^^^^^^^^^^^^^^^
  File "/Users/sergeizeliabovskii/Documents/python_ptojects/DjangoProject/.venv/lib/python3.13/site-packages/django/db/models/base.py", line 902, in save
    self.save_base(
    ~~~~~~~~~~~~~~^
        using=using,
        ^^^^^^^^^^^^
    ...<2 lines>...
        update_fields=update_fields,
        ^^^^^^^^^^^^^^^^^^^^^^^^^^^^
    )
    ^
  File "/Users/sergeizeliabovskii/Documents/python_ptojects/DjangoProject/.venv/lib/python3.13/site-packages/django/db/models/base.py", line 1023, in save_base
    post_save.send(
    ~~~~~~~~~~~~~~^
        sender=origin,
        ^^^^^^^^^^^^^^
    ...<4 lines>...
        using=using,
        ^^^^^^^^^^^^
    )
    ^
  File "/Users/sergeizeliabovskii/Documents/python_ptojects/DjangoProject/.venv/lib/python3.13/site-packages/django/dispatch/dispatcher.py", line 189, in send
    response = receiver(signal=self, sender=sender, **named)
  File "/Users/sergeizeliabovskii/Documents/python_ptojects/DjangoProject/main/signals.py", line 33, in create_contact_card
    emergency_contact = EmergencyContact.objects.create(user_id=instance.id)
  File "/Users/sergeizeliabovskii/Documents/python_ptojects/DjangoProject/.venv/lib/python3.13/site-packages/django/db/models/manager.py", line 87, in manager_method
    return getattr(self.get_queryset(), name)(*args, **kwargs)
           ~~~~~~~~~~~~~~~~~~~~~~~~~~~~~~~~~~^^^^^^^^^^^^^^^^^
  File "/Users/sergeizeliabovskii/Documents/python_ptojects/DjangoProject/.venv/lib/python3.13/site-packages/django/db/models/query.py", line 661, in create
    obj = self.model(**kwargs)
  File "/Users/sergeizeliabovskii/Documents/python_ptojects/DjangoProject/.venv/lib/python3.13/site-packages/django/db/models/base.py", line 569, in __init__
    raise TypeError(
    ...<2 lines>...
    )
TypeError: EmergencyContact() got unexpected keyword arguments: 'user_id'
ERROR 2025-05-21 02:22:59,800 basehttp "POST /api/v1/registration/ HTTP/1.1" 500 154183
ERROR 2025-05-21 02:25:29,230 log Internal Server Error: /api/v1/registration/
Traceback (most recent call last):
  File "/Users/sergeizeliabovskii/Documents/python_ptojects/DjangoProject/.venv/lib/python3.13/site-packages/django/core/handlers/exception.py", line 55, in inner
    response = get_response(request)
  File "/Users/sergeizeliabovskii/Documents/python_ptojects/DjangoProject/.venv/lib/python3.13/site-packages/django/core/handlers/base.py", line 197, in _get_response
    response = wrapped_callback(request, *callback_args, **callback_kwargs)
  File "/Users/sergeizeliabovskii/Documents/python_ptojects/DjangoProject/.venv/lib/python3.13/site-packages/django/views/decorators/csrf.py", line 65, in _view_wrapper
    return view_func(request, *args, **kwargs)
  File "/Users/sergeizeliabovskii/Documents/python_ptojects/DjangoProject/.venv/lib/python3.13/site-packages/django/views/generic/base.py", line 104, in view
    return self.dispatch(request, *args, **kwargs)
           ~~~~~~~~~~~~~^^^^^^^^^^^^^^^^^^^^^^^^^^
  File "/Users/sergeizeliabovskii/Documents/python_ptojects/DjangoProject/.venv/lib/python3.13/site-packages/rest_framework/views.py", line 515, in dispatch
    response = self.handle_exception(exc)
  File "/Users/sergeizeliabovskii/Documents/python_ptojects/DjangoProject/.venv/lib/python3.13/site-packages/rest_framework/views.py", line 475, in handle_exception
    self.raise_uncaught_exception(exc)
    ~~~~~~~~~~~~~~~~~~~~~~~~~~~~~^^^^^
  File "/Users/sergeizeliabovskii/Documents/python_ptojects/DjangoProject/.venv/lib/python3.13/site-packages/rest_framework/views.py", line 486, in raise_uncaught_exception
    raise exc
  File "/Users/sergeizeliabovskii/Documents/python_ptojects/DjangoProject/.venv/lib/python3.13/site-packages/rest_framework/views.py", line 512, in dispatch
    response = handler(request, *args, **kwargs)
  File "/Users/sergeizeliabovskii/Documents/python_ptojects/DjangoProject/.venv/lib/python3.13/site-packages/rest_framework/decorators.py", line 50, in handler
    return func(*args, **kwargs)
  File "/Library/Frameworks/Python.framework/Versions/3.13/lib/python3.13/contextlib.py", line 85, in inner
    return func(*args, **kwds)
  File "/Users/sergeizeliabovskii/Documents/python_ptojects/DjangoProject/main/views.py", line 21, in registration
    serializer.save()
    ~~~~~~~~~~~~~~~^^
  File "/Users/sergeizeliabovskii/Documents/python_ptojects/DjangoProject/.venv/lib/python3.13/site-packages/rest_framework/serializers.py", line 210, in save
    self.instance = self.create(validated_data)
                    ~~~~~~~~~~~^^^^^^^^^^^^^^^^
  File "/Users/sergeizeliabovskii/Documents/python_ptojects/DjangoProject/main/serializers.py", line 16, in create
    user = User.objects.create_user(
        username=validated_data['username'],
        email=validated_data.get('email'),
        password=validated_data['password']
    )
  File "/Users/sergeizeliabovskii/Documents/python_ptojects/DjangoProject/.venv/lib/python3.13/site-packages/django/contrib/auth/models.py", line 175, in create_user
    return self._create_user(username, email, password, **extra_fields)
           ~~~~~~~~~~~~~~~~~^^^^^^^^^^^^^^^^^^^^^^^^^^^^^^^^^^^^^^^^^^^
  File "/Users/sergeizeliabovskii/Documents/python_ptojects/DjangoProject/.venv/lib/python3.13/site-packages/django/contrib/auth/models.py", line 163, in _create_user
    user.save(using=self._db)
    ~~~~~~~~~^^^^^^^^^^^^^^^^
  File "/Users/sergeizeliabovskii/Documents/python_ptojects/DjangoProject/.venv/lib/python3.13/site-packages/django/contrib/auth/base_user.py", line 65, in save
    super().save(*args, **kwargs)
    ~~~~~~~~~~~~^^^^^^^^^^^^^^^^^
  File "/Users/sergeizeliabovskii/Documents/python_ptojects/DjangoProject/.venv/lib/python3.13/site-packages/django/db/models/base.py", line 902, in save
    self.save_base(
    ~~~~~~~~~~~~~~^
        using=using,
        ^^^^^^^^^^^^
    ...<2 lines>...
        update_fields=update_fields,
        ^^^^^^^^^^^^^^^^^^^^^^^^^^^^
    )
    ^
  File "/Users/sergeizeliabovskii/Documents/python_ptojects/DjangoProject/.venv/lib/python3.13/site-packages/django/db/models/base.py", line 1023, in save_base
    post_save.send(
    ~~~~~~~~~~~~~~^
        sender=origin,
        ^^^^^^^^^^^^^^
    ...<4 lines>...
        using=using,
        ^^^^^^^^^^^^
    )
    ^
  File "/Users/sergeizeliabovskii/Documents/python_ptojects/DjangoProject/.venv/lib/python3.13/site-packages/django/dispatch/dispatcher.py", line 189, in send
    response = receiver(signal=self, sender=sender, **named)
  File "/Users/sergeizeliabovskii/Documents/python_ptojects/DjangoProject/main/signals.py", line 33, in create_contact_card
    emergency_contact = EmergencyContact.objects.create(user_id=instance.id)
  File "/Users/sergeizeliabovskii/Documents/python_ptojects/DjangoProject/.venv/lib/python3.13/site-packages/django/db/models/manager.py", line 87, in manager_method
    return getattr(self.get_queryset(), name)(*args, **kwargs)
           ~~~~~~~~~~~~~~~~~~~~~~~~~~~~~~~~~~^^^^^^^^^^^^^^^^^
  File "/Users/sergeizeliabovskii/Documents/python_ptojects/DjangoProject/.venv/lib/python3.13/site-packages/django/db/models/query.py", line 661, in create
    obj = self.model(**kwargs)
  File "/Users/sergeizeliabovskii/Documents/python_ptojects/DjangoProject/.venv/lib/python3.13/site-packages/django/db/models/base.py", line 569, in __init__
    raise TypeError(
    ...<2 lines>...
    )
TypeError: EmergencyContact() got unexpected keyword arguments: 'user_id'
ERROR 2025-05-21 02:25:29,250 basehttp "POST /api/v1/registration/ HTTP/1.1" 500 154180
ERROR 2025-05-21 02:26:38,558 log Internal Server Error: /api/v1/registration/
Traceback (most recent call last):
  File "/Users/sergeizeliabovskii/Documents/python_ptojects/DjangoProject/.venv/lib/python3.13/site-packages/django/core/handlers/exception.py", line 55, in inner
    response = get_response(request)
  File "/Users/sergeizeliabovskii/Documents/python_ptojects/DjangoProject/.venv/lib/python3.13/site-packages/django/core/handlers/base.py", line 197, in _get_response
    response = wrapped_callback(request, *callback_args, **callback_kwargs)
  File "/Users/sergeizeliabovskii/Documents/python_ptojects/DjangoProject/.venv/lib/python3.13/site-packages/django/views/decorators/csrf.py", line 65, in _view_wrapper
    return view_func(request, *args, **kwargs)
  File "/Users/sergeizeliabovskii/Documents/python_ptojects/DjangoProject/.venv/lib/python3.13/site-packages/django/views/generic/base.py", line 104, in view
    return self.dispatch(request, *args, **kwargs)
           ~~~~~~~~~~~~~^^^^^^^^^^^^^^^^^^^^^^^^^^
  File "/Users/sergeizeliabovskii/Documents/python_ptojects/DjangoProject/.venv/lib/python3.13/site-packages/rest_framework/views.py", line 515, in dispatch
    response = self.handle_exception(exc)
  File "/Users/sergeizeliabovskii/Documents/python_ptojects/DjangoProject/.venv/lib/python3.13/site-packages/rest_framework/views.py", line 475, in handle_exception
    self.raise_uncaught_exception(exc)
    ~~~~~~~~~~~~~~~~~~~~~~~~~~~~~^^^^^
  File "/Users/sergeizeliabovskii/Documents/python_ptojects/DjangoProject/.venv/lib/python3.13/site-packages/rest_framework/views.py", line 486, in raise_uncaught_exception
    raise exc
  File "/Users/sergeizeliabovskii/Documents/python_ptojects/DjangoProject/.venv/lib/python3.13/site-packages/rest_framework/views.py", line 512, in dispatch
    response = handler(request, *args, **kwargs)
  File "/Users/sergeizeliabovskii/Documents/python_ptojects/DjangoProject/.venv/lib/python3.13/site-packages/rest_framework/decorators.py", line 50, in handler
    return func(*args, **kwargs)
  File "/Library/Frameworks/Python.framework/Versions/3.13/lib/python3.13/contextlib.py", line 85, in inner
    return func(*args, **kwds)
  File "/Users/sergeizeliabovskii/Documents/python_ptojects/DjangoProject/main/views.py", line 21, in registration
    serializer.save()
    ~~~~~~~~~~~~~~~^^
  File "/Users/sergeizeliabovskii/Documents/python_ptojects/DjangoProject/.venv/lib/python3.13/site-packages/rest_framework/serializers.py", line 210, in save
    self.instance = self.create(validated_data)
                    ~~~~~~~~~~~^^^^^^^^^^^^^^^^
  File "/Users/sergeizeliabovskii/Documents/python_ptojects/DjangoProject/main/serializers.py", line 16, in create
    user = User.objects.create_user(
        username=validated_data['username'],
        email=validated_data.get('email'),
        password=validated_data['password']
    )
  File "/Users/sergeizeliabovskii/Documents/python_ptojects/DjangoProject/.venv/lib/python3.13/site-packages/django/contrib/auth/models.py", line 175, in create_user
    return self._create_user(username, email, password, **extra_fields)
           ~~~~~~~~~~~~~~~~~^^^^^^^^^^^^^^^^^^^^^^^^^^^^^^^^^^^^^^^^^^^
  File "/Users/sergeizeliabovskii/Documents/python_ptojects/DjangoProject/.venv/lib/python3.13/site-packages/django/contrib/auth/models.py", line 163, in _create_user
    user.save(using=self._db)
    ~~~~~~~~~^^^^^^^^^^^^^^^^
  File "/Users/sergeizeliabovskii/Documents/python_ptojects/DjangoProject/.venv/lib/python3.13/site-packages/django/contrib/auth/base_user.py", line 65, in save
    super().save(*args, **kwargs)
    ~~~~~~~~~~~~^^^^^^^^^^^^^^^^^
  File "/Users/sergeizeliabovskii/Documents/python_ptojects/DjangoProject/.venv/lib/python3.13/site-packages/django/db/models/base.py", line 902, in save
    self.save_base(
    ~~~~~~~~~~~~~~^
        using=using,
        ^^^^^^^^^^^^
    ...<2 lines>...
        update_fields=update_fields,
        ^^^^^^^^^^^^^^^^^^^^^^^^^^^^
    )
    ^
  File "/Users/sergeizeliabovskii/Documents/python_ptojects/DjangoProject/.venv/lib/python3.13/site-packages/django/db/models/base.py", line 1023, in save_base
    post_save.send(
    ~~~~~~~~~~~~~~^
        sender=origin,
        ^^^^^^^^^^^^^^
    ...<4 lines>...
        using=using,
        ^^^^^^^^^^^^
    )
    ^
  File "/Users/sergeizeliabovskii/Documents/python_ptojects/DjangoProject/.venv/lib/python3.13/site-packages/django/dispatch/dispatcher.py", line 189, in send
    response = receiver(signal=self, sender=sender, **named)
  File "/Users/sergeizeliabovskii/Documents/python_ptojects/DjangoProject/main/signals.py", line 33, in create_contact_card
    emergency_contact = EmergencyContact.objects.create(user=instance.id)
  File "/Users/sergeizeliabovskii/Documents/python_ptojects/DjangoProject/.venv/lib/python3.13/site-packages/django/db/models/manager.py", line 87, in manager_method
    return getattr(self.get_queryset(), name)(*args, **kwargs)
           ~~~~~~~~~~~~~~~~~~~~~~~~~~~~~~~~~~^^^^^^^^^^^^^^^^^
  File "/Users/sergeizeliabovskii/Documents/python_ptojects/DjangoProject/.venv/lib/python3.13/site-packages/django/db/models/query.py", line 661, in create
    obj = self.model(**kwargs)
  File "/Users/sergeizeliabovskii/Documents/python_ptojects/DjangoProject/.venv/lib/python3.13/site-packages/django/db/models/base.py", line 569, in __init__
    raise TypeError(
    ...<2 lines>...
    )
TypeError: EmergencyContact() got unexpected keyword arguments: 'user'
ERROR 2025-05-21 02:26:38,586 basehttp "POST /api/v1/registration/ HTTP/1.1" 500 154132
ERROR 2025-05-21 02:28:36,833 log Internal Server Error: /api/v1/registration/
Traceback (most recent call last):
  File "/Users/sergeizeliabovskii/Documents/python_ptojects/DjangoProject/.venv/lib/python3.13/site-packages/django/core/handlers/exception.py", line 55, in inner
    response = get_response(request)
  File "/Users/sergeizeliabovskii/Documents/python_ptojects/DjangoProject/.venv/lib/python3.13/site-packages/django/core/handlers/base.py", line 197, in _get_response
    response = wrapped_callback(request, *callback_args, **callback_kwargs)
  File "/Users/sergeizeliabovskii/Documents/python_ptojects/DjangoProject/.venv/lib/python3.13/site-packages/django/views/decorators/csrf.py", line 65, in _view_wrapper
    return view_func(request, *args, **kwargs)
  File "/Users/sergeizeliabovskii/Documents/python_ptojects/DjangoProject/.venv/lib/python3.13/site-packages/django/views/generic/base.py", line 104, in view
    return self.dispatch(request, *args, **kwargs)
           ~~~~~~~~~~~~~^^^^^^^^^^^^^^^^^^^^^^^^^^
  File "/Users/sergeizeliabovskii/Documents/python_ptojects/DjangoProject/.venv/lib/python3.13/site-packages/rest_framework/views.py", line 515, in dispatch
    response = self.handle_exception(exc)
  File "/Users/sergeizeliabovskii/Documents/python_ptojects/DjangoProject/.venv/lib/python3.13/site-packages/rest_framework/views.py", line 475, in handle_exception
    self.raise_uncaught_exception(exc)
    ~~~~~~~~~~~~~~~~~~~~~~~~~~~~~^^^^^
  File "/Users/sergeizeliabovskii/Documents/python_ptojects/DjangoProject/.venv/lib/python3.13/site-packages/rest_framework/views.py", line 486, in raise_uncaught_exception
    raise exc
  File "/Users/sergeizeliabovskii/Documents/python_ptojects/DjangoProject/.venv/lib/python3.13/site-packages/rest_framework/views.py", line 512, in dispatch
    response = handler(request, *args, **kwargs)
  File "/Users/sergeizeliabovskii/Documents/python_ptojects/DjangoProject/.venv/lib/python3.13/site-packages/rest_framework/decorators.py", line 50, in handler
    return func(*args, **kwargs)
  File "/Library/Frameworks/Python.framework/Versions/3.13/lib/python3.13/contextlib.py", line 85, in inner
    return func(*args, **kwds)
  File "/Users/sergeizeliabovskii/Documents/python_ptojects/DjangoProject/main/views.py", line 21, in registration
    serializer.save()
    ~~~~~~~~~~~~~~~^^
  File "/Users/sergeizeliabovskii/Documents/python_ptojects/DjangoProject/.venv/lib/python3.13/site-packages/rest_framework/serializers.py", line 210, in save
    self.instance = self.create(validated_data)
                    ~~~~~~~~~~~^^^^^^^^^^^^^^^^
  File "/Users/sergeizeliabovskii/Documents/python_ptojects/DjangoProject/main/serializers.py", line 16, in create
    user = User.objects.create_user(
        username=validated_data['username'],
        email=validated_data.get('email'),
        password=validated_data['password']
    )
  File "/Users/sergeizeliabovskii/Documents/python_ptojects/DjangoProject/.venv/lib/python3.13/site-packages/django/contrib/auth/models.py", line 175, in create_user
    return self._create_user(username, email, password, **extra_fields)
           ~~~~~~~~~~~~~~~~~^^^^^^^^^^^^^^^^^^^^^^^^^^^^^^^^^^^^^^^^^^^
  File "/Users/sergeizeliabovskii/Documents/python_ptojects/DjangoProject/.venv/lib/python3.13/site-packages/django/contrib/auth/models.py", line 163, in _create_user
    user.save(using=self._db)
    ~~~~~~~~~^^^^^^^^^^^^^^^^
  File "/Users/sergeizeliabovskii/Documents/python_ptojects/DjangoProject/.venv/lib/python3.13/site-packages/django/contrib/auth/base_user.py", line 65, in save
    super().save(*args, **kwargs)
    ~~~~~~~~~~~~^^^^^^^^^^^^^^^^^
  File "/Users/sergeizeliabovskii/Documents/python_ptojects/DjangoProject/.venv/lib/python3.13/site-packages/django/db/models/base.py", line 902, in save
    self.save_base(
    ~~~~~~~~~~~~~~^
        using=using,
        ^^^^^^^^^^^^
    ...<2 lines>...
        update_fields=update_fields,
        ^^^^^^^^^^^^^^^^^^^^^^^^^^^^
    )
    ^
  File "/Users/sergeizeliabovskii/Documents/python_ptojects/DjangoProject/.venv/lib/python3.13/site-packages/django/db/models/base.py", line 1023, in save_base
    post_save.send(
    ~~~~~~~~~~~~~~^
        sender=origin,
        ^^^^^^^^^^^^^^
    ...<4 lines>...
        using=using,
        ^^^^^^^^^^^^
    )
    ^
  File "/Users/sergeizeliabovskii/Documents/python_ptojects/DjangoProject/.venv/lib/python3.13/site-packages/django/dispatch/dispatcher.py", line 189, in send
    response = receiver(signal=self, sender=sender, **named)
  File "/Users/sergeizeliabovskii/Documents/python_ptojects/DjangoProject/main/signals.py", line 33, in create_contact_card
    emergency_contact = EmergencyContact.objects.create(user=instance.id)
  File "/Users/sergeizeliabovskii/Documents/python_ptojects/DjangoProject/.venv/lib/python3.13/site-packages/django/db/models/manager.py", line 87, in manager_method
    return getattr(self.get_queryset(), name)(*args, **kwargs)
           ~~~~~~~~~~~~~~~~~~~~~~~~~~~~~~~~~~^^^^^^^^^^^^^^^^^
  File "/Users/sergeizeliabovskii/Documents/python_ptojects/DjangoProject/.venv/lib/python3.13/site-packages/django/db/models/query.py", line 661, in create
    obj = self.model(**kwargs)
  File "/Users/sergeizeliabovskii/Documents/python_ptojects/DjangoProject/.venv/lib/python3.13/site-packages/django/db/models/base.py", line 545, in __init__
    _setattr(self, field.name, rel_obj)
    ~~~~~~~~^^^^^^^^^^^^^^^^^^^^^^^^^^^
  File "/Users/sergeizeliabovskii/Documents/python_ptojects/DjangoProject/.venv/lib/python3.13/site-packages/django/db/models/fields/related_descriptors.py", line 391, in __set__
    super().__set__(instance, value)
    ~~~~~~~~~~~~~~~^^^^^^^^^^^^^^^^^
  File "/Users/sergeizeliabovskii/Documents/python_ptojects/DjangoProject/.venv/lib/python3.13/site-packages/django/db/models/fields/related_descriptors.py", line 288, in __set__
    raise ValueError(
    ...<7 lines>...
    )
ValueError: Cannot assign "5": "EmergencyContact.user" must be a "User" instance.
ERROR 2025-05-21 02:28:36,842 basehttp "POST /api/v1/registration/ HTTP/1.1" 500 162626
ERROR 2025-05-21 21:10:00,176 log Internal Server Error: /api/v1/user/edit/6/
ERROR 2025-05-21 21:10:00,177 basehttp "PATCH /api/v1/user/edit/6/ HTTP/1.1" 500 96
ERROR 2025-05-21 22:45:21,907 log Internal Server Error: /api/v1/user/edit/contact/6/
Traceback (most recent call last):
  File "/Users/sergeizeliabovskii/Documents/python_ptojects/DjangoProject/.venv/lib/python3.13/site-packages/django/core/handlers/exception.py", line 55, in inner
    response = get_response(request)
  File "/Users/sergeizeliabovskii/Documents/python_ptojects/DjangoProject/.venv/lib/python3.13/site-packages/django/core/handlers/base.py", line 197, in _get_response
    response = wrapped_callback(request, *callback_args, **callback_kwargs)
  File "/Users/sergeizeliabovskii/Documents/python_ptojects/DjangoProject/.venv/lib/python3.13/site-packages/django/views/decorators/csrf.py", line 65, in _view_wrapper
    return view_func(request, *args, **kwargs)
  File "/Users/sergeizeliabovskii/Documents/python_ptojects/DjangoProject/.venv/lib/python3.13/site-packages/django/views/generic/base.py", line 104, in view
    return self.dispatch(request, *args, **kwargs)
           ~~~~~~~~~~~~~^^^^^^^^^^^^^^^^^^^^^^^^^^
  File "/Users/sergeizeliabovskii/Documents/python_ptojects/DjangoProject/.venv/lib/python3.13/site-packages/rest_framework/views.py", line 515, in dispatch
    response = self.handle_exception(exc)
  File "/Users/sergeizeliabovskii/Documents/python_ptojects/DjangoProject/.venv/lib/python3.13/site-packages/rest_framework/views.py", line 475, in handle_exception
    self.raise_uncaught_exception(exc)
    ~~~~~~~~~~~~~~~~~~~~~~~~~~~~~^^^^^
  File "/Users/sergeizeliabovskii/Documents/python_ptojects/DjangoProject/.venv/lib/python3.13/site-packages/rest_framework/views.py", line 486, in raise_uncaught_exception
    raise exc
  File "/Users/sergeizeliabovskii/Documents/python_ptojects/DjangoProject/.venv/lib/python3.13/site-packages/rest_framework/views.py", line 512, in dispatch
    response = handler(request, *args, **kwargs)
  File "/Users/sergeizeliabovskii/Documents/python_ptojects/DjangoProject/.venv/lib/python3.13/site-packages/rest_framework/decorators.py", line 50, in handler
    return func(*args, **kwargs)
TypeError: edit_emergency_contact() got an unexpected keyword argument 'user_id'
ERROR 2025-05-21 22:45:21,911 basehttp "PATCH /api/v1/user/edit/contact/6/ HTTP/1.1" 500 89185
ERROR 2025-05-22 01:15:56,085 log Internal Server Error: /api/v1/event/trigger/2/
Traceback (most recent call last):
  File "/Users/sergeizeliabovskii/Documents/python_ptojects/DjangoProject/.venv/lib/python3.13/site-packages/django/core/handlers/exception.py", line 55, in inner
    response = get_response(request)
  File "/Users/sergeizeliabovskii/Documents/python_ptojects/DjangoProject/.venv/lib/python3.13/site-packages/django/core/handlers/base.py", line 197, in _get_response
    response = wrapped_callback(request, *callback_args, **callback_kwargs)
  File "/Users/sergeizeliabovskii/Documents/python_ptojects/DjangoProject/.venv/lib/python3.13/site-packages/django/views/decorators/csrf.py", line 65, in _view_wrapper
    return view_func(request, *args, **kwargs)
  File "/Users/sergeizeliabovskii/Documents/python_ptojects/DjangoProject/.venv/lib/python3.13/site-packages/django/views/generic/base.py", line 104, in view
    return self.dispatch(request, *args, **kwargs)
           ~~~~~~~~~~~~~^^^^^^^^^^^^^^^^^^^^^^^^^^
  File "/Users/sergeizeliabovskii/Documents/python_ptojects/DjangoProject/.venv/lib/python3.13/site-packages/rest_framework/views.py", line 515, in dispatch
    response = self.handle_exception(exc)
  File "/Users/sergeizeliabovskii/Documents/python_ptojects/DjangoProject/.venv/lib/python3.13/site-packages/rest_framework/views.py", line 475, in handle_exception
    self.raise_uncaught_exception(exc)
    ~~~~~~~~~~~~~~~~~~~~~~~~~~~~~^^^^^
  File "/Users/sergeizeliabovskii/Documents/python_ptojects/DjangoProject/.venv/lib/python3.13/site-packages/rest_framework/views.py", line 486, in raise_uncaught_exception
    raise exc
  File "/Users/sergeizeliabovskii/Documents/python_ptojects/DjangoProject/.venv/lib/python3.13/site-packages/rest_framework/views.py", line 512, in dispatch
    response = handler(request, *args, **kwargs)
  File "/Users/sergeizeliabovskii/Documents/python_ptojects/DjangoProject/.venv/lib/python3.13/site-packages/rest_framework/decorators.py", line 50, in handler
    return func(*args, **kwargs)
  File "/Users/sergeizeliabovskii/Documents/python_ptojects/DjangoProject/event/views.py", line 46, in trigger
    if scenario.notify_contact and user_info.emergency_contacts.exists():
                                   ^^^^^^^^^^^^^^^^^^^^^^^^^^^^
AttributeError: 'UserInfo' object has no attribute 'emergency_contacts'
ERROR 2025-05-22 01:15:56,097 basehttp "GET /api/v1/event/trigger/2/ HTTP/1.1" 500 93912
ERROR 2025-05-22 01:19:10,500 log Internal Server Error: /api/v1/event/trigger/2/
Traceback (most recent call last):
  File "/Users/sergeizeliabovskii/Documents/python_ptojects/DjangoProject/.venv/lib/python3.13/site-packages/django/core/handlers/exception.py", line 55, in inner
    response = get_response(request)
  File "/Users/sergeizeliabovskii/Documents/python_ptojects/DjangoProject/.venv/lib/python3.13/site-packages/django/core/handlers/base.py", line 197, in _get_response
    response = wrapped_callback(request, *callback_args, **callback_kwargs)
  File "/Users/sergeizeliabovskii/Documents/python_ptojects/DjangoProject/.venv/lib/python3.13/site-packages/django/views/decorators/csrf.py", line 65, in _view_wrapper
    return view_func(request, *args, **kwargs)
  File "/Users/sergeizeliabovskii/Documents/python_ptojects/DjangoProject/.venv/lib/python3.13/site-packages/django/views/generic/base.py", line 104, in view
    return self.dispatch(request, *args, **kwargs)
           ~~~~~~~~~~~~~^^^^^^^^^^^^^^^^^^^^^^^^^^
  File "/Users/sergeizeliabovskii/Documents/python_ptojects/DjangoProject/.venv/lib/python3.13/site-packages/rest_framework/views.py", line 515, in dispatch
    response = self.handle_exception(exc)
  File "/Users/sergeizeliabovskii/Documents/python_ptojects/DjangoProject/.venv/lib/python3.13/site-packages/rest_framework/views.py", line 475, in handle_exception
    self.raise_uncaught_exception(exc)
    ~~~~~~~~~~~~~~~~~~~~~~~~~~~~~^^^^^
  File "/Users/sergeizeliabovskii/Documents/python_ptojects/DjangoProject/.venv/lib/python3.13/site-packages/rest_framework/views.py", line 486, in raise_uncaught_exception
    raise exc
  File "/Users/sergeizeliabovskii/Documents/python_ptojects/DjangoProject/.venv/lib/python3.13/site-packages/rest_framework/views.py", line 512, in dispatch
    response = handler(request, *args, **kwargs)
  File "/Users/sergeizeliabovskii/Documents/python_ptojects/DjangoProject/.venv/lib/python3.13/site-packages/rest_framework/decorators.py", line 50, in handler
    return func(*args, **kwargs)
  File "/Users/sergeizeliabovskii/Documents/python_ptojects/DjangoProject/event/views.py", line 61, in trigger
    notification.send_notification()
    ^^^^^^^^^^^^^^^^^^^^^^^^^^^^^^
AttributeError: 'Notification' object has no attribute 'send_notification'
ERROR 2025-05-22 01:19:10,504 basehttp "GET /api/v1/event/trigger/2/ HTTP/1.1" 500 95481
ERROR 2025-05-22 01:50:53,426 log Internal Server Error: /api/v1/user/music/edit/2/
Traceback (most recent call last):
  File "/Users/sergeizeliabovskii/Documents/python_ptojects/DjangoProject/.venv/lib/python3.13/site-packages/django/core/handlers/exception.py", line 55, in inner
    response = get_response(request)
  File "/Users/sergeizeliabovskii/Documents/python_ptojects/DjangoProject/.venv/lib/python3.13/site-packages/django/core/handlers/base.py", line 197, in _get_response
    response = wrapped_callback(request, *callback_args, **callback_kwargs)
  File "/Users/sergeizeliabovskii/Documents/python_ptojects/DjangoProject/.venv/lib/python3.13/site-packages/django/views/decorators/csrf.py", line 65, in _view_wrapper
    return view_func(request, *args, **kwargs)
  File "/Users/sergeizeliabovskii/Documents/python_ptojects/DjangoProject/.venv/lib/python3.13/site-packages/django/views/generic/base.py", line 104, in view
    return self.dispatch(request, *args, **kwargs)
           ~~~~~~~~~~~~~^^^^^^^^^^^^^^^^^^^^^^^^^^
  File "/Users/sergeizeliabovskii/Documents/python_ptojects/DjangoProject/.venv/lib/python3.13/site-packages/rest_framework/views.py", line 517, in dispatch
    self.response = self.finalize_response(request, response, *args, **kwargs)
                    ~~~~~~~~~~~~~~~~~~~~~~^^^^^^^^^^^^^^^^^^^^^^^^^^^^^^^^^^^^
  File "/Users/sergeizeliabovskii/Documents/python_ptojects/DjangoProject/.venv/lib/python3.13/site-packages/rest_framework/views.py", line 429, in finalize_response
    assert isinstance(response, HttpResponseBase), (
           ~~~~~~~~~~^^^^^^^^^^^^^^^^^^^^^^^^^^^^
AssertionError: Expected a `Response`, `HttpResponse` or `StreamingHttpResponse` to be returned from the view, but received a `<class 'NoneType'>`
ERROR 2025-05-22 01:50:53,430 basehttp "POST /api/v1/user/music/edit/2/ HTTP/1.1" 500 75918
ERROR 2025-05-22 01:52:57,752 log Internal Server Error: /api/v1/event/trigger/2/
Traceback (most recent call last):
  File "/Users/sergeizeliabovskii/Documents/python_ptojects/DjangoProject/.venv/lib/python3.13/site-packages/django/db/backends/utils.py", line 105, in _execute
    return self.cursor.execute(sql, params)
           ~~~~~~~~~~~~~~~~~~~^^^^^^^^^^^^^
psycopg2.errors.UndefinedColumn: column main_userinfo.music_id does not exist
LINE 1: ...."military_status", "main_userinfo"."ptsd_level", "main_user...
                                                             ^
HINT:  Perhaps you meant to reference the column "main_userinfo.user_id".


The above exception was the direct cause of the following exception:

Traceback (most recent call last):
  File "/Users/sergeizeliabovskii/Documents/python_ptojects/DjangoProject/.venv/lib/python3.13/site-packages/django/core/handlers/exception.py", line 55, in inner
    response = get_response(request)
  File "/Users/sergeizeliabovskii/Documents/python_ptojects/DjangoProject/.venv/lib/python3.13/site-packages/django/core/handlers/base.py", line 197, in _get_response
    response = wrapped_callback(request, *callback_args, **callback_kwargs)
  File "/Users/sergeizeliabovskii/Documents/python_ptojects/DjangoProject/.venv/lib/python3.13/site-packages/django/views/decorators/csrf.py", line 65, in _view_wrapper
    return view_func(request, *args, **kwargs)
  File "/Users/sergeizeliabovskii/Documents/python_ptojects/DjangoProject/.venv/lib/python3.13/site-packages/django/views/generic/base.py", line 104, in view
    return self.dispatch(request, *args, **kwargs)
           ~~~~~~~~~~~~~^^^^^^^^^^^^^^^^^^^^^^^^^^
  File "/Users/sergeizeliabovskii/Documents/python_ptojects/DjangoProject/.venv/lib/python3.13/site-packages/rest_framework/views.py", line 515, in dispatch
    response = self.handle_exception(exc)
  File "/Users/sergeizeliabovskii/Documents/python_ptojects/DjangoProject/.venv/lib/python3.13/site-packages/rest_framework/views.py", line 475, in handle_exception
    self.raise_uncaught_exception(exc)
    ~~~~~~~~~~~~~~~~~~~~~~~~~~~~~^^^^^
  File "/Users/sergeizeliabovskii/Documents/python_ptojects/DjangoProject/.venv/lib/python3.13/site-packages/rest_framework/views.py", line 486, in raise_uncaught_exception
    raise exc
  File "/Users/sergeizeliabovskii/Documents/python_ptojects/DjangoProject/.venv/lib/python3.13/site-packages/rest_framework/views.py", line 512, in dispatch
    response = handler(request, *args, **kwargs)
  File "/Users/sergeizeliabovskii/Documents/python_ptojects/DjangoProject/.venv/lib/python3.13/site-packages/rest_framework/decorators.py", line 50, in handler
    return func(*args, **kwargs)
  File "/Users/sergeizeliabovskii/Documents/python_ptojects/DjangoProject/event/views.py", line 25, in trigger
    user_info = UserInfo.objects.get(user=user)
  File "/Users/sergeizeliabovskii/Documents/python_ptojects/DjangoProject/.venv/lib/python3.13/site-packages/django/db/models/manager.py", line 87, in manager_method
    return getattr(self.get_queryset(), name)(*args, **kwargs)
           ~~~~~~~~~~~~~~~~~~~~~~~~~~~~~~~~~~^^^^^^^^^^^^^^^^^
  File "/Users/sergeizeliabovskii/Documents/python_ptojects/DjangoProject/.venv/lib/python3.13/site-packages/django/db/models/query.py", line 629, in get
    num = len(clone)
  File "/Users/sergeizeliabovskii/Documents/python_ptojects/DjangoProject/.venv/lib/python3.13/site-packages/django/db/models/query.py", line 366, in __len__
    self._fetch_all()
    ~~~~~~~~~~~~~~~^^
  File "/Users/sergeizeliabovskii/Documents/python_ptojects/DjangoProject/.venv/lib/python3.13/site-packages/django/db/models/query.py", line 1945, in _fetch_all
    self._result_cache = list(self._iterable_class(self))
                         ~~~~^^^^^^^^^^^^^^^^^^^^^^^^^^^^
  File "/Users/sergeizeliabovskii/Documents/python_ptojects/DjangoProject/.venv/lib/python3.13/site-packages/django/db/models/query.py", line 91, in __iter__
    results = compiler.execute_sql(
        chunked_fetch=self.chunked_fetch, chunk_size=self.chunk_size
    )
  File "/Users/sergeizeliabovskii/Documents/python_ptojects/DjangoProject/.venv/lib/python3.13/site-packages/django/db/models/sql/compiler.py", line 1623, in execute_sql
    cursor.execute(sql, params)
    ~~~~~~~~~~~~~~^^^^^^^^^^^^^
  File "/Users/sergeizeliabovskii/Documents/python_ptojects/DjangoProject/.venv/lib/python3.13/site-packages/django/db/backends/utils.py", line 122, in execute
    return super().execute(sql, params)
           ~~~~~~~~~~~~~~~^^^^^^^^^^^^^
  File "/Users/sergeizeliabovskii/Documents/python_ptojects/DjangoProject/.venv/lib/python3.13/site-packages/django/db/backends/utils.py", line 79, in execute
    return self._execute_with_wrappers(
           ~~~~~~~~~~~~~~~~~~~~~~~~~~~^
        sql, params, many=False, executor=self._execute
        ^^^^^^^^^^^^^^^^^^^^^^^^^^^^^^^^^^^^^^^^^^^^^^^
    )
    ^
  File "/Users/sergeizeliabovskii/Documents/python_ptojects/DjangoProject/.venv/lib/python3.13/site-packages/django/db/backends/utils.py", line 92, in _execute_with_wrappers
    return executor(sql, params, many, context)
  File "/Users/sergeizeliabovskii/Documents/python_ptojects/DjangoProject/.venv/lib/python3.13/site-packages/django/db/backends/utils.py", line 100, in _execute
    with self.db.wrap_database_errors:
         ^^^^^^^^^^^^^^^^^^^^^^^^^^^^
  File "/Users/sergeizeliabovskii/Documents/python_ptojects/DjangoProject/.venv/lib/python3.13/site-packages/django/db/utils.py", line 91, in __exit__
    raise dj_exc_value.with_traceback(traceback) from exc_value
  File "/Users/sergeizeliabovskii/Documents/python_ptojects/DjangoProject/.venv/lib/python3.13/site-packages/django/db/backends/utils.py", line 105, in _execute
    return self.cursor.execute(sql, params)
           ~~~~~~~~~~~~~~~~~~~^^^^^^^^^^^^^
django.db.utils.ProgrammingError: column main_userinfo.music_id does not exist
LINE 1: ...."military_status", "main_userinfo"."ptsd_level", "main_user...
                                                             ^
HINT:  Perhaps you meant to reference the column "main_userinfo.user_id".

ERROR 2025-05-22 01:52:57,770 basehttp "GET /api/v1/event/trigger/2/ HTTP/1.1" 500 159417
ERROR 2025-05-22 01:54:47,559 log Internal Server Error: /api/v1/event/trigger/2/
Traceback (most recent call last):
  File "/Users/sergeizeliabovskii/Documents/python_ptojects/DjangoProject/.venv/lib/python3.13/site-packages/django/db/backends/utils.py", line 105, in _execute
    return self.cursor.execute(sql, params)
           ~~~~~~~~~~~~~~~~~~~^^^^^^^^^^^^^
psycopg2.errors.UndefinedColumn: column main_userinfo.music_id does not exist
LINE 1: ...."military_status", "main_userinfo"."ptsd_level", "main_user...
                                                             ^
HINT:  Perhaps you meant to reference the column "main_userinfo.user_id".


The above exception was the direct cause of the following exception:

Traceback (most recent call last):
  File "/Users/sergeizeliabovskii/Documents/python_ptojects/DjangoProject/.venv/lib/python3.13/site-packages/django/core/handlers/exception.py", line 55, in inner
    response = get_response(request)
  File "/Users/sergeizeliabovskii/Documents/python_ptojects/DjangoProject/.venv/lib/python3.13/site-packages/django/core/handlers/base.py", line 197, in _get_response
    response = wrapped_callback(request, *callback_args, **callback_kwargs)
  File "/Users/sergeizeliabovskii/Documents/python_ptojects/DjangoProject/.venv/lib/python3.13/site-packages/django/views/decorators/csrf.py", line 65, in _view_wrapper
    return view_func(request, *args, **kwargs)
  File "/Users/sergeizeliabovskii/Documents/python_ptojects/DjangoProject/.venv/lib/python3.13/site-packages/django/views/generic/base.py", line 104, in view
    return self.dispatch(request, *args, **kwargs)
           ~~~~~~~~~~~~~^^^^^^^^^^^^^^^^^^^^^^^^^^
  File "/Users/sergeizeliabovskii/Documents/python_ptojects/DjangoProject/.venv/lib/python3.13/site-packages/rest_framework/views.py", line 515, in dispatch
    response = self.handle_exception(exc)
  File "/Users/sergeizeliabovskii/Documents/python_ptojects/DjangoProject/.venv/lib/python3.13/site-packages/rest_framework/views.py", line 475, in handle_exception
    self.raise_uncaught_exception(exc)
    ~~~~~~~~~~~~~~~~~~~~~~~~~~~~~^^^^^
  File "/Users/sergeizeliabovskii/Documents/python_ptojects/DjangoProject/.venv/lib/python3.13/site-packages/rest_framework/views.py", line 486, in raise_uncaught_exception
    raise exc
  File "/Users/sergeizeliabovskii/Documents/python_ptojects/DjangoProject/.venv/lib/python3.13/site-packages/rest_framework/views.py", line 512, in dispatch
    response = handler(request, *args, **kwargs)
  File "/Users/sergeizeliabovskii/Documents/python_ptojects/DjangoProject/.venv/lib/python3.13/site-packages/rest_framework/decorators.py", line 50, in handler
    return func(*args, **kwargs)
  File "/Users/sergeizeliabovskii/Documents/python_ptojects/DjangoProject/event/views.py", line 25, in trigger
    user_info = UserInfo.objects.get(user=user)
  File "/Users/sergeizeliabovskii/Documents/python_ptojects/DjangoProject/.venv/lib/python3.13/site-packages/django/db/models/manager.py", line 87, in manager_method
    return getattr(self.get_queryset(), name)(*args, **kwargs)
           ~~~~~~~~~~~~~~~~~~~~~~~~~~~~~~~~~~^^^^^^^^^^^^^^^^^
  File "/Users/sergeizeliabovskii/Documents/python_ptojects/DjangoProject/.venv/lib/python3.13/site-packages/django/db/models/query.py", line 629, in get
    num = len(clone)
  File "/Users/sergeizeliabovskii/Documents/python_ptojects/DjangoProject/.venv/lib/python3.13/site-packages/django/db/models/query.py", line 366, in __len__
    self._fetch_all()
    ~~~~~~~~~~~~~~~^^
  File "/Users/sergeizeliabovskii/Documents/python_ptojects/DjangoProject/.venv/lib/python3.13/site-packages/django/db/models/query.py", line 1945, in _fetch_all
    self._result_cache = list(self._iterable_class(self))
                         ~~~~^^^^^^^^^^^^^^^^^^^^^^^^^^^^
  File "/Users/sergeizeliabovskii/Documents/python_ptojects/DjangoProject/.venv/lib/python3.13/site-packages/django/db/models/query.py", line 91, in __iter__
    results = compiler.execute_sql(
        chunked_fetch=self.chunked_fetch, chunk_size=self.chunk_size
    )
  File "/Users/sergeizeliabovskii/Documents/python_ptojects/DjangoProject/.venv/lib/python3.13/site-packages/django/db/models/sql/compiler.py", line 1623, in execute_sql
    cursor.execute(sql, params)
    ~~~~~~~~~~~~~~^^^^^^^^^^^^^
  File "/Users/sergeizeliabovskii/Documents/python_ptojects/DjangoProject/.venv/lib/python3.13/site-packages/django/db/backends/utils.py", line 122, in execute
    return super().execute(sql, params)
           ~~~~~~~~~~~~~~~^^^^^^^^^^^^^
  File "/Users/sergeizeliabovskii/Documents/python_ptojects/DjangoProject/.venv/lib/python3.13/site-packages/django/db/backends/utils.py", line 79, in execute
    return self._execute_with_wrappers(
           ~~~~~~~~~~~~~~~~~~~~~~~~~~~^
        sql, params, many=False, executor=self._execute
        ^^^^^^^^^^^^^^^^^^^^^^^^^^^^^^^^^^^^^^^^^^^^^^^
    )
    ^
  File "/Users/sergeizeliabovskii/Documents/python_ptojects/DjangoProject/.venv/lib/python3.13/site-packages/django/db/backends/utils.py", line 92, in _execute_with_wrappers
    return executor(sql, params, many, context)
  File "/Users/sergeizeliabovskii/Documents/python_ptojects/DjangoProject/.venv/lib/python3.13/site-packages/django/db/backends/utils.py", line 100, in _execute
    with self.db.wrap_database_errors:
         ^^^^^^^^^^^^^^^^^^^^^^^^^^^^
  File "/Users/sergeizeliabovskii/Documents/python_ptojects/DjangoProject/.venv/lib/python3.13/site-packages/django/db/utils.py", line 91, in __exit__
    raise dj_exc_value.with_traceback(traceback) from exc_value
  File "/Users/sergeizeliabovskii/Documents/python_ptojects/DjangoProject/.venv/lib/python3.13/site-packages/django/db/backends/utils.py", line 105, in _execute
    return self.cursor.execute(sql, params)
           ~~~~~~~~~~~~~~~~~~~^^^^^^^^^^^^^
django.db.utils.ProgrammingError: column main_userinfo.music_id does not exist
LINE 1: ...."military_status", "main_userinfo"."ptsd_level", "main_user...
                                                             ^
HINT:  Perhaps you meant to reference the column "main_userinfo.user_id".

ERROR 2025-05-22 01:54:47,574 basehttp "GET /api/v1/event/trigger/2/ HTTP/1.1" 500 159417
ERROR 2025-05-22 02:02:08,418 log Internal Server Error: /api/v1/user/registration
Traceback (most recent call last):
  File "/Users/sergeizeliabovskii/Documents/python_ptojects/DjangoProject/.venv/lib/python3.13/site-packages/django/core/handlers/exception.py", line 55, in inner
    response = get_response(request)
  File "/Users/sergeizeliabovskii/Documents/python_ptojects/DjangoProject/.venv/lib/python3.13/site-packages/django/utils/deprecation.py", line 122, in __call__
    response = self.process_response(request, response)
  File "/Users/sergeizeliabovskii/Documents/python_ptojects/DjangoProject/.venv/lib/python3.13/site-packages/django/middleware/common.py", line 108, in process_response
    return self.response_redirect_class(self.get_full_path_with_slash(request))
                                        ~~~~~~~~~~~~~~~~~~~~~~~~~~~~~^^^^^^^^^
  File "/Users/sergeizeliabovskii/Documents/python_ptojects/DjangoProject/.venv/lib/python3.13/site-packages/django/middleware/common.py", line 87, in get_full_path_with_slash
    raise RuntimeError(
    ...<9 lines>...
    )
RuntimeError: You called this URL via POST, but the URL doesn't end in a slash and you have APPEND_SLASH set. Django can't redirect to the slash URL while maintaining POST data. Change your form to point to 127.0.0.1:8000/api/v1/user/registration/ (note the trailing slash), or set APPEND_SLASH=False in your Django settings.
ERROR 2025-05-22 02:02:08,421 basehttp "POST /api/v1/user/registration HTTP/1.1" 500 66412
ERROR 2025-05-22 02:02:51,022 log Internal Server Error: /api/v1/user/edit/1
Traceback (most recent call last):
  File "/Users/sergeizeliabovskii/Documents/python_ptojects/DjangoProject/.venv/lib/python3.13/site-packages/django/core/handlers/exception.py", line 55, in inner
    response = get_response(request)
  File "/Users/sergeizeliabovskii/Documents/python_ptojects/DjangoProject/.venv/lib/python3.13/site-packages/django/utils/deprecation.py", line 122, in __call__
    response = self.process_response(request, response)
  File "/Users/sergeizeliabovskii/Documents/python_ptojects/DjangoProject/.venv/lib/python3.13/site-packages/django/middleware/common.py", line 108, in process_response
    return self.response_redirect_class(self.get_full_path_with_slash(request))
                                        ~~~~~~~~~~~~~~~~~~~~~~~~~~~~~^^^^^^^^^
  File "/Users/sergeizeliabovskii/Documents/python_ptojects/DjangoProject/.venv/lib/python3.13/site-packages/django/middleware/common.py", line 87, in get_full_path_with_slash
    raise RuntimeError(
    ...<9 lines>...
    )
RuntimeError: You called this URL via PATCH, but the URL doesn't end in a slash and you have APPEND_SLASH set. Django can't redirect to the slash URL while maintaining PATCH data. Change your form to point to 127.0.0.1:8000/api/v1/user/edit/1/ (note the trailing slash), or set APPEND_SLASH=False in your Django settings.
ERROR 2025-05-22 02:02:51,024 basehttp "PATCH /api/v1/user/edit/1 HTTP/1.1" 500 66331
ERROR 2025-05-22 02:03:46,334 log Internal Server Error: /api/v1/user/music/edit/1/
Traceback (most recent call last):
  File "/Users/sergeizeliabovskii/Documents/python_ptojects/DjangoProject/.venv/lib/python3.13/site-packages/django/core/handlers/exception.py", line 55, in inner
    response = get_response(request)
  File "/Users/sergeizeliabovskii/Documents/python_ptojects/DjangoProject/.venv/lib/python3.13/site-packages/django/core/handlers/base.py", line 197, in _get_response
    response = wrapped_callback(request, *callback_args, **callback_kwargs)
  File "/Users/sergeizeliabovskii/Documents/python_ptojects/DjangoProject/.venv/lib/python3.13/site-packages/django/views/decorators/csrf.py", line 65, in _view_wrapper
    return view_func(request, *args, **kwargs)
  File "/Users/sergeizeliabovskii/Documents/python_ptojects/DjangoProject/.venv/lib/python3.13/site-packages/django/views/generic/base.py", line 104, in view
    return self.dispatch(request, *args, **kwargs)
           ~~~~~~~~~~~~~^^^^^^^^^^^^^^^^^^^^^^^^^^
  File "/Users/sergeizeliabovskii/Documents/python_ptojects/DjangoProject/.venv/lib/python3.13/site-packages/rest_framework/views.py", line 517, in dispatch
    self.response = self.finalize_response(request, response, *args, **kwargs)
                    ~~~~~~~~~~~~~~~~~~~~~~^^^^^^^^^^^^^^^^^^^^^^^^^^^^^^^^^^^^
  File "/Users/sergeizeliabovskii/Documents/python_ptojects/DjangoProject/.venv/lib/python3.13/site-packages/rest_framework/views.py", line 429, in finalize_response
    assert isinstance(response, HttpResponseBase), (
           ~~~~~~~~~~^^^^^^^^^^^^^^^^^^^^^^^^^^^^
AssertionError: Expected a `Response`, `HttpResponse` or `StreamingHttpResponse` to be returned from the view, but received a `<class 'NoneType'>`
ERROR 2025-05-22 02:03:46,340 basehttp "POST /api/v1/user/music/edit/1/ HTTP/1.1" 500 75918
ERROR 2025-05-22 02:06:31,751 log Internal Server Error: /api/v1/user/music/edit/1/
Traceback (most recent call last):
  File "/Users/sergeizeliabovskii/Documents/python_ptojects/DjangoProject/.venv/lib/python3.13/site-packages/django/core/handlers/exception.py", line 55, in inner
    response = get_response(request)
  File "/Users/sergeizeliabovskii/Documents/python_ptojects/DjangoProject/.venv/lib/python3.13/site-packages/django/core/handlers/base.py", line 197, in _get_response
    response = wrapped_callback(request, *callback_args, **callback_kwargs)
  File "/Users/sergeizeliabovskii/Documents/python_ptojects/DjangoProject/.venv/lib/python3.13/site-packages/django/views/decorators/csrf.py", line 65, in _view_wrapper
    return view_func(request, *args, **kwargs)
  File "/Users/sergeizeliabovskii/Documents/python_ptojects/DjangoProject/.venv/lib/python3.13/site-packages/django/views/generic/base.py", line 104, in view
    return self.dispatch(request, *args, **kwargs)
           ~~~~~~~~~~~~~^^^^^^^^^^^^^^^^^^^^^^^^^^
  File "/Users/sergeizeliabovskii/Documents/python_ptojects/DjangoProject/.venv/lib/python3.13/site-packages/rest_framework/views.py", line 517, in dispatch
    self.response = self.finalize_response(request, response, *args, **kwargs)
                    ~~~~~~~~~~~~~~~~~~~~~~^^^^^^^^^^^^^^^^^^^^^^^^^^^^^^^^^^^^
  File "/Users/sergeizeliabovskii/Documents/python_ptojects/DjangoProject/.venv/lib/python3.13/site-packages/rest_framework/views.py", line 429, in finalize_response
    assert isinstance(response, HttpResponseBase), (
           ~~~~~~~~~~^^^^^^^^^^^^^^^^^^^^^^^^^^^^
AssertionError: Expected a `Response`, `HttpResponse` or `StreamingHttpResponse` to be returned from the view, but received a `<class 'NoneType'>`
ERROR 2025-05-22 02:06:31,753 basehttp "POST /api/v1/user/music/edit/1/ HTTP/1.1" 500 75918
ERROR 2025-05-22 02:10:49,131 log Internal Server Error: /api/v1/event/trigger/2/
Traceback (most recent call last):
  File "/Users/sergeizeliabovskii/Documents/python_ptojects/DjangoProject/.venv/lib/python3.13/site-packages/django/core/handlers/exception.py", line 55, in inner
    response = get_response(request)
  File "/Users/sergeizeliabovskii/Documents/python_ptojects/DjangoProject/.venv/lib/python3.13/site-packages/django/core/handlers/base.py", line 197, in _get_response
    response = wrapped_callback(request, *callback_args, **callback_kwargs)
  File "/Users/sergeizeliabovskii/Documents/python_ptojects/DjangoProject/.venv/lib/python3.13/site-packages/django/views/decorators/csrf.py", line 65, in _view_wrapper
    return view_func(request, *args, **kwargs)
  File "/Users/sergeizeliabovskii/Documents/python_ptojects/DjangoProject/.venv/lib/python3.13/site-packages/django/views/generic/base.py", line 104, in view
    return self.dispatch(request, *args, **kwargs)
           ~~~~~~~~~~~~~^^^^^^^^^^^^^^^^^^^^^^^^^^
  File "/Users/sergeizeliabovskii/Documents/python_ptojects/DjangoProject/.venv/lib/python3.13/site-packages/rest_framework/views.py", line 515, in dispatch
    response = self.handle_exception(exc)
  File "/Users/sergeizeliabovskii/Documents/python_ptojects/DjangoProject/.venv/lib/python3.13/site-packages/rest_framework/views.py", line 475, in handle_exception
    self.raise_uncaught_exception(exc)
    ~~~~~~~~~~~~~~~~~~~~~~~~~~~~~^^^^^
  File "/Users/sergeizeliabovskii/Documents/python_ptojects/DjangoProject/.venv/lib/python3.13/site-packages/rest_framework/views.py", line 486, in raise_uncaught_exception
    raise exc
  File "/Users/sergeizeliabovskii/Documents/python_ptojects/DjangoProject/.venv/lib/python3.13/site-packages/rest_framework/views.py", line 512, in dispatch
    response = handler(request, *args, **kwargs)
  File "/Users/sergeizeliabovskii/Documents/python_ptojects/DjangoProject/.venv/lib/python3.13/site-packages/rest_framework/decorators.py", line 50, in handler
    return func(*args, **kwargs)
  File "/Users/sergeizeliabovskii/Documents/python_ptojects/DjangoProject/event/views.py", line 40, in trigger
    if scenario.play_music and user_info.preferred_music:
                               ^^^^^^^^^^^^^^^^^^^^^^^^^
AttributeError: 'UserInfo' object has no attribute 'preferred_music'
ERROR 2025-05-22 02:10:49,147 basehttp "GET /api/v1/event/trigger/2/ HTTP/1.1" 500 93650
DEBUG 2025-05-27 02:10:49,614 base Exception while resolving variable 'name' in template 'unknown'.
Traceback (most recent call last):
  File "/Users/sergeizeliabovskii/Documents/python_ptojects/DjangoProject/.venv/lib/python3.13/site-packages/asgiref/sync.py", line 518, in thread_handler
    raise exc_info[1]
  File "/Users/sergeizeliabovskii/Documents/python_ptojects/DjangoProject/.venv/lib/python3.13/site-packages/django/core/handlers/exception.py", line 42, in inner
    response = await get_response(request)
               ^^^^^^^^^^^^^^^^^^^^^^^^^^^
  File "/Users/sergeizeliabovskii/Documents/python_ptojects/DjangoProject/.venv/lib/python3.13/site-packages/django/core/handlers/base.py", line 235, in _get_response_async
    callback, callback_args, callback_kwargs = self.resolve_request(request)
                                               ~~~~~~~~~~~~~~~~~~~~^^^^^^^^^
  File "/Users/sergeizeliabovskii/Documents/python_ptojects/DjangoProject/.venv/lib/python3.13/site-packages/django/core/handlers/base.py", line 313, in resolve_request
    resolver_match = resolver.resolve(request.path_info)
  File "/Users/sergeizeliabovskii/Documents/python_ptojects/DjangoProject/.venv/lib/python3.13/site-packages/django/urls/resolvers.py", line 705, in resolve
    raise Resolver404({"tried": tried, "path": new_path})
django.urls.exceptions.Resolver404: {'tried': [[<URLResolver <URLPattern list> (admin:admin) 'admin/'>], [<URLResolver <module 'main.urls' from '/Users/sergeizeliabovskii/Documents/python_ptojects/DjangoProject/main/urls.py'> (None:None) 'api/v1/user/'>], [<URLResolver <module 'event.urls' from '/Users/sergeizeliabovskii/Documents/python_ptojects/DjangoProject/event/urls.py'> (None:None) 'api/v1/event/'>], [<URLResolver <module 'chat.urls' from '/Users/sergeizeliabovskii/Documents/python_ptojects/DjangoProject/chat/urls.py'> (None:None) 'api/v1/chat/'>]], 'path': 'user/login/'}

During handling of the above exception, another exception occurred:

Traceback (most recent call last):
  File "/Users/sergeizeliabovskii/Documents/python_ptojects/DjangoProject/.venv/lib/python3.13/site-packages/django/template/base.py", line 890, in _resolve_lookup
    raise TypeError
TypeError

During handling of the above exception, another exception occurred:

Traceback (most recent call last):
  File "/Users/sergeizeliabovskii/Documents/python_ptojects/DjangoProject/.venv/lib/python3.13/site-packages/django/template/base.py", line 901, in _resolve_lookup
    current = getattr(current, bit)
AttributeError: 'URLResolver' object has no attribute 'name'

During handling of the above exception, another exception occurred:

Traceback (most recent call last):
  File "/Users/sergeizeliabovskii/Documents/python_ptojects/DjangoProject/.venv/lib/python3.13/site-packages/django/template/base.py", line 907, in _resolve_lookup
    current = current[int(bit)]
                      ~~~^^^^^
ValueError: invalid literal for int() with base 10: 'name'

During handling of the above exception, another exception occurred:

Traceback (most recent call last):
  File "/Users/sergeizeliabovskii/Documents/python_ptojects/DjangoProject/.venv/lib/python3.13/site-packages/django/template/base.py", line 914, in _resolve_lookup
    raise VariableDoesNotExist(
    ^^^^^^^^^^^^^^^^^^^^^^^^^^^
    ...<2 lines>...
    )  # missing attribute
    ^
django.template.base.VariableDoesNotExist: Failed lookup for key [name] in <URLResolver <URLPattern list> (admin:admin) 'admin/'>
DEBUG 2025-05-27 02:10:49,620 base Exception while resolving variable 'name' in template 'unknown'.
Traceback (most recent call last):
  File "/Users/sergeizeliabovskii/Documents/python_ptojects/DjangoProject/.venv/lib/python3.13/site-packages/asgiref/sync.py", line 518, in thread_handler
    raise exc_info[1]
  File "/Users/sergeizeliabovskii/Documents/python_ptojects/DjangoProject/.venv/lib/python3.13/site-packages/django/core/handlers/exception.py", line 42, in inner
    response = await get_response(request)
               ^^^^^^^^^^^^^^^^^^^^^^^^^^^
  File "/Users/sergeizeliabovskii/Documents/python_ptojects/DjangoProject/.venv/lib/python3.13/site-packages/django/core/handlers/base.py", line 235, in _get_response_async
    callback, callback_args, callback_kwargs = self.resolve_request(request)
                                               ~~~~~~~~~~~~~~~~~~~~^^^^^^^^^
  File "/Users/sergeizeliabovskii/Documents/python_ptojects/DjangoProject/.venv/lib/python3.13/site-packages/django/core/handlers/base.py", line 313, in resolve_request
    resolver_match = resolver.resolve(request.path_info)
  File "/Users/sergeizeliabovskii/Documents/python_ptojects/DjangoProject/.venv/lib/python3.13/site-packages/django/urls/resolvers.py", line 705, in resolve
    raise Resolver404({"tried": tried, "path": new_path})
django.urls.exceptions.Resolver404: {'tried': [[<URLResolver <URLPattern list> (admin:admin) 'admin/'>], [<URLResolver <module 'main.urls' from '/Users/sergeizeliabovskii/Documents/python_ptojects/DjangoProject/main/urls.py'> (None:None) 'api/v1/user/'>], [<URLResolver <module 'event.urls' from '/Users/sergeizeliabovskii/Documents/python_ptojects/DjangoProject/event/urls.py'> (None:None) 'api/v1/event/'>], [<URLResolver <module 'chat.urls' from '/Users/sergeizeliabovskii/Documents/python_ptojects/DjangoProject/chat/urls.py'> (None:None) 'api/v1/chat/'>]], 'path': 'user/login/'}

During handling of the above exception, another exception occurred:

Traceback (most recent call last):
  File "/Users/sergeizeliabovskii/Documents/python_ptojects/DjangoProject/.venv/lib/python3.13/site-packages/django/template/base.py", line 890, in _resolve_lookup
    raise TypeError
TypeError

During handling of the above exception, another exception occurred:

Traceback (most recent call last):
  File "/Users/sergeizeliabovskii/Documents/python_ptojects/DjangoProject/.venv/lib/python3.13/site-packages/django/template/base.py", line 901, in _resolve_lookup
    current = getattr(current, bit)
AttributeError: 'URLResolver' object has no attribute 'name'

During handling of the above exception, another exception occurred:

Traceback (most recent call last):
  File "/Users/sergeizeliabovskii/Documents/python_ptojects/DjangoProject/.venv/lib/python3.13/site-packages/django/template/base.py", line 907, in _resolve_lookup
    current = current[int(bit)]
                      ~~~^^^^^
ValueError: invalid literal for int() with base 10: 'name'

During handling of the above exception, another exception occurred:

Traceback (most recent call last):
  File "/Users/sergeizeliabovskii/Documents/python_ptojects/DjangoProject/.venv/lib/python3.13/site-packages/django/template/base.py", line 914, in _resolve_lookup
    raise VariableDoesNotExist(
    ^^^^^^^^^^^^^^^^^^^^^^^^^^^
    ...<2 lines>...
    )  # missing attribute
    ^
django.template.base.VariableDoesNotExist: Failed lookup for key [name] in <URLResolver <module 'main.urls' from '/Users/sergeizeliabovskii/Documents/python_ptojects/DjangoProject/main/urls.py'> (None:None) 'api/v1/user/'>
DEBUG 2025-05-27 02:10:49,623 base Exception while resolving variable 'name' in template 'unknown'.
Traceback (most recent call last):
  File "/Users/sergeizeliabovskii/Documents/python_ptojects/DjangoProject/.venv/lib/python3.13/site-packages/asgiref/sync.py", line 518, in thread_handler
    raise exc_info[1]
  File "/Users/sergeizeliabovskii/Documents/python_ptojects/DjangoProject/.venv/lib/python3.13/site-packages/django/core/handlers/exception.py", line 42, in inner
    response = await get_response(request)
               ^^^^^^^^^^^^^^^^^^^^^^^^^^^
  File "/Users/sergeizeliabovskii/Documents/python_ptojects/DjangoProject/.venv/lib/python3.13/site-packages/django/core/handlers/base.py", line 235, in _get_response_async
    callback, callback_args, callback_kwargs = self.resolve_request(request)
                                               ~~~~~~~~~~~~~~~~~~~~^^^^^^^^^
  File "/Users/sergeizeliabovskii/Documents/python_ptojects/DjangoProject/.venv/lib/python3.13/site-packages/django/core/handlers/base.py", line 313, in resolve_request
    resolver_match = resolver.resolve(request.path_info)
  File "/Users/sergeizeliabovskii/Documents/python_ptojects/DjangoProject/.venv/lib/python3.13/site-packages/django/urls/resolvers.py", line 705, in resolve
    raise Resolver404({"tried": tried, "path": new_path})
django.urls.exceptions.Resolver404: {'tried': [[<URLResolver <URLPattern list> (admin:admin) 'admin/'>], [<URLResolver <module 'main.urls' from '/Users/sergeizeliabovskii/Documents/python_ptojects/DjangoProject/main/urls.py'> (None:None) 'api/v1/user/'>], [<URLResolver <module 'event.urls' from '/Users/sergeizeliabovskii/Documents/python_ptojects/DjangoProject/event/urls.py'> (None:None) 'api/v1/event/'>], [<URLResolver <module 'chat.urls' from '/Users/sergeizeliabovskii/Documents/python_ptojects/DjangoProject/chat/urls.py'> (None:None) 'api/v1/chat/'>]], 'path': 'user/login/'}

During handling of the above exception, another exception occurred:

Traceback (most recent call last):
  File "/Users/sergeizeliabovskii/Documents/python_ptojects/DjangoProject/.venv/lib/python3.13/site-packages/django/template/base.py", line 890, in _resolve_lookup
    raise TypeError
TypeError

During handling of the above exception, another exception occurred:

Traceback (most recent call last):
  File "/Users/sergeizeliabovskii/Documents/python_ptojects/DjangoProject/.venv/lib/python3.13/site-packages/django/template/base.py", line 901, in _resolve_lookup
    current = getattr(current, bit)
AttributeError: 'URLResolver' object has no attribute 'name'

During handling of the above exception, another exception occurred:

Traceback (most recent call last):
  File "/Users/sergeizeliabovskii/Documents/python_ptojects/DjangoProject/.venv/lib/python3.13/site-packages/django/template/base.py", line 907, in _resolve_lookup
    current = current[int(bit)]
                      ~~~^^^^^
ValueError: invalid literal for int() with base 10: 'name'

During handling of the above exception, another exception occurred:

Traceback (most recent call last):
  File "/Users/sergeizeliabovskii/Documents/python_ptojects/DjangoProject/.venv/lib/python3.13/site-packages/django/template/base.py", line 914, in _resolve_lookup
    raise VariableDoesNotExist(
    ^^^^^^^^^^^^^^^^^^^^^^^^^^^
    ...<2 lines>...
    )  # missing attribute
    ^
django.template.base.VariableDoesNotExist: Failed lookup for key [name] in <URLResolver <module 'event.urls' from '/Users/sergeizeliabovskii/Documents/python_ptojects/DjangoProject/event/urls.py'> (None:None) 'api/v1/event/'>
DEBUG 2025-05-27 02:10:49,626 base Exception while resolving variable 'name' in template 'unknown'.
Traceback (most recent call last):
  File "/Users/sergeizeliabovskii/Documents/python_ptojects/DjangoProject/.venv/lib/python3.13/site-packages/asgiref/sync.py", line 518, in thread_handler
    raise exc_info[1]
  File "/Users/sergeizeliabovskii/Documents/python_ptojects/DjangoProject/.venv/lib/python3.13/site-packages/django/core/handlers/exception.py", line 42, in inner
    response = await get_response(request)
               ^^^^^^^^^^^^^^^^^^^^^^^^^^^
  File "/Users/sergeizeliabovskii/Documents/python_ptojects/DjangoProject/.venv/lib/python3.13/site-packages/django/core/handlers/base.py", line 235, in _get_response_async
    callback, callback_args, callback_kwargs = self.resolve_request(request)
                                               ~~~~~~~~~~~~~~~~~~~~^^^^^^^^^
  File "/Users/sergeizeliabovskii/Documents/python_ptojects/DjangoProject/.venv/lib/python3.13/site-packages/django/core/handlers/base.py", line 313, in resolve_request
    resolver_match = resolver.resolve(request.path_info)
  File "/Users/sergeizeliabovskii/Documents/python_ptojects/DjangoProject/.venv/lib/python3.13/site-packages/django/urls/resolvers.py", line 705, in resolve
    raise Resolver404({"tried": tried, "path": new_path})
django.urls.exceptions.Resolver404: {'tried': [[<URLResolver <URLPattern list> (admin:admin) 'admin/'>], [<URLResolver <module 'main.urls' from '/Users/sergeizeliabovskii/Documents/python_ptojects/DjangoProject/main/urls.py'> (None:None) 'api/v1/user/'>], [<URLResolver <module 'event.urls' from '/Users/sergeizeliabovskii/Documents/python_ptojects/DjangoProject/event/urls.py'> (None:None) 'api/v1/event/'>], [<URLResolver <module 'chat.urls' from '/Users/sergeizeliabovskii/Documents/python_ptojects/DjangoProject/chat/urls.py'> (None:None) 'api/v1/chat/'>]], 'path': 'user/login/'}

During handling of the above exception, another exception occurred:

Traceback (most recent call last):
  File "/Users/sergeizeliabovskii/Documents/python_ptojects/DjangoProject/.venv/lib/python3.13/site-packages/django/template/base.py", line 890, in _resolve_lookup
    raise TypeError
TypeError

During handling of the above exception, another exception occurred:

Traceback (most recent call last):
  File "/Users/sergeizeliabovskii/Documents/python_ptojects/DjangoProject/.venv/lib/python3.13/site-packages/django/template/base.py", line 901, in _resolve_lookup
    current = getattr(current, bit)
AttributeError: 'URLResolver' object has no attribute 'name'

During handling of the above exception, another exception occurred:

Traceback (most recent call last):
  File "/Users/sergeizeliabovskii/Documents/python_ptojects/DjangoProject/.venv/lib/python3.13/site-packages/django/template/base.py", line 907, in _resolve_lookup
    current = current[int(bit)]
                      ~~~^^^^^
ValueError: invalid literal for int() with base 10: 'name'

During handling of the above exception, another exception occurred:

Traceback (most recent call last):
  File "/Users/sergeizeliabovskii/Documents/python_ptojects/DjangoProject/.venv/lib/python3.13/site-packages/django/template/base.py", line 914, in _resolve_lookup
    raise VariableDoesNotExist(
    ^^^^^^^^^^^^^^^^^^^^^^^^^^^
    ...<2 lines>...
    )  # missing attribute
    ^
django.template.base.VariableDoesNotExist: Failed lookup for key [name] in <URLResolver <module 'chat.urls' from '/Users/sergeizeliabovskii/Documents/python_ptojects/DjangoProject/chat/urls.py'> (None:None) 'api/v1/chat/'>
WARNING 2025-05-27 02:10:49,629 log Not Found: /user/login/
DEBUG 2025-05-27 02:11:39,047 utils (0.000) BEGIN; args=None; alias=default
DEBUG 2025-05-27 02:11:39,052 utils (0.001) SELECT "auth_user"."id", "auth_user"."password", "auth_user"."last_login", "auth_user"."is_superuser", "auth_user"."username", "auth_user"."first_name", "auth_user"."last_name", "auth_user"."email", "auth_user"."is_staff", "auth_user"."is_active", "auth_user"."date_joined" FROM "auth_user" WHERE "auth_user"."username" = 'admin' LIMIT 21; args=('admin',); alias=default
DEBUG 2025-05-27 02:11:39,274 utils (0.004) SELECT "authtoken_token"."key", "authtoken_token"."user_id", "authtoken_token"."created" FROM "authtoken_token" WHERE "authtoken_token"."user_id" = 1 LIMIT 21; args=(1,); alias=default
DEBUG 2025-05-27 02:11:39,275 utils (0.000) SAVEPOINT "s6188363776_x1"; args=None; alias=default
DEBUG 2025-05-27 02:11:39,277 utils (0.002) INSERT INTO "authtoken_token" ("key", "user_id", "created") VALUES ('889e10d16483c21f9b775f9bf98ecff96f7af71c', 1, '2025-05-27T02:11:39.275819+00:00'::timestamptz); args=('889e10d16483c21f9b775f9bf98ecff96f7af71c', 1, datetime.datetime(2025, 5, 27, 2, 11, 39, 275819, tzinfo=datetime.timezone.utc)); alias=default
DEBUG 2025-05-27 02:11:39,277 utils (0.000) RELEASE SAVEPOINT "s6188363776_x1"; args=None; alias=default
DEBUG 2025-05-27 02:11:39,279 utils (0.001) COMMIT; args=None; alias=default
DEBUG 2025-05-27 02:12:30,745 utils (0.000) BEGIN; args=None; alias=default
DEBUG 2025-05-27 02:12:30,749 utils (0.002) SELECT "auth_user"."id", "auth_user"."password", "auth_user"."last_login", "auth_user"."is_superuser", "auth_user"."username", "auth_user"."first_name", "auth_user"."last_name", "auth_user"."email", "auth_user"."is_staff", "auth_user"."is_active", "auth_user"."date_joined" FROM "auth_user" WHERE "auth_user"."username" = 'admin' LIMIT 21; args=('admin',); alias=default
DEBUG 2025-05-27 02:12:30,987 utils (0.004) SELECT "authtoken_token"."key", "authtoken_token"."user_id", "authtoken_token"."created" FROM "authtoken_token" WHERE "authtoken_token"."user_id" = 1 LIMIT 21; args=(1,); alias=default
DEBUG 2025-05-27 02:12:30,988 utils (0.000) COMMIT; args=None; alias=default
DEBUG 2025-05-27 02:13:04,633 base Exception while resolving variable 'name' in template 'unknown'.
Traceback (most recent call last):
  File "/Users/sergeizeliabovskii/Documents/python_ptojects/DjangoProject/.venv/lib/python3.13/site-packages/asgiref/sync.py", line 518, in thread_handler
    raise exc_info[1]
  File "/Users/sergeizeliabovskii/Documents/python_ptojects/DjangoProject/.venv/lib/python3.13/site-packages/django/core/handlers/exception.py", line 42, in inner
    response = await get_response(request)
               ^^^^^^^^^^^^^^^^^^^^^^^^^^^
  File "/Users/sergeizeliabovskii/Documents/python_ptojects/DjangoProject/.venv/lib/python3.13/site-packages/django/core/handlers/base.py", line 235, in _get_response_async
    callback, callback_args, callback_kwargs = self.resolve_request(request)
                                               ~~~~~~~~~~~~~~~~~~~~^^^^^^^^^
  File "/Users/sergeizeliabovskii/Documents/python_ptojects/DjangoProject/.venv/lib/python3.13/site-packages/django/core/handlers/base.py", line 313, in resolve_request
    resolver_match = resolver.resolve(request.path_info)
  File "/Users/sergeizeliabovskii/Documents/python_ptojects/DjangoProject/.venv/lib/python3.13/site-packages/django/urls/resolvers.py", line 705, in resolve
    raise Resolver404({"tried": tried, "path": new_path})
django.urls.exceptions.Resolver404: {'tried': [[<URLResolver <URLPattern list> (admin:admin) 'admin/'>], [<URLResolver <module 'main.urls' from '/Users/sergeizeliabovskii/Documents/python_ptojects/DjangoProject/main/urls.py'> (None:None) 'api/v1/user/'>], [<URLResolver <module 'event.urls' from '/Users/sergeizeliabovskii/Documents/python_ptojects/DjangoProject/event/urls.py'> (None:None) 'api/v1/event/'>, <URLPattern 'trigger/<int:user_id>/' [name='alarm']>], [<URLResolver <module 'chat.urls' from '/Users/sergeizeliabovskii/Documents/python_ptojects/DjangoProject/chat/urls.py'> (None:None) 'api/v1/chat/'>]], 'path': 'api/v1/event/1'}

During handling of the above exception, another exception occurred:

Traceback (most recent call last):
  File "/Users/sergeizeliabovskii/Documents/python_ptojects/DjangoProject/.venv/lib/python3.13/site-packages/django/template/base.py", line 890, in _resolve_lookup
    raise TypeError
TypeError

During handling of the above exception, another exception occurred:

Traceback (most recent call last):
  File "/Users/sergeizeliabovskii/Documents/python_ptojects/DjangoProject/.venv/lib/python3.13/site-packages/django/template/base.py", line 901, in _resolve_lookup
    current = getattr(current, bit)
AttributeError: 'URLResolver' object has no attribute 'name'

During handling of the above exception, another exception occurred:

Traceback (most recent call last):
  File "/Users/sergeizeliabovskii/Documents/python_ptojects/DjangoProject/.venv/lib/python3.13/site-packages/django/template/base.py", line 907, in _resolve_lookup
    current = current[int(bit)]
                      ~~~^^^^^
ValueError: invalid literal for int() with base 10: 'name'

During handling of the above exception, another exception occurred:

Traceback (most recent call last):
  File "/Users/sergeizeliabovskii/Documents/python_ptojects/DjangoProject/.venv/lib/python3.13/site-packages/django/template/base.py", line 914, in _resolve_lookup
    raise VariableDoesNotExist(
    ^^^^^^^^^^^^^^^^^^^^^^^^^^^
    ...<2 lines>...
    )  # missing attribute
    ^
django.template.base.VariableDoesNotExist: Failed lookup for key [name] in <URLResolver <URLPattern list> (admin:admin) 'admin/'>
DEBUG 2025-05-27 02:13:04,641 base Exception while resolving variable 'name' in template 'unknown'.
Traceback (most recent call last):
  File "/Users/sergeizeliabovskii/Documents/python_ptojects/DjangoProject/.venv/lib/python3.13/site-packages/asgiref/sync.py", line 518, in thread_handler
    raise exc_info[1]
  File "/Users/sergeizeliabovskii/Documents/python_ptojects/DjangoProject/.venv/lib/python3.13/site-packages/django/core/handlers/exception.py", line 42, in inner
    response = await get_response(request)
               ^^^^^^^^^^^^^^^^^^^^^^^^^^^
  File "/Users/sergeizeliabovskii/Documents/python_ptojects/DjangoProject/.venv/lib/python3.13/site-packages/django/core/handlers/base.py", line 235, in _get_response_async
    callback, callback_args, callback_kwargs = self.resolve_request(request)
                                               ~~~~~~~~~~~~~~~~~~~~^^^^^^^^^
  File "/Users/sergeizeliabovskii/Documents/python_ptojects/DjangoProject/.venv/lib/python3.13/site-packages/django/core/handlers/base.py", line 313, in resolve_request
    resolver_match = resolver.resolve(request.path_info)
  File "/Users/sergeizeliabovskii/Documents/python_ptojects/DjangoProject/.venv/lib/python3.13/site-packages/django/urls/resolvers.py", line 705, in resolve
    raise Resolver404({"tried": tried, "path": new_path})
django.urls.exceptions.Resolver404: {'tried': [[<URLResolver <URLPattern list> (admin:admin) 'admin/'>], [<URLResolver <module 'main.urls' from '/Users/sergeizeliabovskii/Documents/python_ptojects/DjangoProject/main/urls.py'> (None:None) 'api/v1/user/'>], [<URLResolver <module 'event.urls' from '/Users/sergeizeliabovskii/Documents/python_ptojects/DjangoProject/event/urls.py'> (None:None) 'api/v1/event/'>, <URLPattern 'trigger/<int:user_id>/' [name='alarm']>], [<URLResolver <module 'chat.urls' from '/Users/sergeizeliabovskii/Documents/python_ptojects/DjangoProject/chat/urls.py'> (None:None) 'api/v1/chat/'>]], 'path': 'api/v1/event/1'}

During handling of the above exception, another exception occurred:

Traceback (most recent call last):
  File "/Users/sergeizeliabovskii/Documents/python_ptojects/DjangoProject/.venv/lib/python3.13/site-packages/django/template/base.py", line 890, in _resolve_lookup
    raise TypeError
TypeError

During handling of the above exception, another exception occurred:

Traceback (most recent call last):
  File "/Users/sergeizeliabovskii/Documents/python_ptojects/DjangoProject/.venv/lib/python3.13/site-packages/django/template/base.py", line 901, in _resolve_lookup
    current = getattr(current, bit)
AttributeError: 'URLResolver' object has no attribute 'name'

During handling of the above exception, another exception occurred:

Traceback (most recent call last):
  File "/Users/sergeizeliabovskii/Documents/python_ptojects/DjangoProject/.venv/lib/python3.13/site-packages/django/template/base.py", line 907, in _resolve_lookup
    current = current[int(bit)]
                      ~~~^^^^^
ValueError: invalid literal for int() with base 10: 'name'

During handling of the above exception, another exception occurred:

Traceback (most recent call last):
  File "/Users/sergeizeliabovskii/Documents/python_ptojects/DjangoProject/.venv/lib/python3.13/site-packages/django/template/base.py", line 914, in _resolve_lookup
    raise VariableDoesNotExist(
    ^^^^^^^^^^^^^^^^^^^^^^^^^^^
    ...<2 lines>...
    )  # missing attribute
    ^
django.template.base.VariableDoesNotExist: Failed lookup for key [name] in <URLResolver <module 'main.urls' from '/Users/sergeizeliabovskii/Documents/python_ptojects/DjangoProject/main/urls.py'> (None:None) 'api/v1/user/'>
DEBUG 2025-05-27 02:13:04,644 base Exception while resolving variable 'name' in template 'unknown'.
Traceback (most recent call last):
  File "/Users/sergeizeliabovskii/Documents/python_ptojects/DjangoProject/.venv/lib/python3.13/site-packages/asgiref/sync.py", line 518, in thread_handler
    raise exc_info[1]
  File "/Users/sergeizeliabovskii/Documents/python_ptojects/DjangoProject/.venv/lib/python3.13/site-packages/django/core/handlers/exception.py", line 42, in inner
    response = await get_response(request)
               ^^^^^^^^^^^^^^^^^^^^^^^^^^^
  File "/Users/sergeizeliabovskii/Documents/python_ptojects/DjangoProject/.venv/lib/python3.13/site-packages/django/core/handlers/base.py", line 235, in _get_response_async
    callback, callback_args, callback_kwargs = self.resolve_request(request)
                                               ~~~~~~~~~~~~~~~~~~~~^^^^^^^^^
  File "/Users/sergeizeliabovskii/Documents/python_ptojects/DjangoProject/.venv/lib/python3.13/site-packages/django/core/handlers/base.py", line 313, in resolve_request
    resolver_match = resolver.resolve(request.path_info)
  File "/Users/sergeizeliabovskii/Documents/python_ptojects/DjangoProject/.venv/lib/python3.13/site-packages/django/urls/resolvers.py", line 705, in resolve
    raise Resolver404({"tried": tried, "path": new_path})
django.urls.exceptions.Resolver404: {'tried': [[<URLResolver <URLPattern list> (admin:admin) 'admin/'>], [<URLResolver <module 'main.urls' from '/Users/sergeizeliabovskii/Documents/python_ptojects/DjangoProject/main/urls.py'> (None:None) 'api/v1/user/'>], [<URLResolver <module 'event.urls' from '/Users/sergeizeliabovskii/Documents/python_ptojects/DjangoProject/event/urls.py'> (None:None) 'api/v1/event/'>, <URLPattern 'trigger/<int:user_id>/' [name='alarm']>], [<URLResolver <module 'chat.urls' from '/Users/sergeizeliabovskii/Documents/python_ptojects/DjangoProject/chat/urls.py'> (None:None) 'api/v1/chat/'>]], 'path': 'api/v1/event/1'}

During handling of the above exception, another exception occurred:

Traceback (most recent call last):
  File "/Users/sergeizeliabovskii/Documents/python_ptojects/DjangoProject/.venv/lib/python3.13/site-packages/django/template/base.py", line 890, in _resolve_lookup
    raise TypeError
TypeError

During handling of the above exception, another exception occurred:

Traceback (most recent call last):
  File "/Users/sergeizeliabovskii/Documents/python_ptojects/DjangoProject/.venv/lib/python3.13/site-packages/django/template/base.py", line 901, in _resolve_lookup
    current = getattr(current, bit)
AttributeError: 'URLResolver' object has no attribute 'name'

During handling of the above exception, another exception occurred:

Traceback (most recent call last):
  File "/Users/sergeizeliabovskii/Documents/python_ptojects/DjangoProject/.venv/lib/python3.13/site-packages/django/template/base.py", line 907, in _resolve_lookup
    current = current[int(bit)]
                      ~~~^^^^^
ValueError: invalid literal for int() with base 10: 'name'

During handling of the above exception, another exception occurred:

Traceback (most recent call last):
  File "/Users/sergeizeliabovskii/Documents/python_ptojects/DjangoProject/.venv/lib/python3.13/site-packages/django/template/base.py", line 914, in _resolve_lookup
    raise VariableDoesNotExist(
    ^^^^^^^^^^^^^^^^^^^^^^^^^^^
    ...<2 lines>...
    )  # missing attribute
    ^
django.template.base.VariableDoesNotExist: Failed lookup for key [name] in <URLResolver <module 'chat.urls' from '/Users/sergeizeliabovskii/Documents/python_ptojects/DjangoProject/chat/urls.py'> (None:None) 'api/v1/chat/'>
WARNING 2025-05-27 02:13:04,650 log Not Found: /api/v1/event/1
DEBUG 2025-05-27 02:13:09,311 base Exception while resolving variable 'name' in template 'unknown'.
Traceback (most recent call last):
  File "/Users/sergeizeliabovskii/Documents/python_ptojects/DjangoProject/.venv/lib/python3.13/site-packages/asgiref/sync.py", line 518, in thread_handler
    raise exc_info[1]
  File "/Users/sergeizeliabovskii/Documents/python_ptojects/DjangoProject/.venv/lib/python3.13/site-packages/django/core/handlers/exception.py", line 42, in inner
    response = await get_response(request)
               ^^^^^^^^^^^^^^^^^^^^^^^^^^^
  File "/Users/sergeizeliabovskii/Documents/python_ptojects/DjangoProject/.venv/lib/python3.13/site-packages/django/core/handlers/base.py", line 235, in _get_response_async
    callback, callback_args, callback_kwargs = self.resolve_request(request)
                                               ~~~~~~~~~~~~~~~~~~~~^^^^^^^^^
  File "/Users/sergeizeliabovskii/Documents/python_ptojects/DjangoProject/.venv/lib/python3.13/site-packages/django/core/handlers/base.py", line 313, in resolve_request
    resolver_match = resolver.resolve(request.path_info)
  File "/Users/sergeizeliabovskii/Documents/python_ptojects/DjangoProject/.venv/lib/python3.13/site-packages/django/urls/resolvers.py", line 705, in resolve
    raise Resolver404({"tried": tried, "path": new_path})
django.urls.exceptions.Resolver404: {'tried': [[<URLResolver <URLPattern list> (admin:admin) 'admin/'>], [<URLResolver <module 'main.urls' from '/Users/sergeizeliabovskii/Documents/python_ptojects/DjangoProject/main/urls.py'> (None:None) 'api/v1/user/'>], [<URLResolver <module 'event.urls' from '/Users/sergeizeliabovskii/Documents/python_ptojects/DjangoProject/event/urls.py'> (None:None) 'api/v1/event/'>, <URLPattern 'trigger/<int:user_id>/' [name='alarm']>], [<URLResolver <module 'chat.urls' from '/Users/sergeizeliabovskii/Documents/python_ptojects/DjangoProject/chat/urls.py'> (None:None) 'api/v1/chat/'>]], 'path': 'api/v1/event/1/'}

During handling of the above exception, another exception occurred:

Traceback (most recent call last):
  File "/Users/sergeizeliabovskii/Documents/python_ptojects/DjangoProject/.venv/lib/python3.13/site-packages/django/template/base.py", line 890, in _resolve_lookup
    raise TypeError
TypeError

During handling of the above exception, another exception occurred:

Traceback (most recent call last):
  File "/Users/sergeizeliabovskii/Documents/python_ptojects/DjangoProject/.venv/lib/python3.13/site-packages/django/template/base.py", line 901, in _resolve_lookup
    current = getattr(current, bit)
AttributeError: 'URLResolver' object has no attribute 'name'

During handling of the above exception, another exception occurred:

Traceback (most recent call last):
  File "/Users/sergeizeliabovskii/Documents/python_ptojects/DjangoProject/.venv/lib/python3.13/site-packages/django/template/base.py", line 907, in _resolve_lookup
    current = current[int(bit)]
                      ~~~^^^^^
ValueError: invalid literal for int() with base 10: 'name'

During handling of the above exception, another exception occurred:

Traceback (most recent call last):
  File "/Users/sergeizeliabovskii/Documents/python_ptojects/DjangoProject/.venv/lib/python3.13/site-packages/django/template/base.py", line 914, in _resolve_lookup
    raise VariableDoesNotExist(
    ^^^^^^^^^^^^^^^^^^^^^^^^^^^
    ...<2 lines>...
    )  # missing attribute
    ^
django.template.base.VariableDoesNotExist: Failed lookup for key [name] in <URLResolver <URLPattern list> (admin:admin) 'admin/'>
DEBUG 2025-05-27 02:13:09,317 base Exception while resolving variable 'name' in template 'unknown'.
Traceback (most recent call last):
  File "/Users/sergeizeliabovskii/Documents/python_ptojects/DjangoProject/.venv/lib/python3.13/site-packages/asgiref/sync.py", line 518, in thread_handler
    raise exc_info[1]
  File "/Users/sergeizeliabovskii/Documents/python_ptojects/DjangoProject/.venv/lib/python3.13/site-packages/django/core/handlers/exception.py", line 42, in inner
    response = await get_response(request)
               ^^^^^^^^^^^^^^^^^^^^^^^^^^^
  File "/Users/sergeizeliabovskii/Documents/python_ptojects/DjangoProject/.venv/lib/python3.13/site-packages/django/core/handlers/base.py", line 235, in _get_response_async
    callback, callback_args, callback_kwargs = self.resolve_request(request)
                                               ~~~~~~~~~~~~~~~~~~~~^^^^^^^^^
  File "/Users/sergeizeliabovskii/Documents/python_ptojects/DjangoProject/.venv/lib/python3.13/site-packages/django/core/handlers/base.py", line 313, in resolve_request
    resolver_match = resolver.resolve(request.path_info)
  File "/Users/sergeizeliabovskii/Documents/python_ptojects/DjangoProject/.venv/lib/python3.13/site-packages/django/urls/resolvers.py", line 705, in resolve
    raise Resolver404({"tried": tried, "path": new_path})
django.urls.exceptions.Resolver404: {'tried': [[<URLResolver <URLPattern list> (admin:admin) 'admin/'>], [<URLResolver <module 'main.urls' from '/Users/sergeizeliabovskii/Documents/python_ptojects/DjangoProject/main/urls.py'> (None:None) 'api/v1/user/'>], [<URLResolver <module 'event.urls' from '/Users/sergeizeliabovskii/Documents/python_ptojects/DjangoProject/event/urls.py'> (None:None) 'api/v1/event/'>, <URLPattern 'trigger/<int:user_id>/' [name='alarm']>], [<URLResolver <module 'chat.urls' from '/Users/sergeizeliabovskii/Documents/python_ptojects/DjangoProject/chat/urls.py'> (None:None) 'api/v1/chat/'>]], 'path': 'api/v1/event/1/'}

During handling of the above exception, another exception occurred:

Traceback (most recent call last):
  File "/Users/sergeizeliabovskii/Documents/python_ptojects/DjangoProject/.venv/lib/python3.13/site-packages/django/template/base.py", line 890, in _resolve_lookup
    raise TypeError
TypeError

During handling of the above exception, another exception occurred:

Traceback (most recent call last):
  File "/Users/sergeizeliabovskii/Documents/python_ptojects/DjangoProject/.venv/lib/python3.13/site-packages/django/template/base.py", line 901, in _resolve_lookup
    current = getattr(current, bit)
AttributeError: 'URLResolver' object has no attribute 'name'

During handling of the above exception, another exception occurred:

Traceback (most recent call last):
  File "/Users/sergeizeliabovskii/Documents/python_ptojects/DjangoProject/.venv/lib/python3.13/site-packages/django/template/base.py", line 907, in _resolve_lookup
    current = current[int(bit)]
                      ~~~^^^^^
ValueError: invalid literal for int() with base 10: 'name'

During handling of the above exception, another exception occurred:

Traceback (most recent call last):
  File "/Users/sergeizeliabovskii/Documents/python_ptojects/DjangoProject/.venv/lib/python3.13/site-packages/django/template/base.py", line 914, in _resolve_lookup
    raise VariableDoesNotExist(
    ^^^^^^^^^^^^^^^^^^^^^^^^^^^
    ...<2 lines>...
    )  # missing attribute
    ^
django.template.base.VariableDoesNotExist: Failed lookup for key [name] in <URLResolver <module 'main.urls' from '/Users/sergeizeliabovskii/Documents/python_ptojects/DjangoProject/main/urls.py'> (None:None) 'api/v1/user/'>
DEBUG 2025-05-27 02:13:09,324 base Exception while resolving variable 'name' in template 'unknown'.
Traceback (most recent call last):
  File "/Users/sergeizeliabovskii/Documents/python_ptojects/DjangoProject/.venv/lib/python3.13/site-packages/asgiref/sync.py", line 518, in thread_handler
    raise exc_info[1]
  File "/Users/sergeizeliabovskii/Documents/python_ptojects/DjangoProject/.venv/lib/python3.13/site-packages/django/core/handlers/exception.py", line 42, in inner
    response = await get_response(request)
               ^^^^^^^^^^^^^^^^^^^^^^^^^^^
  File "/Users/sergeizeliabovskii/Documents/python_ptojects/DjangoProject/.venv/lib/python3.13/site-packages/django/core/handlers/base.py", line 235, in _get_response_async
    callback, callback_args, callback_kwargs = self.resolve_request(request)
                                               ~~~~~~~~~~~~~~~~~~~~^^^^^^^^^
  File "/Users/sergeizeliabovskii/Documents/python_ptojects/DjangoProject/.venv/lib/python3.13/site-packages/django/core/handlers/base.py", line 313, in resolve_request
    resolver_match = resolver.resolve(request.path_info)
  File "/Users/sergeizeliabovskii/Documents/python_ptojects/DjangoProject/.venv/lib/python3.13/site-packages/django/urls/resolvers.py", line 705, in resolve
    raise Resolver404({"tried": tried, "path": new_path})
django.urls.exceptions.Resolver404: {'tried': [[<URLResolver <URLPattern list> (admin:admin) 'admin/'>], [<URLResolver <module 'main.urls' from '/Users/sergeizeliabovskii/Documents/python_ptojects/DjangoProject/main/urls.py'> (None:None) 'api/v1/user/'>], [<URLResolver <module 'event.urls' from '/Users/sergeizeliabovskii/Documents/python_ptojects/DjangoProject/event/urls.py'> (None:None) 'api/v1/event/'>, <URLPattern 'trigger/<int:user_id>/' [name='alarm']>], [<URLResolver <module 'chat.urls' from '/Users/sergeizeliabovskii/Documents/python_ptojects/DjangoProject/chat/urls.py'> (None:None) 'api/v1/chat/'>]], 'path': 'api/v1/event/1/'}

During handling of the above exception, another exception occurred:

Traceback (most recent call last):
  File "/Users/sergeizeliabovskii/Documents/python_ptojects/DjangoProject/.venv/lib/python3.13/site-packages/django/template/base.py", line 890, in _resolve_lookup
    raise TypeError
TypeError

During handling of the above exception, another exception occurred:

Traceback (most recent call last):
  File "/Users/sergeizeliabovskii/Documents/python_ptojects/DjangoProject/.venv/lib/python3.13/site-packages/django/template/base.py", line 901, in _resolve_lookup
    current = getattr(current, bit)
AttributeError: 'URLResolver' object has no attribute 'name'

During handling of the above exception, another exception occurred:

Traceback (most recent call last):
  File "/Users/sergeizeliabovskii/Documents/python_ptojects/DjangoProject/.venv/lib/python3.13/site-packages/django/template/base.py", line 907, in _resolve_lookup
    current = current[int(bit)]
                      ~~~^^^^^
ValueError: invalid literal for int() with base 10: 'name'

During handling of the above exception, another exception occurred:

Traceback (most recent call last):
  File "/Users/sergeizeliabovskii/Documents/python_ptojects/DjangoProject/.venv/lib/python3.13/site-packages/django/template/base.py", line 914, in _resolve_lookup
    raise VariableDoesNotExist(
    ^^^^^^^^^^^^^^^^^^^^^^^^^^^
    ...<2 lines>...
    )  # missing attribute
    ^
django.template.base.VariableDoesNotExist: Failed lookup for key [name] in <URLResolver <module 'chat.urls' from '/Users/sergeizeliabovskii/Documents/python_ptojects/DjangoProject/chat/urls.py'> (None:None) 'api/v1/chat/'>
WARNING 2025-05-27 02:13:09,330 log Not Found: /api/v1/event/1/
WARNING 2025-05-27 02:13:46,379 log Unauthorized: /api/v1/user/1/
WARNING 2025-05-27 02:15:06,087 log Unauthorized: /api/v1/user/1/
WARNING 2025-05-27 02:15:07,352 log Unauthorized: /api/v1/user/1/
WARNING 2025-05-27 02:15:17,349 log Unauthorized: /api/v1/user/1/
DEBUG 2025-05-27 02:17:18,912 utils (0.004) SELECT "authtoken_token"."key", "authtoken_token"."user_id", "authtoken_token"."created", "auth_user"."id", "auth_user"."password", "auth_user"."last_login", "auth_user"."is_superuser", "auth_user"."username", "auth_user"."first_name", "auth_user"."last_name", "auth_user"."email", "auth_user"."is_staff", "auth_user"."is_active", "auth_user"."date_joined" FROM "authtoken_token" INNER JOIN "auth_user" ON ("authtoken_token"."user_id" = "auth_user"."id") WHERE "authtoken_token"."key" = '889e10d16483c21f9b775f9bf98ecff96f7af71c' LIMIT 21; args=('889e10d16483c21f9b775f9bf98ecff96f7af71c',); alias=default
DEBUG 2025-05-27 02:17:18,919 utils (0.003) SELECT "main_userinfo"."id", "main_userinfo"."user_id", "main_userinfo"."age", "main_userinfo"."location", "main_userinfo"."military_status", "main_userinfo"."ptsd_level", "main_userinfo"."music_id", "main_userinfo"."therapist_contact_id", "main_userinfo"."scenario_id" FROM "main_userinfo" WHERE "main_userinfo"."user_id" = 1 LIMIT 21; args=(1,); alias=default
DEBUG 2025-05-27 02:17:18,926 utils (0.000) SELECT "auth_user"."id", "auth_user"."password", "auth_user"."last_login", "auth_user"."is_superuser", "auth_user"."username", "auth_user"."first_name", "auth_user"."last_name", "auth_user"."email", "auth_user"."is_staff", "auth_user"."is_active", "auth_user"."date_joined" FROM "auth_user" WHERE "auth_user"."id" = 1 LIMIT 21; args=(1,); alias=default
DEBUG 2025-05-27 02:21:35,908 base Exception while resolving variable 'name' in template 'unknown'.
Traceback (most recent call last):
  File "/Users/sergeizeliabovskii/Documents/python_ptojects/DjangoProject/.venv/lib/python3.13/site-packages/asgiref/sync.py", line 518, in thread_handler
    raise exc_info[1]
  File "/Users/sergeizeliabovskii/Documents/python_ptojects/DjangoProject/.venv/lib/python3.13/site-packages/django/core/handlers/exception.py", line 42, in inner
    response = await get_response(request)
               ^^^^^^^^^^^^^^^^^^^^^^^^^^^
  File "/Users/sergeizeliabovskii/Documents/python_ptojects/DjangoProject/.venv/lib/python3.13/site-packages/django/core/handlers/base.py", line 235, in _get_response_async
    callback, callback_args, callback_kwargs = self.resolve_request(request)
                                               ~~~~~~~~~~~~~~~~~~~~^^^^^^^^^
  File "/Users/sergeizeliabovskii/Documents/python_ptojects/DjangoProject/.venv/lib/python3.13/site-packages/django/core/handlers/base.py", line 313, in resolve_request
    resolver_match = resolver.resolve(request.path_info)
  File "/Users/sergeizeliabovskii/Documents/python_ptojects/DjangoProject/.venv/lib/python3.13/site-packages/django/urls/resolvers.py", line 705, in resolve
    raise Resolver404({"tried": tried, "path": new_path})
django.urls.exceptions.Resolver404: {'tried': [[<URLResolver <URLPattern list> (admin:admin) 'admin/'>], [<URLResolver <module 'main.urls' from '/Users/sergeizeliabovskii/Documents/python_ptojects/DjangoProject/main/urls.py'> (None:None) 'api/v1/user/'>], [<URLResolver <module 'event.urls' from '/Users/sergeizeliabovskii/Documents/python_ptojects/DjangoProject/event/urls.py'> (None:None) 'api/v1/event/'>], [<URLResolver <module 'chat.urls' from '/Users/sergeizeliabovskii/Documents/python_ptojects/DjangoProject/chat/urls.py'> (None:None) 'api/v1/chat/'>]], 'path': 'user/support/1/'}

During handling of the above exception, another exception occurred:

Traceback (most recent call last):
  File "/Users/sergeizeliabovskii/Documents/python_ptojects/DjangoProject/.venv/lib/python3.13/site-packages/django/template/base.py", line 890, in _resolve_lookup
    raise TypeError
TypeError

During handling of the above exception, another exception occurred:

Traceback (most recent call last):
  File "/Users/sergeizeliabovskii/Documents/python_ptojects/DjangoProject/.venv/lib/python3.13/site-packages/django/template/base.py", line 901, in _resolve_lookup
    current = getattr(current, bit)
AttributeError: 'URLResolver' object has no attribute 'name'

During handling of the above exception, another exception occurred:

Traceback (most recent call last):
  File "/Users/sergeizeliabovskii/Documents/python_ptojects/DjangoProject/.venv/lib/python3.13/site-packages/django/template/base.py", line 907, in _resolve_lookup
    current = current[int(bit)]
                      ~~~^^^^^
ValueError: invalid literal for int() with base 10: 'name'

During handling of the above exception, another exception occurred:

Traceback (most recent call last):
  File "/Users/sergeizeliabovskii/Documents/python_ptojects/DjangoProject/.venv/lib/python3.13/site-packages/django/template/base.py", line 914, in _resolve_lookup
    raise VariableDoesNotExist(
    ^^^^^^^^^^^^^^^^^^^^^^^^^^^
    ...<2 lines>...
    )  # missing attribute
    ^
django.template.base.VariableDoesNotExist: Failed lookup for key [name] in <URLResolver <URLPattern list> (admin:admin) 'admin/'>
DEBUG 2025-05-27 02:21:35,914 base Exception while resolving variable 'name' in template 'unknown'.
Traceback (most recent call last):
  File "/Users/sergeizeliabovskii/Documents/python_ptojects/DjangoProject/.venv/lib/python3.13/site-packages/asgiref/sync.py", line 518, in thread_handler
    raise exc_info[1]
  File "/Users/sergeizeliabovskii/Documents/python_ptojects/DjangoProject/.venv/lib/python3.13/site-packages/django/core/handlers/exception.py", line 42, in inner
    response = await get_response(request)
               ^^^^^^^^^^^^^^^^^^^^^^^^^^^
  File "/Users/sergeizeliabovskii/Documents/python_ptojects/DjangoProject/.venv/lib/python3.13/site-packages/django/core/handlers/base.py", line 235, in _get_response_async
    callback, callback_args, callback_kwargs = self.resolve_request(request)
                                               ~~~~~~~~~~~~~~~~~~~~^^^^^^^^^
  File "/Users/sergeizeliabovskii/Documents/python_ptojects/DjangoProject/.venv/lib/python3.13/site-packages/django/core/handlers/base.py", line 313, in resolve_request
    resolver_match = resolver.resolve(request.path_info)
  File "/Users/sergeizeliabovskii/Documents/python_ptojects/DjangoProject/.venv/lib/python3.13/site-packages/django/urls/resolvers.py", line 705, in resolve
    raise Resolver404({"tried": tried, "path": new_path})
django.urls.exceptions.Resolver404: {'tried': [[<URLResolver <URLPattern list> (admin:admin) 'admin/'>], [<URLResolver <module 'main.urls' from '/Users/sergeizeliabovskii/Documents/python_ptojects/DjangoProject/main/urls.py'> (None:None) 'api/v1/user/'>], [<URLResolver <module 'event.urls' from '/Users/sergeizeliabovskii/Documents/python_ptojects/DjangoProject/event/urls.py'> (None:None) 'api/v1/event/'>], [<URLResolver <module 'chat.urls' from '/Users/sergeizeliabovskii/Documents/python_ptojects/DjangoProject/chat/urls.py'> (None:None) 'api/v1/chat/'>]], 'path': 'user/support/1/'}

During handling of the above exception, another exception occurred:

Traceback (most recent call last):
  File "/Users/sergeizeliabovskii/Documents/python_ptojects/DjangoProject/.venv/lib/python3.13/site-packages/django/template/base.py", line 890, in _resolve_lookup
    raise TypeError
TypeError

During handling of the above exception, another exception occurred:

Traceback (most recent call last):
  File "/Users/sergeizeliabovskii/Documents/python_ptojects/DjangoProject/.venv/lib/python3.13/site-packages/django/template/base.py", line 901, in _resolve_lookup
    current = getattr(current, bit)
AttributeError: 'URLResolver' object has no attribute 'name'

During handling of the above exception, another exception occurred:

Traceback (most recent call last):
  File "/Users/sergeizeliabovskii/Documents/python_ptojects/DjangoProject/.venv/lib/python3.13/site-packages/django/template/base.py", line 907, in _resolve_lookup
    current = current[int(bit)]
                      ~~~^^^^^
ValueError: invalid literal for int() with base 10: 'name'

During handling of the above exception, another exception occurred:

Traceback (most recent call last):
  File "/Users/sergeizeliabovskii/Documents/python_ptojects/DjangoProject/.venv/lib/python3.13/site-packages/django/template/base.py", line 914, in _resolve_lookup
    raise VariableDoesNotExist(
    ^^^^^^^^^^^^^^^^^^^^^^^^^^^
    ...<2 lines>...
    )  # missing attribute
    ^
django.template.base.VariableDoesNotExist: Failed lookup for key [name] in <URLResolver <module 'main.urls' from '/Users/sergeizeliabovskii/Documents/python_ptojects/DjangoProject/main/urls.py'> (None:None) 'api/v1/user/'>
DEBUG 2025-05-27 02:21:35,918 base Exception while resolving variable 'name' in template 'unknown'.
Traceback (most recent call last):
  File "/Users/sergeizeliabovskii/Documents/python_ptojects/DjangoProject/.venv/lib/python3.13/site-packages/asgiref/sync.py", line 518, in thread_handler
    raise exc_info[1]
  File "/Users/sergeizeliabovskii/Documents/python_ptojects/DjangoProject/.venv/lib/python3.13/site-packages/django/core/handlers/exception.py", line 42, in inner
    response = await get_response(request)
               ^^^^^^^^^^^^^^^^^^^^^^^^^^^
  File "/Users/sergeizeliabovskii/Documents/python_ptojects/DjangoProject/.venv/lib/python3.13/site-packages/django/core/handlers/base.py", line 235, in _get_response_async
    callback, callback_args, callback_kwargs = self.resolve_request(request)
                                               ~~~~~~~~~~~~~~~~~~~~^^^^^^^^^
  File "/Users/sergeizeliabovskii/Documents/python_ptojects/DjangoProject/.venv/lib/python3.13/site-packages/django/core/handlers/base.py", line 313, in resolve_request
    resolver_match = resolver.resolve(request.path_info)
  File "/Users/sergeizeliabovskii/Documents/python_ptojects/DjangoProject/.venv/lib/python3.13/site-packages/django/urls/resolvers.py", line 705, in resolve
    raise Resolver404({"tried": tried, "path": new_path})
django.urls.exceptions.Resolver404: {'tried': [[<URLResolver <URLPattern list> (admin:admin) 'admin/'>], [<URLResolver <module 'main.urls' from '/Users/sergeizeliabovskii/Documents/python_ptojects/DjangoProject/main/urls.py'> (None:None) 'api/v1/user/'>], [<URLResolver <module 'event.urls' from '/Users/sergeizeliabovskii/Documents/python_ptojects/DjangoProject/event/urls.py'> (None:None) 'api/v1/event/'>], [<URLResolver <module 'chat.urls' from '/Users/sergeizeliabovskii/Documents/python_ptojects/DjangoProject/chat/urls.py'> (None:None) 'api/v1/chat/'>]], 'path': 'user/support/1/'}

During handling of the above exception, another exception occurred:

Traceback (most recent call last):
  File "/Users/sergeizeliabovskii/Documents/python_ptojects/DjangoProject/.venv/lib/python3.13/site-packages/django/template/base.py", line 890, in _resolve_lookup
    raise TypeError
TypeError

During handling of the above exception, another exception occurred:

Traceback (most recent call last):
  File "/Users/sergeizeliabovskii/Documents/python_ptojects/DjangoProject/.venv/lib/python3.13/site-packages/django/template/base.py", line 901, in _resolve_lookup
    current = getattr(current, bit)
AttributeError: 'URLResolver' object has no attribute 'name'

During handling of the above exception, another exception occurred:

Traceback (most recent call last):
  File "/Users/sergeizeliabovskii/Documents/python_ptojects/DjangoProject/.venv/lib/python3.13/site-packages/django/template/base.py", line 907, in _resolve_lookup
    current = current[int(bit)]
                      ~~~^^^^^
ValueError: invalid literal for int() with base 10: 'name'

During handling of the above exception, another exception occurred:

Traceback (most recent call last):
  File "/Users/sergeizeliabovskii/Documents/python_ptojects/DjangoProject/.venv/lib/python3.13/site-packages/django/template/base.py", line 914, in _resolve_lookup
    raise VariableDoesNotExist(
    ^^^^^^^^^^^^^^^^^^^^^^^^^^^
    ...<2 lines>...
    )  # missing attribute
    ^
django.template.base.VariableDoesNotExist: Failed lookup for key [name] in <URLResolver <module 'event.urls' from '/Users/sergeizeliabovskii/Documents/python_ptojects/DjangoProject/event/urls.py'> (None:None) 'api/v1/event/'>
DEBUG 2025-05-27 02:21:35,921 base Exception while resolving variable 'name' in template 'unknown'.
Traceback (most recent call last):
  File "/Users/sergeizeliabovskii/Documents/python_ptojects/DjangoProject/.venv/lib/python3.13/site-packages/asgiref/sync.py", line 518, in thread_handler
    raise exc_info[1]
  File "/Users/sergeizeliabovskii/Documents/python_ptojects/DjangoProject/.venv/lib/python3.13/site-packages/django/core/handlers/exception.py", line 42, in inner
    response = await get_response(request)
               ^^^^^^^^^^^^^^^^^^^^^^^^^^^
  File "/Users/sergeizeliabovskii/Documents/python_ptojects/DjangoProject/.venv/lib/python3.13/site-packages/django/core/handlers/base.py", line 235, in _get_response_async
    callback, callback_args, callback_kwargs = self.resolve_request(request)
                                               ~~~~~~~~~~~~~~~~~~~~^^^^^^^^^
  File "/Users/sergeizeliabovskii/Documents/python_ptojects/DjangoProject/.venv/lib/python3.13/site-packages/django/core/handlers/base.py", line 313, in resolve_request
    resolver_match = resolver.resolve(request.path_info)
  File "/Users/sergeizeliabovskii/Documents/python_ptojects/DjangoProject/.venv/lib/python3.13/site-packages/django/urls/resolvers.py", line 705, in resolve
    raise Resolver404({"tried": tried, "path": new_path})
django.urls.exceptions.Resolver404: {'tried': [[<URLResolver <URLPattern list> (admin:admin) 'admin/'>], [<URLResolver <module 'main.urls' from '/Users/sergeizeliabovskii/Documents/python_ptojects/DjangoProject/main/urls.py'> (None:None) 'api/v1/user/'>], [<URLResolver <module 'event.urls' from '/Users/sergeizeliabovskii/Documents/python_ptojects/DjangoProject/event/urls.py'> (None:None) 'api/v1/event/'>], [<URLResolver <module 'chat.urls' from '/Users/sergeizeliabovskii/Documents/python_ptojects/DjangoProject/chat/urls.py'> (None:None) 'api/v1/chat/'>]], 'path': 'user/support/1/'}

During handling of the above exception, another exception occurred:

Traceback (most recent call last):
  File "/Users/sergeizeliabovskii/Documents/python_ptojects/DjangoProject/.venv/lib/python3.13/site-packages/django/template/base.py", line 890, in _resolve_lookup
    raise TypeError
TypeError

During handling of the above exception, another exception occurred:

Traceback (most recent call last):
  File "/Users/sergeizeliabovskii/Documents/python_ptojects/DjangoProject/.venv/lib/python3.13/site-packages/django/template/base.py", line 901, in _resolve_lookup
    current = getattr(current, bit)
AttributeError: 'URLResolver' object has no attribute 'name'

During handling of the above exception, another exception occurred:

Traceback (most recent call last):
  File "/Users/sergeizeliabovskii/Documents/python_ptojects/DjangoProject/.venv/lib/python3.13/site-packages/django/template/base.py", line 907, in _resolve_lookup
    current = current[int(bit)]
                      ~~~^^^^^
ValueError: invalid literal for int() with base 10: 'name'

During handling of the above exception, another exception occurred:

Traceback (most recent call last):
  File "/Users/sergeizeliabovskii/Documents/python_ptojects/DjangoProject/.venv/lib/python3.13/site-packages/django/template/base.py", line 914, in _resolve_lookup
    raise VariableDoesNotExist(
    ^^^^^^^^^^^^^^^^^^^^^^^^^^^
    ...<2 lines>...
    )  # missing attribute
    ^
django.template.base.VariableDoesNotExist: Failed lookup for key [name] in <URLResolver <module 'chat.urls' from '/Users/sergeizeliabovskii/Documents/python_ptojects/DjangoProject/chat/urls.py'> (None:None) 'api/v1/chat/'>
WARNING 2025-05-27 02:21:35,927 log Not Found: /user/support/1/
DEBUG 2025-05-27 02:23:05,432 base Exception while resolving variable 'name' in template 'unknown'.
Traceback (most recent call last):
  File "/Users/sergeizeliabovskii/Documents/python_ptojects/DjangoProject/.venv/lib/python3.13/site-packages/asgiref/sync.py", line 518, in thread_handler
    raise exc_info[1]
  File "/Users/sergeizeliabovskii/Documents/python_ptojects/DjangoProject/.venv/lib/python3.13/site-packages/django/core/handlers/exception.py", line 42, in inner
    response = await get_response(request)
               ^^^^^^^^^^^^^^^^^^^^^^^^^^^
  File "/Users/sergeizeliabovskii/Documents/python_ptojects/DjangoProject/.venv/lib/python3.13/site-packages/django/core/handlers/base.py", line 235, in _get_response_async
    callback, callback_args, callback_kwargs = self.resolve_request(request)
                                               ~~~~~~~~~~~~~~~~~~~~^^^^^^^^^
  File "/Users/sergeizeliabovskii/Documents/python_ptojects/DjangoProject/.venv/lib/python3.13/site-packages/django/core/handlers/base.py", line 313, in resolve_request
    resolver_match = resolver.resolve(request.path_info)
  File "/Users/sergeizeliabovskii/Documents/python_ptojects/DjangoProject/.venv/lib/python3.13/site-packages/django/urls/resolvers.py", line 705, in resolve
    raise Resolver404({"tried": tried, "path": new_path})
django.urls.exceptions.Resolver404: {'tried': [[<URLResolver <URLPattern list> (admin:admin) 'admin/'>], [<URLResolver <module 'main.urls' from '/Users/sergeizeliabovskii/Documents/python_ptojects/DjangoProject/main/urls.py'> (None:None) 'api/v1/user/'>], [<URLResolver <module 'event.urls' from '/Users/sergeizeliabovskii/Documents/python_ptojects/DjangoProject/event/urls.py'> (None:None) 'api/v1/event/'>], [<URLResolver <module 'chat.urls' from '/Users/sergeizeliabovskii/Documents/python_ptojects/DjangoProject/chat/urls.py'> (None:None) 'api/v1/chat/'>]], 'path': 'user/support/1/'}

During handling of the above exception, another exception occurred:

Traceback (most recent call last):
  File "/Users/sergeizeliabovskii/Documents/python_ptojects/DjangoProject/.venv/lib/python3.13/site-packages/django/template/base.py", line 890, in _resolve_lookup
    raise TypeError
TypeError

During handling of the above exception, another exception occurred:

Traceback (most recent call last):
  File "/Users/sergeizeliabovskii/Documents/python_ptojects/DjangoProject/.venv/lib/python3.13/site-packages/django/template/base.py", line 901, in _resolve_lookup
    current = getattr(current, bit)
AttributeError: 'URLResolver' object has no attribute 'name'

During handling of the above exception, another exception occurred:

Traceback (most recent call last):
  File "/Users/sergeizeliabovskii/Documents/python_ptojects/DjangoProject/.venv/lib/python3.13/site-packages/django/template/base.py", line 907, in _resolve_lookup
    current = current[int(bit)]
                      ~~~^^^^^
ValueError: invalid literal for int() with base 10: 'name'

During handling of the above exception, another exception occurred:

Traceback (most recent call last):
  File "/Users/sergeizeliabovskii/Documents/python_ptojects/DjangoProject/.venv/lib/python3.13/site-packages/django/template/base.py", line 914, in _resolve_lookup
    raise VariableDoesNotExist(
    ^^^^^^^^^^^^^^^^^^^^^^^^^^^
    ...<2 lines>...
    )  # missing attribute
    ^
django.template.base.VariableDoesNotExist: Failed lookup for key [name] in <URLResolver <URLPattern list> (admin:admin) 'admin/'>
DEBUG 2025-05-27 02:23:05,438 base Exception while resolving variable 'name' in template 'unknown'.
Traceback (most recent call last):
  File "/Users/sergeizeliabovskii/Documents/python_ptojects/DjangoProject/.venv/lib/python3.13/site-packages/asgiref/sync.py", line 518, in thread_handler
    raise exc_info[1]
  File "/Users/sergeizeliabovskii/Documents/python_ptojects/DjangoProject/.venv/lib/python3.13/site-packages/django/core/handlers/exception.py", line 42, in inner
    response = await get_response(request)
               ^^^^^^^^^^^^^^^^^^^^^^^^^^^
  File "/Users/sergeizeliabovskii/Documents/python_ptojects/DjangoProject/.venv/lib/python3.13/site-packages/django/core/handlers/base.py", line 235, in _get_response_async
    callback, callback_args, callback_kwargs = self.resolve_request(request)
                                               ~~~~~~~~~~~~~~~~~~~~^^^^^^^^^
  File "/Users/sergeizeliabovskii/Documents/python_ptojects/DjangoProject/.venv/lib/python3.13/site-packages/django/core/handlers/base.py", line 313, in resolve_request
    resolver_match = resolver.resolve(request.path_info)
  File "/Users/sergeizeliabovskii/Documents/python_ptojects/DjangoProject/.venv/lib/python3.13/site-packages/django/urls/resolvers.py", line 705, in resolve
    raise Resolver404({"tried": tried, "path": new_path})
django.urls.exceptions.Resolver404: {'tried': [[<URLResolver <URLPattern list> (admin:admin) 'admin/'>], [<URLResolver <module 'main.urls' from '/Users/sergeizeliabovskii/Documents/python_ptojects/DjangoProject/main/urls.py'> (None:None) 'api/v1/user/'>], [<URLResolver <module 'event.urls' from '/Users/sergeizeliabovskii/Documents/python_ptojects/DjangoProject/event/urls.py'> (None:None) 'api/v1/event/'>], [<URLResolver <module 'chat.urls' from '/Users/sergeizeliabovskii/Documents/python_ptojects/DjangoProject/chat/urls.py'> (None:None) 'api/v1/chat/'>]], 'path': 'user/support/1/'}

During handling of the above exception, another exception occurred:

Traceback (most recent call last):
  File "/Users/sergeizeliabovskii/Documents/python_ptojects/DjangoProject/.venv/lib/python3.13/site-packages/django/template/base.py", line 890, in _resolve_lookup
    raise TypeError
TypeError

During handling of the above exception, another exception occurred:

Traceback (most recent call last):
  File "/Users/sergeizeliabovskii/Documents/python_ptojects/DjangoProject/.venv/lib/python3.13/site-packages/django/template/base.py", line 901, in _resolve_lookup
    current = getattr(current, bit)
AttributeError: 'URLResolver' object has no attribute 'name'

During handling of the above exception, another exception occurred:

Traceback (most recent call last):
  File "/Users/sergeizeliabovskii/Documents/python_ptojects/DjangoProject/.venv/lib/python3.13/site-packages/django/template/base.py", line 907, in _resolve_lookup
    current = current[int(bit)]
                      ~~~^^^^^
ValueError: invalid literal for int() with base 10: 'name'

During handling of the above exception, another exception occurred:

Traceback (most recent call last):
  File "/Users/sergeizeliabovskii/Documents/python_ptojects/DjangoProject/.venv/lib/python3.13/site-packages/django/template/base.py", line 914, in _resolve_lookup
    raise VariableDoesNotExist(
    ^^^^^^^^^^^^^^^^^^^^^^^^^^^
    ...<2 lines>...
    )  # missing attribute
    ^
django.template.base.VariableDoesNotExist: Failed lookup for key [name] in <URLResolver <module 'main.urls' from '/Users/sergeizeliabovskii/Documents/python_ptojects/DjangoProject/main/urls.py'> (None:None) 'api/v1/user/'>
DEBUG 2025-05-27 02:23:05,443 base Exception while resolving variable 'name' in template 'unknown'.
Traceback (most recent call last):
  File "/Users/sergeizeliabovskii/Documents/python_ptojects/DjangoProject/.venv/lib/python3.13/site-packages/asgiref/sync.py", line 518, in thread_handler
    raise exc_info[1]
  File "/Users/sergeizeliabovskii/Documents/python_ptojects/DjangoProject/.venv/lib/python3.13/site-packages/django/core/handlers/exception.py", line 42, in inner
    response = await get_response(request)
               ^^^^^^^^^^^^^^^^^^^^^^^^^^^
  File "/Users/sergeizeliabovskii/Documents/python_ptojects/DjangoProject/.venv/lib/python3.13/site-packages/django/core/handlers/base.py", line 235, in _get_response_async
    callback, callback_args, callback_kwargs = self.resolve_request(request)
                                               ~~~~~~~~~~~~~~~~~~~~^^^^^^^^^
  File "/Users/sergeizeliabovskii/Documents/python_ptojects/DjangoProject/.venv/lib/python3.13/site-packages/django/core/handlers/base.py", line 313, in resolve_request
    resolver_match = resolver.resolve(request.path_info)
  File "/Users/sergeizeliabovskii/Documents/python_ptojects/DjangoProject/.venv/lib/python3.13/site-packages/django/urls/resolvers.py", line 705, in resolve
    raise Resolver404({"tried": tried, "path": new_path})
django.urls.exceptions.Resolver404: {'tried': [[<URLResolver <URLPattern list> (admin:admin) 'admin/'>], [<URLResolver <module 'main.urls' from '/Users/sergeizeliabovskii/Documents/python_ptojects/DjangoProject/main/urls.py'> (None:None) 'api/v1/user/'>], [<URLResolver <module 'event.urls' from '/Users/sergeizeliabovskii/Documents/python_ptojects/DjangoProject/event/urls.py'> (None:None) 'api/v1/event/'>], [<URLResolver <module 'chat.urls' from '/Users/sergeizeliabovskii/Documents/python_ptojects/DjangoProject/chat/urls.py'> (None:None) 'api/v1/chat/'>]], 'path': 'user/support/1/'}

During handling of the above exception, another exception occurred:

Traceback (most recent call last):
  File "/Users/sergeizeliabovskii/Documents/python_ptojects/DjangoProject/.venv/lib/python3.13/site-packages/django/template/base.py", line 890, in _resolve_lookup
    raise TypeError
TypeError

During handling of the above exception, another exception occurred:

Traceback (most recent call last):
  File "/Users/sergeizeliabovskii/Documents/python_ptojects/DjangoProject/.venv/lib/python3.13/site-packages/django/template/base.py", line 901, in _resolve_lookup
    current = getattr(current, bit)
AttributeError: 'URLResolver' object has no attribute 'name'

During handling of the above exception, another exception occurred:

Traceback (most recent call last):
  File "/Users/sergeizeliabovskii/Documents/python_ptojects/DjangoProject/.venv/lib/python3.13/site-packages/django/template/base.py", line 907, in _resolve_lookup
    current = current[int(bit)]
                      ~~~^^^^^
ValueError: invalid literal for int() with base 10: 'name'

During handling of the above exception, another exception occurred:

Traceback (most recent call last):
  File "/Users/sergeizeliabovskii/Documents/python_ptojects/DjangoProject/.venv/lib/python3.13/site-packages/django/template/base.py", line 914, in _resolve_lookup
    raise VariableDoesNotExist(
    ^^^^^^^^^^^^^^^^^^^^^^^^^^^
    ...<2 lines>...
    )  # missing attribute
    ^
django.template.base.VariableDoesNotExist: Failed lookup for key [name] in <URLResolver <module 'event.urls' from '/Users/sergeizeliabovskii/Documents/python_ptojects/DjangoProject/event/urls.py'> (None:None) 'api/v1/event/'>
DEBUG 2025-05-27 02:23:05,446 base Exception while resolving variable 'name' in template 'unknown'.
Traceback (most recent call last):
  File "/Users/sergeizeliabovskii/Documents/python_ptojects/DjangoProject/.venv/lib/python3.13/site-packages/asgiref/sync.py", line 518, in thread_handler
    raise exc_info[1]
  File "/Users/sergeizeliabovskii/Documents/python_ptojects/DjangoProject/.venv/lib/python3.13/site-packages/django/core/handlers/exception.py", line 42, in inner
    response = await get_response(request)
               ^^^^^^^^^^^^^^^^^^^^^^^^^^^
  File "/Users/sergeizeliabovskii/Documents/python_ptojects/DjangoProject/.venv/lib/python3.13/site-packages/django/core/handlers/base.py", line 235, in _get_response_async
    callback, callback_args, callback_kwargs = self.resolve_request(request)
                                               ~~~~~~~~~~~~~~~~~~~~^^^^^^^^^
  File "/Users/sergeizeliabovskii/Documents/python_ptojects/DjangoProject/.venv/lib/python3.13/site-packages/django/core/handlers/base.py", line 313, in resolve_request
    resolver_match = resolver.resolve(request.path_info)
  File "/Users/sergeizeliabovskii/Documents/python_ptojects/DjangoProject/.venv/lib/python3.13/site-packages/django/urls/resolvers.py", line 705, in resolve
    raise Resolver404({"tried": tried, "path": new_path})
django.urls.exceptions.Resolver404: {'tried': [[<URLResolver <URLPattern list> (admin:admin) 'admin/'>], [<URLResolver <module 'main.urls' from '/Users/sergeizeliabovskii/Documents/python_ptojects/DjangoProject/main/urls.py'> (None:None) 'api/v1/user/'>], [<URLResolver <module 'event.urls' from '/Users/sergeizeliabovskii/Documents/python_ptojects/DjangoProject/event/urls.py'> (None:None) 'api/v1/event/'>], [<URLResolver <module 'chat.urls' from '/Users/sergeizeliabovskii/Documents/python_ptojects/DjangoProject/chat/urls.py'> (None:None) 'api/v1/chat/'>]], 'path': 'user/support/1/'}

During handling of the above exception, another exception occurred:

Traceback (most recent call last):
  File "/Users/sergeizeliabovskii/Documents/python_ptojects/DjangoProject/.venv/lib/python3.13/site-packages/django/template/base.py", line 890, in _resolve_lookup
    raise TypeError
TypeError

During handling of the above exception, another exception occurred:

Traceback (most recent call last):
  File "/Users/sergeizeliabovskii/Documents/python_ptojects/DjangoProject/.venv/lib/python3.13/site-packages/django/template/base.py", line 901, in _resolve_lookup
    current = getattr(current, bit)
AttributeError: 'URLResolver' object has no attribute 'name'

During handling of the above exception, another exception occurred:

Traceback (most recent call last):
  File "/Users/sergeizeliabovskii/Documents/python_ptojects/DjangoProject/.venv/lib/python3.13/site-packages/django/template/base.py", line 907, in _resolve_lookup
    current = current[int(bit)]
                      ~~~^^^^^
ValueError: invalid literal for int() with base 10: 'name'

During handling of the above exception, another exception occurred:

Traceback (most recent call last):
  File "/Users/sergeizeliabovskii/Documents/python_ptojects/DjangoProject/.venv/lib/python3.13/site-packages/django/template/base.py", line 914, in _resolve_lookup
    raise VariableDoesNotExist(
    ^^^^^^^^^^^^^^^^^^^^^^^^^^^
    ...<2 lines>...
    )  # missing attribute
    ^
django.template.base.VariableDoesNotExist: Failed lookup for key [name] in <URLResolver <module 'chat.urls' from '/Users/sergeizeliabovskii/Documents/python_ptojects/DjangoProject/chat/urls.py'> (None:None) 'api/v1/chat/'>
WARNING 2025-05-27 02:23:05,452 log Not Found: /user/support/1/
DEBUG 2025-05-27 02:23:26,415 base Exception while resolving variable 'name' in template 'unknown'.
Traceback (most recent call last):
  File "/Users/sergeizeliabovskii/Documents/python_ptojects/DjangoProject/.venv/lib/python3.13/site-packages/asgiref/sync.py", line 518, in thread_handler
    raise exc_info[1]
  File "/Users/sergeizeliabovskii/Documents/python_ptojects/DjangoProject/.venv/lib/python3.13/site-packages/django/core/handlers/exception.py", line 42, in inner
    response = await get_response(request)
               ^^^^^^^^^^^^^^^^^^^^^^^^^^^
  File "/Users/sergeizeliabovskii/Documents/python_ptojects/DjangoProject/.venv/lib/python3.13/site-packages/django/core/handlers/base.py", line 235, in _get_response_async
    callback, callback_args, callback_kwargs = self.resolve_request(request)
                                               ~~~~~~~~~~~~~~~~~~~~^^^^^^^^^
  File "/Users/sergeizeliabovskii/Documents/python_ptojects/DjangoProject/.venv/lib/python3.13/site-packages/django/core/handlers/base.py", line 313, in resolve_request
    resolver_match = resolver.resolve(request.path_info)
  File "/Users/sergeizeliabovskii/Documents/python_ptojects/DjangoProject/.venv/lib/python3.13/site-packages/django/urls/resolvers.py", line 705, in resolve
    raise Resolver404({"tried": tried, "path": new_path})
django.urls.exceptions.Resolver404: {'tried': [[<URLResolver <URLPattern list> (admin:admin) 'admin/'>], [<URLResolver <module 'main.urls' from '/Users/sergeizeliabovskii/Documents/python_ptojects/DjangoProject/main/urls.py'> (None:None) 'api/v1/user/'>], [<URLResolver <module 'event.urls' from '/Users/sergeizeliabovskii/Documents/python_ptojects/DjangoProject/event/urls.py'> (None:None) 'api/v1/event/'>], [<URLResolver <module 'chat.urls' from '/Users/sergeizeliabovskii/Documents/python_ptojects/DjangoProject/chat/urls.py'> (None:None) 'api/v1/chat/'>]], 'path': 'user/support/1/'}

During handling of the above exception, another exception occurred:

Traceback (most recent call last):
  File "/Users/sergeizeliabovskii/Documents/python_ptojects/DjangoProject/.venv/lib/python3.13/site-packages/django/template/base.py", line 890, in _resolve_lookup
    raise TypeError
TypeError

During handling of the above exception, another exception occurred:

Traceback (most recent call last):
  File "/Users/sergeizeliabovskii/Documents/python_ptojects/DjangoProject/.venv/lib/python3.13/site-packages/django/template/base.py", line 901, in _resolve_lookup
    current = getattr(current, bit)
AttributeError: 'URLResolver' object has no attribute 'name'

During handling of the above exception, another exception occurred:

Traceback (most recent call last):
  File "/Users/sergeizeliabovskii/Documents/python_ptojects/DjangoProject/.venv/lib/python3.13/site-packages/django/template/base.py", line 907, in _resolve_lookup
    current = current[int(bit)]
                      ~~~^^^^^
ValueError: invalid literal for int() with base 10: 'name'

During handling of the above exception, another exception occurred:

Traceback (most recent call last):
  File "/Users/sergeizeliabovskii/Documents/python_ptojects/DjangoProject/.venv/lib/python3.13/site-packages/django/template/base.py", line 914, in _resolve_lookup
    raise VariableDoesNotExist(
    ^^^^^^^^^^^^^^^^^^^^^^^^^^^
    ...<2 lines>...
    )  # missing attribute
    ^
django.template.base.VariableDoesNotExist: Failed lookup for key [name] in <URLResolver <URLPattern list> (admin:admin) 'admin/'>
DEBUG 2025-05-27 02:23:26,422 base Exception while resolving variable 'name' in template 'unknown'.
Traceback (most recent call last):
  File "/Users/sergeizeliabovskii/Documents/python_ptojects/DjangoProject/.venv/lib/python3.13/site-packages/asgiref/sync.py", line 518, in thread_handler
    raise exc_info[1]
  File "/Users/sergeizeliabovskii/Documents/python_ptojects/DjangoProject/.venv/lib/python3.13/site-packages/django/core/handlers/exception.py", line 42, in inner
    response = await get_response(request)
               ^^^^^^^^^^^^^^^^^^^^^^^^^^^
  File "/Users/sergeizeliabovskii/Documents/python_ptojects/DjangoProject/.venv/lib/python3.13/site-packages/django/core/handlers/base.py", line 235, in _get_response_async
    callback, callback_args, callback_kwargs = self.resolve_request(request)
                                               ~~~~~~~~~~~~~~~~~~~~^^^^^^^^^
  File "/Users/sergeizeliabovskii/Documents/python_ptojects/DjangoProject/.venv/lib/python3.13/site-packages/django/core/handlers/base.py", line 313, in resolve_request
    resolver_match = resolver.resolve(request.path_info)
  File "/Users/sergeizeliabovskii/Documents/python_ptojects/DjangoProject/.venv/lib/python3.13/site-packages/django/urls/resolvers.py", line 705, in resolve
    raise Resolver404({"tried": tried, "path": new_path})
django.urls.exceptions.Resolver404: {'tried': [[<URLResolver <URLPattern list> (admin:admin) 'admin/'>], [<URLResolver <module 'main.urls' from '/Users/sergeizeliabovskii/Documents/python_ptojects/DjangoProject/main/urls.py'> (None:None) 'api/v1/user/'>], [<URLResolver <module 'event.urls' from '/Users/sergeizeliabovskii/Documents/python_ptojects/DjangoProject/event/urls.py'> (None:None) 'api/v1/event/'>], [<URLResolver <module 'chat.urls' from '/Users/sergeizeliabovskii/Documents/python_ptojects/DjangoProject/chat/urls.py'> (None:None) 'api/v1/chat/'>]], 'path': 'user/support/1/'}

During handling of the above exception, another exception occurred:

Traceback (most recent call last):
  File "/Users/sergeizeliabovskii/Documents/python_ptojects/DjangoProject/.venv/lib/python3.13/site-packages/django/template/base.py", line 890, in _resolve_lookup
    raise TypeError
TypeError

During handling of the above exception, another exception occurred:

Traceback (most recent call last):
  File "/Users/sergeizeliabovskii/Documents/python_ptojects/DjangoProject/.venv/lib/python3.13/site-packages/django/template/base.py", line 901, in _resolve_lookup
    current = getattr(current, bit)
AttributeError: 'URLResolver' object has no attribute 'name'

During handling of the above exception, another exception occurred:

Traceback (most recent call last):
  File "/Users/sergeizeliabovskii/Documents/python_ptojects/DjangoProject/.venv/lib/python3.13/site-packages/django/template/base.py", line 907, in _resolve_lookup
    current = current[int(bit)]
                      ~~~^^^^^
ValueError: invalid literal for int() with base 10: 'name'

During handling of the above exception, another exception occurred:

Traceback (most recent call last):
  File "/Users/sergeizeliabovskii/Documents/python_ptojects/DjangoProject/.venv/lib/python3.13/site-packages/django/template/base.py", line 914, in _resolve_lookup
    raise VariableDoesNotExist(
    ^^^^^^^^^^^^^^^^^^^^^^^^^^^
    ...<2 lines>...
    )  # missing attribute
    ^
django.template.base.VariableDoesNotExist: Failed lookup for key [name] in <URLResolver <module 'main.urls' from '/Users/sergeizeliabovskii/Documents/python_ptojects/DjangoProject/main/urls.py'> (None:None) 'api/v1/user/'>
DEBUG 2025-05-27 02:23:26,425 base Exception while resolving variable 'name' in template 'unknown'.
Traceback (most recent call last):
  File "/Users/sergeizeliabovskii/Documents/python_ptojects/DjangoProject/.venv/lib/python3.13/site-packages/asgiref/sync.py", line 518, in thread_handler
    raise exc_info[1]
  File "/Users/sergeizeliabovskii/Documents/python_ptojects/DjangoProject/.venv/lib/python3.13/site-packages/django/core/handlers/exception.py", line 42, in inner
    response = await get_response(request)
               ^^^^^^^^^^^^^^^^^^^^^^^^^^^
  File "/Users/sergeizeliabovskii/Documents/python_ptojects/DjangoProject/.venv/lib/python3.13/site-packages/django/core/handlers/base.py", line 235, in _get_response_async
    callback, callback_args, callback_kwargs = self.resolve_request(request)
                                               ~~~~~~~~~~~~~~~~~~~~^^^^^^^^^
  File "/Users/sergeizeliabovskii/Documents/python_ptojects/DjangoProject/.venv/lib/python3.13/site-packages/django/core/handlers/base.py", line 313, in resolve_request
    resolver_match = resolver.resolve(request.path_info)
  File "/Users/sergeizeliabovskii/Documents/python_ptojects/DjangoProject/.venv/lib/python3.13/site-packages/django/urls/resolvers.py", line 705, in resolve
    raise Resolver404({"tried": tried, "path": new_path})
django.urls.exceptions.Resolver404: {'tried': [[<URLResolver <URLPattern list> (admin:admin) 'admin/'>], [<URLResolver <module 'main.urls' from '/Users/sergeizeliabovskii/Documents/python_ptojects/DjangoProject/main/urls.py'> (None:None) 'api/v1/user/'>], [<URLResolver <module 'event.urls' from '/Users/sergeizeliabovskii/Documents/python_ptojects/DjangoProject/event/urls.py'> (None:None) 'api/v1/event/'>], [<URLResolver <module 'chat.urls' from '/Users/sergeizeliabovskii/Documents/python_ptojects/DjangoProject/chat/urls.py'> (None:None) 'api/v1/chat/'>]], 'path': 'user/support/1/'}

During handling of the above exception, another exception occurred:

Traceback (most recent call last):
  File "/Users/sergeizeliabovskii/Documents/python_ptojects/DjangoProject/.venv/lib/python3.13/site-packages/django/template/base.py", line 890, in _resolve_lookup
    raise TypeError
TypeError

During handling of the above exception, another exception occurred:

Traceback (most recent call last):
  File "/Users/sergeizeliabovskii/Documents/python_ptojects/DjangoProject/.venv/lib/python3.13/site-packages/django/template/base.py", line 901, in _resolve_lookup
    current = getattr(current, bit)
AttributeError: 'URLResolver' object has no attribute 'name'

During handling of the above exception, another exception occurred:

Traceback (most recent call last):
  File "/Users/sergeizeliabovskii/Documents/python_ptojects/DjangoProject/.venv/lib/python3.13/site-packages/django/template/base.py", line 907, in _resolve_lookup
    current = current[int(bit)]
                      ~~~^^^^^
ValueError: invalid literal for int() with base 10: 'name'

During handling of the above exception, another exception occurred:

Traceback (most recent call last):
  File "/Users/sergeizeliabovskii/Documents/python_ptojects/DjangoProject/.venv/lib/python3.13/site-packages/django/template/base.py", line 914, in _resolve_lookup
    raise VariableDoesNotExist(
    ^^^^^^^^^^^^^^^^^^^^^^^^^^^
    ...<2 lines>...
    )  # missing attribute
    ^
django.template.base.VariableDoesNotExist: Failed lookup for key [name] in <URLResolver <module 'event.urls' from '/Users/sergeizeliabovskii/Documents/python_ptojects/DjangoProject/event/urls.py'> (None:None) 'api/v1/event/'>
DEBUG 2025-05-27 02:23:26,429 base Exception while resolving variable 'name' in template 'unknown'.
Traceback (most recent call last):
  File "/Users/sergeizeliabovskii/Documents/python_ptojects/DjangoProject/.venv/lib/python3.13/site-packages/asgiref/sync.py", line 518, in thread_handler
    raise exc_info[1]
  File "/Users/sergeizeliabovskii/Documents/python_ptojects/DjangoProject/.venv/lib/python3.13/site-packages/django/core/handlers/exception.py", line 42, in inner
    response = await get_response(request)
               ^^^^^^^^^^^^^^^^^^^^^^^^^^^
  File "/Users/sergeizeliabovskii/Documents/python_ptojects/DjangoProject/.venv/lib/python3.13/site-packages/django/core/handlers/base.py", line 235, in _get_response_async
    callback, callback_args, callback_kwargs = self.resolve_request(request)
                                               ~~~~~~~~~~~~~~~~~~~~^^^^^^^^^
  File "/Users/sergeizeliabovskii/Documents/python_ptojects/DjangoProject/.venv/lib/python3.13/site-packages/django/core/handlers/base.py", line 313, in resolve_request
    resolver_match = resolver.resolve(request.path_info)
  File "/Users/sergeizeliabovskii/Documents/python_ptojects/DjangoProject/.venv/lib/python3.13/site-packages/django/urls/resolvers.py", line 705, in resolve
    raise Resolver404({"tried": tried, "path": new_path})
django.urls.exceptions.Resolver404: {'tried': [[<URLResolver <URLPattern list> (admin:admin) 'admin/'>], [<URLResolver <module 'main.urls' from '/Users/sergeizeliabovskii/Documents/python_ptojects/DjangoProject/main/urls.py'> (None:None) 'api/v1/user/'>], [<URLResolver <module 'event.urls' from '/Users/sergeizeliabovskii/Documents/python_ptojects/DjangoProject/event/urls.py'> (None:None) 'api/v1/event/'>], [<URLResolver <module 'chat.urls' from '/Users/sergeizeliabovskii/Documents/python_ptojects/DjangoProject/chat/urls.py'> (None:None) 'api/v1/chat/'>]], 'path': 'user/support/1/'}

During handling of the above exception, another exception occurred:

Traceback (most recent call last):
  File "/Users/sergeizeliabovskii/Documents/python_ptojects/DjangoProject/.venv/lib/python3.13/site-packages/django/template/base.py", line 890, in _resolve_lookup
    raise TypeError
TypeError

During handling of the above exception, another exception occurred:

Traceback (most recent call last):
  File "/Users/sergeizeliabovskii/Documents/python_ptojects/DjangoProject/.venv/lib/python3.13/site-packages/django/template/base.py", line 901, in _resolve_lookup
    current = getattr(current, bit)
AttributeError: 'URLResolver' object has no attribute 'name'

During handling of the above exception, another exception occurred:

Traceback (most recent call last):
  File "/Users/sergeizeliabovskii/Documents/python_ptojects/DjangoProject/.venv/lib/python3.13/site-packages/django/template/base.py", line 907, in _resolve_lookup
    current = current[int(bit)]
                      ~~~^^^^^
ValueError: invalid literal for int() with base 10: 'name'

During handling of the above exception, another exception occurred:

Traceback (most recent call last):
  File "/Users/sergeizeliabovskii/Documents/python_ptojects/DjangoProject/.venv/lib/python3.13/site-packages/django/template/base.py", line 914, in _resolve_lookup
    raise VariableDoesNotExist(
    ^^^^^^^^^^^^^^^^^^^^^^^^^^^
    ...<2 lines>...
    )  # missing attribute
    ^
django.template.base.VariableDoesNotExist: Failed lookup for key [name] in <URLResolver <module 'chat.urls' from '/Users/sergeizeliabovskii/Documents/python_ptojects/DjangoProject/chat/urls.py'> (None:None) 'api/v1/chat/'>
WARNING 2025-05-27 02:23:26,435 log Not Found: /user/support/1/
DEBUG 2025-05-27 02:27:44,976 base Exception while resolving variable 'name' in template 'unknown'.
Traceback (most recent call last):
  File "/Users/sergeizeliabovskii/Documents/python_ptojects/DjangoProject/.venv/lib/python3.13/site-packages/asgiref/sync.py", line 518, in thread_handler
    raise exc_info[1]
  File "/Users/sergeizeliabovskii/Documents/python_ptojects/DjangoProject/.venv/lib/python3.13/site-packages/django/core/handlers/exception.py", line 42, in inner
    response = await get_response(request)
               ^^^^^^^^^^^^^^^^^^^^^^^^^^^
  File "/Users/sergeizeliabovskii/Documents/python_ptojects/DjangoProject/.venv/lib/python3.13/site-packages/django/core/handlers/base.py", line 235, in _get_response_async
    callback, callback_args, callback_kwargs = self.resolve_request(request)
                                               ~~~~~~~~~~~~~~~~~~~~^^^^^^^^^
  File "/Users/sergeizeliabovskii/Documents/python_ptojects/DjangoProject/.venv/lib/python3.13/site-packages/django/core/handlers/base.py", line 313, in resolve_request
    resolver_match = resolver.resolve(request.path_info)
  File "/Users/sergeizeliabovskii/Documents/python_ptojects/DjangoProject/.venv/lib/python3.13/site-packages/django/urls/resolvers.py", line 705, in resolve
    raise Resolver404({"tried": tried, "path": new_path})
django.urls.exceptions.Resolver404: {'tried': [[<URLResolver <URLPattern list> (admin:admin) 'admin/'>], [<URLResolver <module 'main.urls' from '/Users/sergeizeliabovskii/Documents/python_ptojects/DjangoProject/main/urls.py'> (None:None) 'api/v1/user/'>], [<URLResolver <module 'event.urls' from '/Users/sergeizeliabovskii/Documents/python_ptojects/DjangoProject/event/urls.py'> (None:None) 'api/v1/event/'>], [<URLResolver <module 'chat.urls' from '/Users/sergeizeliabovskii/Documents/python_ptojects/DjangoProject/chat/urls.py'> (None:None) 'api/v1/chat/'>]], 'path': 'user/support/1/'}

During handling of the above exception, another exception occurred:

Traceback (most recent call last):
  File "/Users/sergeizeliabovskii/Documents/python_ptojects/DjangoProject/.venv/lib/python3.13/site-packages/django/template/base.py", line 890, in _resolve_lookup
    raise TypeError
TypeError

During handling of the above exception, another exception occurred:

Traceback (most recent call last):
  File "/Users/sergeizeliabovskii/Documents/python_ptojects/DjangoProject/.venv/lib/python3.13/site-packages/django/template/base.py", line 901, in _resolve_lookup
    current = getattr(current, bit)
AttributeError: 'URLResolver' object has no attribute 'name'

During handling of the above exception, another exception occurred:

Traceback (most recent call last):
  File "/Users/sergeizeliabovskii/Documents/python_ptojects/DjangoProject/.venv/lib/python3.13/site-packages/django/template/base.py", line 907, in _resolve_lookup
    current = current[int(bit)]
                      ~~~^^^^^
ValueError: invalid literal for int() with base 10: 'name'

During handling of the above exception, another exception occurred:

Traceback (most recent call last):
  File "/Users/sergeizeliabovskii/Documents/python_ptojects/DjangoProject/.venv/lib/python3.13/site-packages/django/template/base.py", line 914, in _resolve_lookup
    raise VariableDoesNotExist(
    ^^^^^^^^^^^^^^^^^^^^^^^^^^^
    ...<2 lines>...
    )  # missing attribute
    ^
django.template.base.VariableDoesNotExist: Failed lookup for key [name] in <URLResolver <URLPattern list> (admin:admin) 'admin/'>
DEBUG 2025-05-27 02:27:44,982 base Exception while resolving variable 'name' in template 'unknown'.
Traceback (most recent call last):
  File "/Users/sergeizeliabovskii/Documents/python_ptojects/DjangoProject/.venv/lib/python3.13/site-packages/asgiref/sync.py", line 518, in thread_handler
    raise exc_info[1]
  File "/Users/sergeizeliabovskii/Documents/python_ptojects/DjangoProject/.venv/lib/python3.13/site-packages/django/core/handlers/exception.py", line 42, in inner
    response = await get_response(request)
               ^^^^^^^^^^^^^^^^^^^^^^^^^^^
  File "/Users/sergeizeliabovskii/Documents/python_ptojects/DjangoProject/.venv/lib/python3.13/site-packages/django/core/handlers/base.py", line 235, in _get_response_async
    callback, callback_args, callback_kwargs = self.resolve_request(request)
                                               ~~~~~~~~~~~~~~~~~~~~^^^^^^^^^
  File "/Users/sergeizeliabovskii/Documents/python_ptojects/DjangoProject/.venv/lib/python3.13/site-packages/django/core/handlers/base.py", line 313, in resolve_request
    resolver_match = resolver.resolve(request.path_info)
  File "/Users/sergeizeliabovskii/Documents/python_ptojects/DjangoProject/.venv/lib/python3.13/site-packages/django/urls/resolvers.py", line 705, in resolve
    raise Resolver404({"tried": tried, "path": new_path})
django.urls.exceptions.Resolver404: {'tried': [[<URLResolver <URLPattern list> (admin:admin) 'admin/'>], [<URLResolver <module 'main.urls' from '/Users/sergeizeliabovskii/Documents/python_ptojects/DjangoProject/main/urls.py'> (None:None) 'api/v1/user/'>], [<URLResolver <module 'event.urls' from '/Users/sergeizeliabovskii/Documents/python_ptojects/DjangoProject/event/urls.py'> (None:None) 'api/v1/event/'>], [<URLResolver <module 'chat.urls' from '/Users/sergeizeliabovskii/Documents/python_ptojects/DjangoProject/chat/urls.py'> (None:None) 'api/v1/chat/'>]], 'path': 'user/support/1/'}

During handling of the above exception, another exception occurred:

Traceback (most recent call last):
  File "/Users/sergeizeliabovskii/Documents/python_ptojects/DjangoProject/.venv/lib/python3.13/site-packages/django/template/base.py", line 890, in _resolve_lookup
    raise TypeError
TypeError

During handling of the above exception, another exception occurred:

Traceback (most recent call last):
  File "/Users/sergeizeliabovskii/Documents/python_ptojects/DjangoProject/.venv/lib/python3.13/site-packages/django/template/base.py", line 901, in _resolve_lookup
    current = getattr(current, bit)
AttributeError: 'URLResolver' object has no attribute 'name'

During handling of the above exception, another exception occurred:

Traceback (most recent call last):
  File "/Users/sergeizeliabovskii/Documents/python_ptojects/DjangoProject/.venv/lib/python3.13/site-packages/django/template/base.py", line 907, in _resolve_lookup
    current = current[int(bit)]
                      ~~~^^^^^
ValueError: invalid literal for int() with base 10: 'name'

During handling of the above exception, another exception occurred:

Traceback (most recent call last):
  File "/Users/sergeizeliabovskii/Documents/python_ptojects/DjangoProject/.venv/lib/python3.13/site-packages/django/template/base.py", line 914, in _resolve_lookup
    raise VariableDoesNotExist(
    ^^^^^^^^^^^^^^^^^^^^^^^^^^^
    ...<2 lines>...
    )  # missing attribute
    ^
django.template.base.VariableDoesNotExist: Failed lookup for key [name] in <URLResolver <module 'main.urls' from '/Users/sergeizeliabovskii/Documents/python_ptojects/DjangoProject/main/urls.py'> (None:None) 'api/v1/user/'>
DEBUG 2025-05-27 02:27:44,988 base Exception while resolving variable 'name' in template 'unknown'.
Traceback (most recent call last):
  File "/Users/sergeizeliabovskii/Documents/python_ptojects/DjangoProject/.venv/lib/python3.13/site-packages/asgiref/sync.py", line 518, in thread_handler
    raise exc_info[1]
  File "/Users/sergeizeliabovskii/Documents/python_ptojects/DjangoProject/.venv/lib/python3.13/site-packages/django/core/handlers/exception.py", line 42, in inner
    response = await get_response(request)
               ^^^^^^^^^^^^^^^^^^^^^^^^^^^
  File "/Users/sergeizeliabovskii/Documents/python_ptojects/DjangoProject/.venv/lib/python3.13/site-packages/django/core/handlers/base.py", line 235, in _get_response_async
    callback, callback_args, callback_kwargs = self.resolve_request(request)
                                               ~~~~~~~~~~~~~~~~~~~~^^^^^^^^^
  File "/Users/sergeizeliabovskii/Documents/python_ptojects/DjangoProject/.venv/lib/python3.13/site-packages/django/core/handlers/base.py", line 313, in resolve_request
    resolver_match = resolver.resolve(request.path_info)
  File "/Users/sergeizeliabovskii/Documents/python_ptojects/DjangoProject/.venv/lib/python3.13/site-packages/django/urls/resolvers.py", line 705, in resolve
    raise Resolver404({"tried": tried, "path": new_path})
django.urls.exceptions.Resolver404: {'tried': [[<URLResolver <URLPattern list> (admin:admin) 'admin/'>], [<URLResolver <module 'main.urls' from '/Users/sergeizeliabovskii/Documents/python_ptojects/DjangoProject/main/urls.py'> (None:None) 'api/v1/user/'>], [<URLResolver <module 'event.urls' from '/Users/sergeizeliabovskii/Documents/python_ptojects/DjangoProject/event/urls.py'> (None:None) 'api/v1/event/'>], [<URLResolver <module 'chat.urls' from '/Users/sergeizeliabovskii/Documents/python_ptojects/DjangoProject/chat/urls.py'> (None:None) 'api/v1/chat/'>]], 'path': 'user/support/1/'}

During handling of the above exception, another exception occurred:

Traceback (most recent call last):
  File "/Users/sergeizeliabovskii/Documents/python_ptojects/DjangoProject/.venv/lib/python3.13/site-packages/django/template/base.py", line 890, in _resolve_lookup
    raise TypeError
TypeError

During handling of the above exception, another exception occurred:

Traceback (most recent call last):
  File "/Users/sergeizeliabovskii/Documents/python_ptojects/DjangoProject/.venv/lib/python3.13/site-packages/django/template/base.py", line 901, in _resolve_lookup
    current = getattr(current, bit)
AttributeError: 'URLResolver' object has no attribute 'name'

During handling of the above exception, another exception occurred:

Traceback (most recent call last):
  File "/Users/sergeizeliabovskii/Documents/python_ptojects/DjangoProject/.venv/lib/python3.13/site-packages/django/template/base.py", line 907, in _resolve_lookup
    current = current[int(bit)]
                      ~~~^^^^^
ValueError: invalid literal for int() with base 10: 'name'

During handling of the above exception, another exception occurred:

Traceback (most recent call last):
  File "/Users/sergeizeliabovskii/Documents/python_ptojects/DjangoProject/.venv/lib/python3.13/site-packages/django/template/base.py", line 914, in _resolve_lookup
    raise VariableDoesNotExist(
    ^^^^^^^^^^^^^^^^^^^^^^^^^^^
    ...<2 lines>...
    )  # missing attribute
    ^
django.template.base.VariableDoesNotExist: Failed lookup for key [name] in <URLResolver <module 'event.urls' from '/Users/sergeizeliabovskii/Documents/python_ptojects/DjangoProject/event/urls.py'> (None:None) 'api/v1/event/'>
DEBUG 2025-05-27 02:27:44,990 base Exception while resolving variable 'name' in template 'unknown'.
Traceback (most recent call last):
  File "/Users/sergeizeliabovskii/Documents/python_ptojects/DjangoProject/.venv/lib/python3.13/site-packages/asgiref/sync.py", line 518, in thread_handler
    raise exc_info[1]
  File "/Users/sergeizeliabovskii/Documents/python_ptojects/DjangoProject/.venv/lib/python3.13/site-packages/django/core/handlers/exception.py", line 42, in inner
    response = await get_response(request)
               ^^^^^^^^^^^^^^^^^^^^^^^^^^^
  File "/Users/sergeizeliabovskii/Documents/python_ptojects/DjangoProject/.venv/lib/python3.13/site-packages/django/core/handlers/base.py", line 235, in _get_response_async
    callback, callback_args, callback_kwargs = self.resolve_request(request)
                                               ~~~~~~~~~~~~~~~~~~~~^^^^^^^^^
  File "/Users/sergeizeliabovskii/Documents/python_ptojects/DjangoProject/.venv/lib/python3.13/site-packages/django/core/handlers/base.py", line 313, in resolve_request
    resolver_match = resolver.resolve(request.path_info)
  File "/Users/sergeizeliabovskii/Documents/python_ptojects/DjangoProject/.venv/lib/python3.13/site-packages/django/urls/resolvers.py", line 705, in resolve
    raise Resolver404({"tried": tried, "path": new_path})
django.urls.exceptions.Resolver404: {'tried': [[<URLResolver <URLPattern list> (admin:admin) 'admin/'>], [<URLResolver <module 'main.urls' from '/Users/sergeizeliabovskii/Documents/python_ptojects/DjangoProject/main/urls.py'> (None:None) 'api/v1/user/'>], [<URLResolver <module 'event.urls' from '/Users/sergeizeliabovskii/Documents/python_ptojects/DjangoProject/event/urls.py'> (None:None) 'api/v1/event/'>], [<URLResolver <module 'chat.urls' from '/Users/sergeizeliabovskii/Documents/python_ptojects/DjangoProject/chat/urls.py'> (None:None) 'api/v1/chat/'>]], 'path': 'user/support/1/'}

During handling of the above exception, another exception occurred:

Traceback (most recent call last):
  File "/Users/sergeizeliabovskii/Documents/python_ptojects/DjangoProject/.venv/lib/python3.13/site-packages/django/template/base.py", line 890, in _resolve_lookup
    raise TypeError
TypeError

During handling of the above exception, another exception occurred:

Traceback (most recent call last):
  File "/Users/sergeizeliabovskii/Documents/python_ptojects/DjangoProject/.venv/lib/python3.13/site-packages/django/template/base.py", line 901, in _resolve_lookup
    current = getattr(current, bit)
AttributeError: 'URLResolver' object has no attribute 'name'

During handling of the above exception, another exception occurred:

Traceback (most recent call last):
  File "/Users/sergeizeliabovskii/Documents/python_ptojects/DjangoProject/.venv/lib/python3.13/site-packages/django/template/base.py", line 907, in _resolve_lookup
    current = current[int(bit)]
                      ~~~^^^^^
ValueError: invalid literal for int() with base 10: 'name'

During handling of the above exception, another exception occurred:

Traceback (most recent call last):
  File "/Users/sergeizeliabovskii/Documents/python_ptojects/DjangoProject/.venv/lib/python3.13/site-packages/django/template/base.py", line 914, in _resolve_lookup
    raise VariableDoesNotExist(
    ^^^^^^^^^^^^^^^^^^^^^^^^^^^
    ...<2 lines>...
    )  # missing attribute
    ^
django.template.base.VariableDoesNotExist: Failed lookup for key [name] in <URLResolver <module 'chat.urls' from '/Users/sergeizeliabovskii/Documents/python_ptojects/DjangoProject/chat/urls.py'> (None:None) 'api/v1/chat/'>
WARNING 2025-05-27 02:27:44,995 log Not Found: /user/support/1/
DEBUG 2025-05-27 03:44:03,895 base Exception while resolving variable 'name' in template 'unknown'.
Traceback (most recent call last):
  File "/Users/sergeizeliabovskii/Documents/python_ptojects/DjangoProject/.venv/lib/python3.13/site-packages/asgiref/sync.py", line 518, in thread_handler
    raise exc_info[1]
  File "/Users/sergeizeliabovskii/Documents/python_ptojects/DjangoProject/.venv/lib/python3.13/site-packages/django/core/handlers/exception.py", line 42, in inner
    response = await get_response(request)
               ^^^^^^^^^^^^^^^^^^^^^^^^^^^
  File "/Users/sergeizeliabovskii/Documents/python_ptojects/DjangoProject/.venv/lib/python3.13/site-packages/django/core/handlers/base.py", line 235, in _get_response_async
    callback, callback_args, callback_kwargs = self.resolve_request(request)
                                               ~~~~~~~~~~~~~~~~~~~~^^^^^^^^^
  File "/Users/sergeizeliabovskii/Documents/python_ptojects/DjangoProject/.venv/lib/python3.13/site-packages/django/core/handlers/base.py", line 313, in resolve_request
    resolver_match = resolver.resolve(request.path_info)
  File "/Users/sergeizeliabovskii/Documents/python_ptojects/DjangoProject/.venv/lib/python3.13/site-packages/django/urls/resolvers.py", line 705, in resolve
    raise Resolver404({"tried": tried, "path": new_path})
django.urls.exceptions.Resolver404: {'tried': [[<URLResolver <URLPattern list> (admin:admin) 'admin/'>], [<URLResolver <module 'main.urls' from '/Users/sergeizeliabovskii/Documents/python_ptojects/DjangoProject/main/urls.py'> (None:None) 'api/v1/user/'>, <URLPattern 'registration/' [name='registration']>], [<URLResolver <module 'main.urls' from '/Users/sergeizeliabovskii/Documents/python_ptojects/DjangoProject/main/urls.py'> (None:None) 'api/v1/user/'>, <URLPattern 'login/' [name='login']>], [<URLResolver <module 'main.urls' from '/Users/sergeizeliabovskii/Documents/python_ptojects/DjangoProject/main/urls.py'> (None:None) 'api/v1/user/'>, <URLPattern 'edit/<int:user_id>/' [name='edit_userinfo']>], [<URLResolver <module 'main.urls' from '/Users/sergeizeliabovskii/Documents/python_ptojects/DjangoProject/main/urls.py'> (None:None) 'api/v1/user/'>, <URLPattern '<int:user_id>/' [name='user']>], [<URLResolver <module 'main.urls' from '/Users/sergeizeliabovskii/Documents/python_ptojects/DjangoProject/main/urls.py'> (None:None) 'api/v1/user/'>, <URLPattern 'edit/contact/<int:user_id>/' [name='edit_emergency_contact']>], [<URLResolver <module 'main.urls' from '/Users/sergeizeliabovskii/Documents/python_ptojects/DjangoProject/main/urls.py'> (None:None) 'api/v1/user/'>, <URLPattern 'music/' [name='get_music']>], [<URLResolver <module 'main.urls' from '/Users/sergeizeliabovskii/Documents/python_ptojects/DjangoProject/main/urls.py'> (None:None) 'api/v1/user/'>, <URLPattern 'music/edit/<int:user_id>/' [name='set_music']>], [<URLResolver <module 'event.urls' from '/Users/sergeizeliabovskii/Documents/python_ptojects/DjangoProject/event/urls.py'> (None:None) 'api/v1/event/'>], [<URLResolver <module 'chat.urls' from '/Users/sergeizeliabovskii/Documents/python_ptojects/DjangoProject/chat/urls.py'> (None:None) 'api/v1/chat/'>]], 'path': 'api/v1/user/1'}

During handling of the above exception, another exception occurred:

Traceback (most recent call last):
  File "/Users/sergeizeliabovskii/Documents/python_ptojects/DjangoProject/.venv/lib/python3.13/site-packages/django/template/base.py", line 890, in _resolve_lookup
    raise TypeError
TypeError

During handling of the above exception, another exception occurred:

Traceback (most recent call last):
  File "/Users/sergeizeliabovskii/Documents/python_ptojects/DjangoProject/.venv/lib/python3.13/site-packages/django/template/base.py", line 901, in _resolve_lookup
    current = getattr(current, bit)
AttributeError: 'URLResolver' object has no attribute 'name'

During handling of the above exception, another exception occurred:

Traceback (most recent call last):
  File "/Users/sergeizeliabovskii/Documents/python_ptojects/DjangoProject/.venv/lib/python3.13/site-packages/django/template/base.py", line 907, in _resolve_lookup
    current = current[int(bit)]
                      ~~~^^^^^
ValueError: invalid literal for int() with base 10: 'name'

During handling of the above exception, another exception occurred:

Traceback (most recent call last):
  File "/Users/sergeizeliabovskii/Documents/python_ptojects/DjangoProject/.venv/lib/python3.13/site-packages/django/template/base.py", line 914, in _resolve_lookup
    raise VariableDoesNotExist(
    ^^^^^^^^^^^^^^^^^^^^^^^^^^^
    ...<2 lines>...
    )  # missing attribute
    ^
django.template.base.VariableDoesNotExist: Failed lookup for key [name] in <URLResolver <URLPattern list> (admin:admin) 'admin/'>
DEBUG 2025-05-27 03:44:03,902 base Exception while resolving variable 'name' in template 'unknown'.
Traceback (most recent call last):
  File "/Users/sergeizeliabovskii/Documents/python_ptojects/DjangoProject/.venv/lib/python3.13/site-packages/asgiref/sync.py", line 518, in thread_handler
    raise exc_info[1]
  File "/Users/sergeizeliabovskii/Documents/python_ptojects/DjangoProject/.venv/lib/python3.13/site-packages/django/core/handlers/exception.py", line 42, in inner
    response = await get_response(request)
               ^^^^^^^^^^^^^^^^^^^^^^^^^^^
  File "/Users/sergeizeliabovskii/Documents/python_ptojects/DjangoProject/.venv/lib/python3.13/site-packages/django/core/handlers/base.py", line 235, in _get_response_async
    callback, callback_args, callback_kwargs = self.resolve_request(request)
                                               ~~~~~~~~~~~~~~~~~~~~^^^^^^^^^
  File "/Users/sergeizeliabovskii/Documents/python_ptojects/DjangoProject/.venv/lib/python3.13/site-packages/django/core/handlers/base.py", line 313, in resolve_request
    resolver_match = resolver.resolve(request.path_info)
  File "/Users/sergeizeliabovskii/Documents/python_ptojects/DjangoProject/.venv/lib/python3.13/site-packages/django/urls/resolvers.py", line 705, in resolve
    raise Resolver404({"tried": tried, "path": new_path})
django.urls.exceptions.Resolver404: {'tried': [[<URLResolver <URLPattern list> (admin:admin) 'admin/'>], [<URLResolver <module 'main.urls' from '/Users/sergeizeliabovskii/Documents/python_ptojects/DjangoProject/main/urls.py'> (None:None) 'api/v1/user/'>, <URLPattern 'registration/' [name='registration']>], [<URLResolver <module 'main.urls' from '/Users/sergeizeliabovskii/Documents/python_ptojects/DjangoProject/main/urls.py'> (None:None) 'api/v1/user/'>, <URLPattern 'login/' [name='login']>], [<URLResolver <module 'main.urls' from '/Users/sergeizeliabovskii/Documents/python_ptojects/DjangoProject/main/urls.py'> (None:None) 'api/v1/user/'>, <URLPattern 'edit/<int:user_id>/' [name='edit_userinfo']>], [<URLResolver <module 'main.urls' from '/Users/sergeizeliabovskii/Documents/python_ptojects/DjangoProject/main/urls.py'> (None:None) 'api/v1/user/'>, <URLPattern '<int:user_id>/' [name='user']>], [<URLResolver <module 'main.urls' from '/Users/sergeizeliabovskii/Documents/python_ptojects/DjangoProject/main/urls.py'> (None:None) 'api/v1/user/'>, <URLPattern 'edit/contact/<int:user_id>/' [name='edit_emergency_contact']>], [<URLResolver <module 'main.urls' from '/Users/sergeizeliabovskii/Documents/python_ptojects/DjangoProject/main/urls.py'> (None:None) 'api/v1/user/'>, <URLPattern 'music/' [name='get_music']>], [<URLResolver <module 'main.urls' from '/Users/sergeizeliabovskii/Documents/python_ptojects/DjangoProject/main/urls.py'> (None:None) 'api/v1/user/'>, <URLPattern 'music/edit/<int:user_id>/' [name='set_music']>], [<URLResolver <module 'event.urls' from '/Users/sergeizeliabovskii/Documents/python_ptojects/DjangoProject/event/urls.py'> (None:None) 'api/v1/event/'>], [<URLResolver <module 'chat.urls' from '/Users/sergeizeliabovskii/Documents/python_ptojects/DjangoProject/chat/urls.py'> (None:None) 'api/v1/chat/'>]], 'path': 'api/v1/user/1'}

During handling of the above exception, another exception occurred:

Traceback (most recent call last):
  File "/Users/sergeizeliabovskii/Documents/python_ptojects/DjangoProject/.venv/lib/python3.13/site-packages/django/template/base.py", line 890, in _resolve_lookup
    raise TypeError
TypeError

During handling of the above exception, another exception occurred:

Traceback (most recent call last):
  File "/Users/sergeizeliabovskii/Documents/python_ptojects/DjangoProject/.venv/lib/python3.13/site-packages/django/template/base.py", line 901, in _resolve_lookup
    current = getattr(current, bit)
AttributeError: 'URLResolver' object has no attribute 'name'

During handling of the above exception, another exception occurred:

Traceback (most recent call last):
  File "/Users/sergeizeliabovskii/Documents/python_ptojects/DjangoProject/.venv/lib/python3.13/site-packages/django/template/base.py", line 907, in _resolve_lookup
    current = current[int(bit)]
                      ~~~^^^^^
ValueError: invalid literal for int() with base 10: 'name'

During handling of the above exception, another exception occurred:

Traceback (most recent call last):
  File "/Users/sergeizeliabovskii/Documents/python_ptojects/DjangoProject/.venv/lib/python3.13/site-packages/django/template/base.py", line 914, in _resolve_lookup
    raise VariableDoesNotExist(
    ^^^^^^^^^^^^^^^^^^^^^^^^^^^
    ...<2 lines>...
    )  # missing attribute
    ^
django.template.base.VariableDoesNotExist: Failed lookup for key [name] in <URLResolver <module 'event.urls' from '/Users/sergeizeliabovskii/Documents/python_ptojects/DjangoProject/event/urls.py'> (None:None) 'api/v1/event/'>
DEBUG 2025-05-27 03:44:03,905 base Exception while resolving variable 'name' in template 'unknown'.
Traceback (most recent call last):
  File "/Users/sergeizeliabovskii/Documents/python_ptojects/DjangoProject/.venv/lib/python3.13/site-packages/asgiref/sync.py", line 518, in thread_handler
    raise exc_info[1]
  File "/Users/sergeizeliabovskii/Documents/python_ptojects/DjangoProject/.venv/lib/python3.13/site-packages/django/core/handlers/exception.py", line 42, in inner
    response = await get_response(request)
               ^^^^^^^^^^^^^^^^^^^^^^^^^^^
  File "/Users/sergeizeliabovskii/Documents/python_ptojects/DjangoProject/.venv/lib/python3.13/site-packages/django/core/handlers/base.py", line 235, in _get_response_async
    callback, callback_args, callback_kwargs = self.resolve_request(request)
                                               ~~~~~~~~~~~~~~~~~~~~^^^^^^^^^
  File "/Users/sergeizeliabovskii/Documents/python_ptojects/DjangoProject/.venv/lib/python3.13/site-packages/django/core/handlers/base.py", line 313, in resolve_request
    resolver_match = resolver.resolve(request.path_info)
  File "/Users/sergeizeliabovskii/Documents/python_ptojects/DjangoProject/.venv/lib/python3.13/site-packages/django/urls/resolvers.py", line 705, in resolve
    raise Resolver404({"tried": tried, "path": new_path})
django.urls.exceptions.Resolver404: {'tried': [[<URLResolver <URLPattern list> (admin:admin) 'admin/'>], [<URLResolver <module 'main.urls' from '/Users/sergeizeliabovskii/Documents/python_ptojects/DjangoProject/main/urls.py'> (None:None) 'api/v1/user/'>, <URLPattern 'registration/' [name='registration']>], [<URLResolver <module 'main.urls' from '/Users/sergeizeliabovskii/Documents/python_ptojects/DjangoProject/main/urls.py'> (None:None) 'api/v1/user/'>, <URLPattern 'login/' [name='login']>], [<URLResolver <module 'main.urls' from '/Users/sergeizeliabovskii/Documents/python_ptojects/DjangoProject/main/urls.py'> (None:None) 'api/v1/user/'>, <URLPattern 'edit/<int:user_id>/' [name='edit_userinfo']>], [<URLResolver <module 'main.urls' from '/Users/sergeizeliabovskii/Documents/python_ptojects/DjangoProject/main/urls.py'> (None:None) 'api/v1/user/'>, <URLPattern '<int:user_id>/' [name='user']>], [<URLResolver <module 'main.urls' from '/Users/sergeizeliabovskii/Documents/python_ptojects/DjangoProject/main/urls.py'> (None:None) 'api/v1/user/'>, <URLPattern 'edit/contact/<int:user_id>/' [name='edit_emergency_contact']>], [<URLResolver <module 'main.urls' from '/Users/sergeizeliabovskii/Documents/python_ptojects/DjangoProject/main/urls.py'> (None:None) 'api/v1/user/'>, <URLPattern 'music/' [name='get_music']>], [<URLResolver <module 'main.urls' from '/Users/sergeizeliabovskii/Documents/python_ptojects/DjangoProject/main/urls.py'> (None:None) 'api/v1/user/'>, <URLPattern 'music/edit/<int:user_id>/' [name='set_music']>], [<URLResolver <module 'event.urls' from '/Users/sergeizeliabovskii/Documents/python_ptojects/DjangoProject/event/urls.py'> (None:None) 'api/v1/event/'>], [<URLResolver <module 'chat.urls' from '/Users/sergeizeliabovskii/Documents/python_ptojects/DjangoProject/chat/urls.py'> (None:None) 'api/v1/chat/'>]], 'path': 'api/v1/user/1'}

During handling of the above exception, another exception occurred:

Traceback (most recent call last):
  File "/Users/sergeizeliabovskii/Documents/python_ptojects/DjangoProject/.venv/lib/python3.13/site-packages/django/template/base.py", line 890, in _resolve_lookup
    raise TypeError
TypeError

During handling of the above exception, another exception occurred:

Traceback (most recent call last):
  File "/Users/sergeizeliabovskii/Documents/python_ptojects/DjangoProject/.venv/lib/python3.13/site-packages/django/template/base.py", line 901, in _resolve_lookup
    current = getattr(current, bit)
AttributeError: 'URLResolver' object has no attribute 'name'

During handling of the above exception, another exception occurred:

Traceback (most recent call last):
  File "/Users/sergeizeliabovskii/Documents/python_ptojects/DjangoProject/.venv/lib/python3.13/site-packages/django/template/base.py", line 907, in _resolve_lookup
    current = current[int(bit)]
                      ~~~^^^^^
ValueError: invalid literal for int() with base 10: 'name'

During handling of the above exception, another exception occurred:

Traceback (most recent call last):
  File "/Users/sergeizeliabovskii/Documents/python_ptojects/DjangoProject/.venv/lib/python3.13/site-packages/django/template/base.py", line 914, in _resolve_lookup
    raise VariableDoesNotExist(
    ^^^^^^^^^^^^^^^^^^^^^^^^^^^
    ...<2 lines>...
    )  # missing attribute
    ^
django.template.base.VariableDoesNotExist: Failed lookup for key [name] in <URLResolver <module 'chat.urls' from '/Users/sergeizeliabovskii/Documents/python_ptojects/DjangoProject/chat/urls.py'> (None:None) 'api/v1/chat/'>
DEBUG 2025-05-27 03:44:04,196 utils (0.007) SELECT "authtoken_token"."key", "authtoken_token"."user_id", "authtoken_token"."created", "auth_user"."id", "auth_user"."password", "auth_user"."last_login", "auth_user"."is_superuser", "auth_user"."username", "auth_user"."first_name", "auth_user"."last_name", "auth_user"."email", "auth_user"."is_staff", "auth_user"."is_active", "auth_user"."date_joined" FROM "authtoken_token" INNER JOIN "auth_user" ON ("authtoken_token"."user_id" = "auth_user"."id") WHERE "authtoken_token"."key" = '889e10d16483c21f9b775f9bf98ecff96f7af71c' LIMIT 21; args=('889e10d16483c21f9b775f9bf98ecff96f7af71c',); alias=default
DEBUG 2025-05-27 03:44:04,199 utils (0.001) SELECT "main_userinfo"."id", "main_userinfo"."user_id", "main_userinfo"."age", "main_userinfo"."location", "main_userinfo"."military_status", "main_userinfo"."ptsd_level", "main_userinfo"."music_id", "main_userinfo"."therapist_contact_id", "main_userinfo"."scenario_id" FROM "main_userinfo" WHERE "main_userinfo"."user_id" = 1 LIMIT 21; args=(1,); alias=default
DEBUG 2025-05-27 03:44:04,202 utils (0.000) SELECT "auth_user"."id", "auth_user"."password", "auth_user"."last_login", "auth_user"."is_superuser", "auth_user"."username", "auth_user"."first_name", "auth_user"."last_name", "auth_user"."email", "auth_user"."is_staff", "auth_user"."is_active", "auth_user"."date_joined" FROM "auth_user" WHERE "auth_user"."id" = 1 LIMIT 21; args=(1,); alias=default
DEBUG 2025-05-27 04:23:29,861 token_auth WebSocket connection headers: [(b'sec-websocket-version', b'13'), (b'sec-websocket-key', b'6lMoM2RReepVVXgRnh5jlg=='), (b'connection', b'Upgrade'), (b'upgrade', b'websocket'), (b'authorization', b'Token 889e10d16483c21f9b775f9bf98ecff96f7af71c'), (b'sec-websocket-extensions', b'permessage-deflate; client_max_window_bits'), (b'host', b'127.0.0.1:8000')]
DEBUG 2025-05-27 04:23:29,863 token_auth Found authorization header: Token 889e10d16483c21f9b775f9bf98ecff96f7af71c
DEBUG 2025-05-27 04:23:29,863 token_auth Extracted token: 889e10d16483c21f9b775f9bf98ecff96f7af71c
DEBUG 2025-05-27 04:23:29,863 token_auth Authenticating with token: 889e10d16483c21f9b775f9bf98ecff96f7af71c
DEBUG 2025-05-27 04:23:29,986 utils (0.003) SELECT "authtoken_token"."key", "authtoken_token"."user_id", "authtoken_token"."created" FROM "authtoken_token" WHERE "authtoken_token"."key" = '889e10d16483c21f9b775f9bf98ecff96f7af71c' LIMIT 21; args=('889e10d16483c21f9b775f9bf98ecff96f7af71c',); alias=default
DEBUG 2025-05-27 04:23:29,988 utils (0.001) SELECT "auth_user"."id", "auth_user"."password", "auth_user"."last_login", "auth_user"."is_superuser", "auth_user"."username", "auth_user"."first_name", "auth_user"."last_name", "auth_user"."email", "auth_user"."is_staff", "auth_user"."is_active", "auth_user"."date_joined" FROM "auth_user" WHERE "auth_user"."id" = 1 LIMIT 21; args=(1,); alias=default
DEBUG 2025-05-27 04:23:29,988 token_auth Successfully authenticated user: admin
DEBUG 2025-05-27 04:23:29,988 admin_auth Admin WebSocket connection detected, bypassing authentication checks
DEBUG 2025-05-27 04:23:29,988 auth_stack Bypassing authentication checks for admin WebSocket connection
DEBUG 2025-05-27 04:25:18,059 token_auth WebSocket connection headers: [(b'sec-websocket-version', b'13'), (b'sec-websocket-key', b'439VVaw4xkR57/rtOCUacg=='), (b'connection', b'Upgrade'), (b'upgrade', b'websocket'), (b'authorization', b'Token 889e10d16483c21f9b775f9bf98ecff96f7af71c'), (b'sec-websocket-extensions', b'permessage-deflate; client_max_window_bits'), (b'host', b'127.0.0.1:8000')]
DEBUG 2025-05-27 04:25:18,079 token_auth Found authorization header: Token 889e10d16483c21f9b775f9bf98ecff96f7af71c
DEBUG 2025-05-27 04:25:18,080 token_auth Extracted token: 889e10d16483c21f9b775f9bf98ecff96f7af71c
DEBUG 2025-05-27 04:25:18,080 token_auth Authenticating with token: 889e10d16483c21f9b775f9bf98ecff96f7af71c
DEBUG 2025-05-27 04:25:18,152 utils (0.003) SELECT "authtoken_token"."key", "authtoken_token"."user_id", "authtoken_token"."created" FROM "authtoken_token" WHERE "authtoken_token"."key" = '889e10d16483c21f9b775f9bf98ecff96f7af71c' LIMIT 21; args=('889e10d16483c21f9b775f9bf98ecff96f7af71c',); alias=default
DEBUG 2025-05-27 04:25:18,154 utils (0.001) SELECT "auth_user"."id", "auth_user"."password", "auth_user"."last_login", "auth_user"."is_superuser", "auth_user"."username", "auth_user"."first_name", "auth_user"."last_name", "auth_user"."email", "auth_user"."is_staff", "auth_user"."is_active", "auth_user"."date_joined" FROM "auth_user" WHERE "auth_user"."id" = 1 LIMIT 21; args=(1,); alias=default
DEBUG 2025-05-27 04:25:18,155 token_auth Successfully authenticated user: admin
DEBUG 2025-05-27 04:25:18,155 admin_auth Admin WebSocket connection detected, bypassing authentication checks
DEBUG 2025-05-27 04:25:18,155 auth_stack Bypassing authentication checks for admin WebSocket connection
DEBUG 2025-05-27 04:26:31,052 token_auth WebSocket connection headers: [(b'sec-websocket-version', b'13'), (b'sec-websocket-key', b'Y4njlqgtx3v63/zUx1ziOQ=='), (b'connection', b'Upgrade'), (b'upgrade', b'websocket'), (b'authorization', b'Token 889e10d16483c21f9b775f9bf98ecff96f7af71c'), (b'sec-websocket-extensions', b'permessage-deflate; client_max_window_bits'), (b'host', b'127.0.0.1:8000')]
DEBUG 2025-05-27 04:26:31,052 token_auth Found authorization header: Token 889e10d16483c21f9b775f9bf98ecff96f7af71c
DEBUG 2025-05-27 04:26:31,052 token_auth Extracted token: 889e10d16483c21f9b775f9bf98ecff96f7af71c
DEBUG 2025-05-27 04:26:31,052 token_auth Authenticating with token: 889e10d16483c21f9b775f9bf98ecff96f7af71c
DEBUG 2025-05-27 04:26:31,102 utils (0.002) SELECT "authtoken_token"."key", "authtoken_token"."user_id", "authtoken_token"."created" FROM "authtoken_token" WHERE "authtoken_token"."key" = '889e10d16483c21f9b775f9bf98ecff96f7af71c' LIMIT 21; args=('889e10d16483c21f9b775f9bf98ecff96f7af71c',); alias=default
DEBUG 2025-05-27 04:26:31,103 utils (0.001) SELECT "auth_user"."id", "auth_user"."password", "auth_user"."last_login", "auth_user"."is_superuser", "auth_user"."username", "auth_user"."first_name", "auth_user"."last_name", "auth_user"."email", "auth_user"."is_staff", "auth_user"."is_active", "auth_user"."date_joined" FROM "auth_user" WHERE "auth_user"."id" = 1 LIMIT 21; args=(1,); alias=default
DEBUG 2025-05-27 04:26:31,104 token_auth Successfully authenticated user: admin
DEBUG 2025-05-27 04:26:31,104 admin_auth Admin WebSocket connection detected, bypassing authentication checks
DEBUG 2025-05-27 04:26:31,104 auth_stack Bypassing authentication checks for admin WebSocket connection
DEBUG 2025-05-27 04:28:42,631 token_auth WebSocket connection headers: [(b'sec-websocket-version', b'13'), (b'sec-websocket-key', b'bifsg1cfRBRwdVR6zqU4RQ=='), (b'connection', b'Upgrade'), (b'upgrade', b'websocket'), (b'authorization', b'Token 889e10d16483c21f9b775f9bf98ecff96f7af71c'), (b'sec-websocket-extensions', b'permessage-deflate; client_max_window_bits'), (b'host', b'127.0.0.1:8000')]
DEBUG 2025-05-27 04:28:42,634 token_auth Found authorization header: Token 889e10d16483c21f9b775f9bf98ecff96f7af71c
DEBUG 2025-05-27 04:28:42,635 token_auth Extracted token: 889e10d16483c21f9b775f9bf98ecff96f7af71c
DEBUG 2025-05-27 04:28:42,636 token_auth Authenticating with token: 889e10d16483c21f9b775f9bf98ecff96f7af71c
DEBUG 2025-05-27 04:28:42,700 utils (0.002) SELECT "authtoken_token"."key", "authtoken_token"."user_id", "authtoken_token"."created" FROM "authtoken_token" WHERE "authtoken_token"."key" = '889e10d16483c21f9b775f9bf98ecff96f7af71c' LIMIT 21; args=('889e10d16483c21f9b775f9bf98ecff96f7af71c',); alias=default
DEBUG 2025-05-27 04:28:42,702 utils (0.001) SELECT "auth_user"."id", "auth_user"."password", "auth_user"."last_login", "auth_user"."is_superuser", "auth_user"."username", "auth_user"."first_name", "auth_user"."last_name", "auth_user"."email", "auth_user"."is_staff", "auth_user"."is_active", "auth_user"."date_joined" FROM "auth_user" WHERE "auth_user"."id" = 1 LIMIT 21; args=(1,); alias=default
DEBUG 2025-05-27 04:28:42,703 token_auth Successfully authenticated user: admin
DEBUG 2025-05-27 04:28:42,703 admin_auth Admin WebSocket connection detected, bypassing authentication checks
DEBUG 2025-05-27 04:28:42,703 auth_stack Bypassing authentication checks for admin WebSocket connection
DEBUG 2025-05-27 04:31:02,719 token_auth WebSocket connection headers: [(b'sec-websocket-version', b'13'), (b'sec-websocket-key', b'595Soa/6L54+MQ07FYP9MQ=='), (b'connection', b'Upgrade'), (b'upgrade', b'websocket'), (b'authorization', b'Token 889e10d16483c21f9b775f9bf98ecff96f7af71c'), (b'sec-websocket-extensions', b'permessage-deflate; client_max_window_bits'), (b'host', b'127.0.0.1:8000')]
DEBUG 2025-05-27 04:31:02,719 token_auth Found authorization header: Token 889e10d16483c21f9b775f9bf98ecff96f7af71c
DEBUG 2025-05-27 04:31:02,720 token_auth Extracted token: 889e10d16483c21f9b775f9bf98ecff96f7af71c
DEBUG 2025-05-27 04:31:02,720 token_auth Authenticating with token: 889e10d16483c21f9b775f9bf98ecff96f7af71c
DEBUG 2025-05-27 04:31:02,778 utils (0.002) SELECT "authtoken_token"."key", "authtoken_token"."user_id", "authtoken_token"."created" FROM "authtoken_token" WHERE "authtoken_token"."key" = '889e10d16483c21f9b775f9bf98ecff96f7af71c' LIMIT 21; args=('889e10d16483c21f9b775f9bf98ecff96f7af71c',); alias=default
DEBUG 2025-05-27 04:31:02,779 utils (0.001) SELECT "auth_user"."id", "auth_user"."password", "auth_user"."last_login", "auth_user"."is_superuser", "auth_user"."username", "auth_user"."first_name", "auth_user"."last_name", "auth_user"."email", "auth_user"."is_staff", "auth_user"."is_active", "auth_user"."date_joined" FROM "auth_user" WHERE "auth_user"."id" = 1 LIMIT 21; args=(1,); alias=default
DEBUG 2025-05-27 04:31:02,780 token_auth Successfully authenticated user: admin
DEBUG 2025-05-27 04:31:02,780 admin_auth Admin WebSocket connection detected, bypassing authentication checks
DEBUG 2025-05-27 04:31:02,780 auth_stack Bypassing authentication checks for admin WebSocket connection
DEBUG 2025-05-27 04:35:11,644 token_auth WebSocket connection headers: [(b'sec-websocket-version', b'13'), (b'sec-websocket-key', b'r3gIQAS5WNOW1w42hzAVwg=='), (b'connection', b'Upgrade'), (b'upgrade', b'websocket'), (b'authorization', b'Token 889e10d16483c21f9b775f9bf98ecff96f7af71c'), (b'sec-websocket-extensions', b'permessage-deflate; client_max_window_bits'), (b'host', b'127.0.0.1:8000')]
DEBUG 2025-05-27 04:35:11,645 token_auth Found authorization header: Token 889e10d16483c21f9b775f9bf98ecff96f7af71c
DEBUG 2025-05-27 04:35:11,645 token_auth Extracted token: 889e10d16483c21f9b775f9bf98ecff96f7af71c
DEBUG 2025-05-27 04:35:11,645 token_auth Authenticating with token: 889e10d16483c21f9b775f9bf98ecff96f7af71c
DEBUG 2025-05-27 04:35:11,688 utils (0.002) SELECT "authtoken_token"."key", "authtoken_token"."user_id", "authtoken_token"."created" FROM "authtoken_token" WHERE "authtoken_token"."key" = '889e10d16483c21f9b775f9bf98ecff96f7af71c' LIMIT 21; args=('889e10d16483c21f9b775f9bf98ecff96f7af71c',); alias=default
DEBUG 2025-05-27 04:35:11,690 utils (0.001) SELECT "auth_user"."id", "auth_user"."password", "auth_user"."last_login", "auth_user"."is_superuser", "auth_user"."username", "auth_user"."first_name", "auth_user"."last_name", "auth_user"."email", "auth_user"."is_staff", "auth_user"."is_active", "auth_user"."date_joined" FROM "auth_user" WHERE "auth_user"."id" = 1 LIMIT 21; args=(1,); alias=default
DEBUG 2025-05-27 04:35:11,691 token_auth Successfully authenticated user: admin
DEBUG 2025-05-27 04:35:11,691 admin_auth Admin WebSocket connection detected, bypassing authentication checks
DEBUG 2025-05-27 04:35:11,691 auth_stack Bypassing authentication checks for admin WebSocket connection
DEBUG 2025-05-27 04:35:23,012 token_auth WebSocket connection headers: [(b'sec-websocket-version', b'13'), (b'sec-websocket-key', b'G7NUrgSYKbg9zy+LqGq9yw=='), (b'connection', b'Upgrade'), (b'upgrade', b'websocket'), (b'authorization', b'Token 889e10d16483c21f9b775f9bf98ecff96f7af71c'), (b'sec-websocket-extensions', b'permessage-deflate; client_max_window_bits'), (b'host', b'127.0.0.1:8000')]
DEBUG 2025-05-27 04:35:23,013 token_auth Found authorization header: Token 889e10d16483c21f9b775f9bf98ecff96f7af71c
DEBUG 2025-05-27 04:35:23,013 token_auth Extracted token: 889e10d16483c21f9b775f9bf98ecff96f7af71c
DEBUG 2025-05-27 04:35:23,014 token_auth Authenticating with token: 889e10d16483c21f9b775f9bf98ecff96f7af71c
DEBUG 2025-05-27 04:35:23,064 utils (0.001) SELECT "authtoken_token"."key", "authtoken_token"."user_id", "authtoken_token"."created" FROM "authtoken_token" WHERE "authtoken_token"."key" = '889e10d16483c21f9b775f9bf98ecff96f7af71c' LIMIT 21; args=('889e10d16483c21f9b775f9bf98ecff96f7af71c',); alias=default
DEBUG 2025-05-27 04:35:23,065 utils (0.000) SELECT "auth_user"."id", "auth_user"."password", "auth_user"."last_login", "auth_user"."is_superuser", "auth_user"."username", "auth_user"."first_name", "auth_user"."last_name", "auth_user"."email", "auth_user"."is_staff", "auth_user"."is_active", "auth_user"."date_joined" FROM "auth_user" WHERE "auth_user"."id" = 1 LIMIT 21; args=(1,); alias=default
DEBUG 2025-05-27 04:35:23,066 token_auth Successfully authenticated user: admin
DEBUG 2025-05-27 04:35:23,066 admin_auth Admin WebSocket connection detected, bypassing authentication checks
DEBUG 2025-05-27 04:35:23,066 auth_stack Bypassing authentication checks for admin WebSocket connection
DEBUG 2025-05-27 04:38:49,233 token_auth WebSocket connection headers: [(b'sec-websocket-version', b'13'), (b'sec-websocket-key', b'DLQaril7bMzOMYB/ii1paQ=='), (b'connection', b'Upgrade'), (b'upgrade', b'websocket'), (b'authorization', b'Token 889e10d16483c21f9b775f9bf98ecff96f7af71c'), (b'sec-websocket-extensions', b'permessage-deflate; client_max_window_bits'), (b'host', b'127.0.0.1:8000')]
DEBUG 2025-05-27 04:38:49,235 token_auth Found authorization header: Token 889e10d16483c21f9b775f9bf98ecff96f7af71c
DEBUG 2025-05-27 04:38:49,236 token_auth Extracted token: 889e10d16483c21f9b775f9bf98ecff96f7af71c
DEBUG 2025-05-27 04:38:49,236 token_auth Authenticating with token: 889e10d16483c21f9b775f9bf98ecff96f7af71c
DEBUG 2025-05-27 04:38:49,295 utils (0.002) SELECT "authtoken_token"."key", "authtoken_token"."user_id", "authtoken_token"."created" FROM "authtoken_token" WHERE "authtoken_token"."key" = '889e10d16483c21f9b775f9bf98ecff96f7af71c' LIMIT 21; args=('889e10d16483c21f9b775f9bf98ecff96f7af71c',); alias=default
DEBUG 2025-05-27 04:38:49,297 utils (0.001) SELECT "auth_user"."id", "auth_user"."password", "auth_user"."last_login", "auth_user"."is_superuser", "auth_user"."username", "auth_user"."first_name", "auth_user"."last_name", "auth_user"."email", "auth_user"."is_staff", "auth_user"."is_active", "auth_user"."date_joined" FROM "auth_user" WHERE "auth_user"."id" = 1 LIMIT 21; args=(1,); alias=default
DEBUG 2025-05-27 04:38:49,298 token_auth Successfully authenticated user: admin
DEBUG 2025-05-27 04:38:49,298 admin_auth Admin WebSocket connection detected, bypassing authentication checks
DEBUG 2025-05-27 04:38:49,298 auth_stack Bypassing authentication checks for admin WebSocket connection
DEBUG 2025-05-27 04:38:55,617 token_auth WebSocket connection headers: [(b'sec-websocket-version', b'13'), (b'sec-websocket-key', b'8xIyhgHIAsP00bybNAGjUQ=='), (b'connection', b'Upgrade'), (b'upgrade', b'websocket'), (b'cookie', b''), (b'sec-websocket-extensions', b'permessage-deflate; client_max_window_bits'), (b'host', b'127.0.0.1:8000')]
DEBUG 2025-05-27 04:38:55,618 token_auth No token found, setting user as AnonymousUser
