ERROR 2025-05-19 16:38:21,826 log Internal Server Error: /api/v1/registration/
Traceback (most recent call last):
  File "/Users/sergeizeliabovskii/Documents/python_ptojects/DjangoProject/.venv/lib/python3.13/site-packages/django/db/backends/utils.py", line 103, in _execute
    return self.cursor.execute(sql)
           ~~~~~~~~~~~~~~~~~~~^^^^^
psycopg2.errors.NoActiveSqlTransaction: SAVEPOINT can only be used in transaction blocks


The above exception was the direct cause of the following exception:

Traceback (most recent call last):
  File "/Users/sergeizeliabovskii/Documents/python_ptojects/DjangoProject/.venv/lib/python3.13/site-packages/django/core/handlers/exception.py", line 55, in inner
    response = get_response(request)
  File "/Users/sergeizeliabovskii/Documents/python_ptojects/DjangoProject/.venv/lib/python3.13/site-packages/django/core/handlers/base.py", line 197, in _get_response
    response = wrapped_callback(request, *callback_args, **callback_kwargs)
  File "/Users/sergeizeliabovskii/Documents/python_ptojects/DjangoProject/.venv/lib/python3.13/site-packages/django/views/decorators/csrf.py", line 65, in _view_wrapper
    return view_func(request, *args, **kwargs)
  File "/Users/sergeizeliabovskii/Documents/python_ptojects/DjangoProject/.venv/lib/python3.13/site-packages/django/views/generic/base.py", line 104, in view
    return self.dispatch(request, *args, **kwargs)
           ~~~~~~~~~~~~~^^^^^^^^^^^^^^^^^^^^^^^^^^
  File "/Users/sergeizeliabovskii/Documents/python_ptojects/DjangoProject/.venv/lib/python3.13/site-packages/rest_framework/views.py", line 515, in dispatch
    response = self.handle_exception(exc)
  File "/Users/sergeizeliabovskii/Documents/python_ptojects/DjangoProject/.venv/lib/python3.13/site-packages/rest_framework/views.py", line 475, in handle_exception
    self.raise_uncaught_exception(exc)
    ~~~~~~~~~~~~~~~~~~~~~~~~~~~~~^^^^^
  File "/Users/sergeizeliabovskii/Documents/python_ptojects/DjangoProject/.venv/lib/python3.13/site-packages/rest_framework/views.py", line 486, in raise_uncaught_exception
    raise exc
  File "/Users/sergeizeliabovskii/Documents/python_ptojects/DjangoProject/.venv/lib/python3.13/site-packages/rest_framework/views.py", line 512, in dispatch
    response = handler(request, *args, **kwargs)
  File "/Users/sergeizeliabovskii/Documents/python_ptojects/DjangoProject/.venv/lib/python3.13/site-packages/rest_framework/decorators.py", line 50, in handler
    return func(*args, **kwargs)
  File "/Library/Frameworks/Python.framework/Versions/3.13/lib/python3.13/contextlib.py", line 84, in inner
    with self._recreate_cm():
         ~~~~~~~~~~~~~~~~~^^
  File "/Users/sergeizeliabovskii/Documents/python_ptojects/DjangoProject/.venv/lib/python3.13/site-packages/django/db/transaction.py", line 211, in __enter__
    sid = connection.savepoint()
  File "/Users/sergeizeliabovskii/Documents/python_ptojects/DjangoProject/.venv/lib/python3.13/site-packages/django/utils/asyncio.py", line 26, in inner
    return func(*args, **kwargs)
  File "/Users/sergeizeliabovskii/Documents/python_ptojects/DjangoProject/.venv/lib/python3.13/site-packages/django/db/backends/base/base.py", line 400, in savepoint
    self._savepoint(sid)
    ~~~~~~~~~~~~~~~^^^^^
  File "/Users/sergeizeliabovskii/Documents/python_ptojects/DjangoProject/.venv/lib/python3.13/site-packages/django/db/backends/base/base.py", line 367, in _savepoint
    cursor.execute(self.ops.savepoint_create_sql(sid))
    ~~~~~~~~~~~~~~^^^^^^^^^^^^^^^^^^^^^^^^^^^^^^^^^^^^
  File "/Users/sergeizeliabovskii/Documents/python_ptojects/DjangoProject/.venv/lib/python3.13/site-packages/django/db/backends/utils.py", line 79, in execute
    return self._execute_with_wrappers(
           ~~~~~~~~~~~~~~~~~~~~~~~~~~~^
        sql, params, many=False, executor=self._execute
        ^^^^^^^^^^^^^^^^^^^^^^^^^^^^^^^^^^^^^^^^^^^^^^^
    )
    ^
  File "/Users/sergeizeliabovskii/Documents/python_ptojects/DjangoProject/.venv/lib/python3.13/site-packages/django/db/backends/utils.py", line 92, in _execute_with_wrappers
    return executor(sql, params, many, context)
  File "/Users/sergeizeliabovskii/Documents/python_ptojects/DjangoProject/.venv/lib/python3.13/site-packages/django/db/backends/utils.py", line 100, in _execute
    with self.db.wrap_database_errors:
         ^^^^^^^^^^^^^^^^^^^^^^^^^^^^
  File "/Users/sergeizeliabovskii/Documents/python_ptojects/DjangoProject/.venv/lib/python3.13/site-packages/django/db/utils.py", line 91, in __exit__
    raise dj_exc_value.with_traceback(traceback) from exc_value
  File "/Users/sergeizeliabovskii/Documents/python_ptojects/DjangoProject/.venv/lib/python3.13/site-packages/django/db/backends/utils.py", line 103, in _execute
    return self.cursor.execute(sql)
           ~~~~~~~~~~~~~~~~~~~^^^^^
django.db.utils.InternalError: SAVEPOINT can only be used in transaction blocks

ERROR 2025-05-19 16:38:22,193 log Internal Server Error: /api/v1/registration/
Traceback (most recent call last):
  File "/Users/sergeizeliabovskii/Documents/python_ptojects/DjangoProject/.venv/lib/python3.13/site-packages/django/db/backends/utils.py", line 103, in _execute
    return self.cursor.execute(sql)
           ~~~~~~~~~~~~~~~~~~~^^^^^
psycopg2.errors.NoActiveSqlTransaction: SAVEPOINT can only be used in transaction blocks


The above exception was the direct cause of the following exception:

Traceback (most recent call last):
  File "/Users/sergeizeliabovskii/Documents/python_ptojects/DjangoProject/.venv/lib/python3.13/site-packages/django/core/handlers/exception.py", line 55, in inner
    response = get_response(request)
  File "/Users/sergeizeliabovskii/Documents/python_ptojects/DjangoProject/.venv/lib/python3.13/site-packages/django/core/handlers/base.py", line 197, in _get_response
    response = wrapped_callback(request, *callback_args, **callback_kwargs)
  File "/Users/sergeizeliabovskii/Documents/python_ptojects/DjangoProject/.venv/lib/python3.13/site-packages/django/views/decorators/csrf.py", line 65, in _view_wrapper
    return view_func(request, *args, **kwargs)
  File "/Users/sergeizeliabovskii/Documents/python_ptojects/DjangoProject/.venv/lib/python3.13/site-packages/django/views/generic/base.py", line 104, in view
    return self.dispatch(request, *args, **kwargs)
           ~~~~~~~~~~~~~^^^^^^^^^^^^^^^^^^^^^^^^^^
  File "/Users/sergeizeliabovskii/Documents/python_ptojects/DjangoProject/.venv/lib/python3.13/site-packages/rest_framework/views.py", line 515, in dispatch
    response = self.handle_exception(exc)
  File "/Users/sergeizeliabovskii/Documents/python_ptojects/DjangoProject/.venv/lib/python3.13/site-packages/rest_framework/views.py", line 475, in handle_exception
    self.raise_uncaught_exception(exc)
    ~~~~~~~~~~~~~~~~~~~~~~~~~~~~~^^^^^
  File "/Users/sergeizeliabovskii/Documents/python_ptojects/DjangoProject/.venv/lib/python3.13/site-packages/rest_framework/views.py", line 486, in raise_uncaught_exception
    raise exc
  File "/Users/sergeizeliabovskii/Documents/python_ptojects/DjangoProject/.venv/lib/python3.13/site-packages/rest_framework/views.py", line 512, in dispatch
    response = handler(request, *args, **kwargs)
  File "/Users/sergeizeliabovskii/Documents/python_ptojects/DjangoProject/.venv/lib/python3.13/site-packages/rest_framework/decorators.py", line 50, in handler
    return func(*args, **kwargs)
  File "/Library/Frameworks/Python.framework/Versions/3.13/lib/python3.13/contextlib.py", line 84, in inner
    with self._recreate_cm():
         ~~~~~~~~~~~~~~~~~^^
  File "/Users/sergeizeliabovskii/Documents/python_ptojects/DjangoProject/.venv/lib/python3.13/site-packages/django/db/transaction.py", line 211, in __enter__
    sid = connection.savepoint()
  File "/Users/sergeizeliabovskii/Documents/python_ptojects/DjangoProject/.venv/lib/python3.13/site-packages/django/utils/asyncio.py", line 26, in inner
    return func(*args, **kwargs)
  File "/Users/sergeizeliabovskii/Documents/python_ptojects/DjangoProject/.venv/lib/python3.13/site-packages/django/db/backends/base/base.py", line 400, in savepoint
    self._savepoint(sid)
    ~~~~~~~~~~~~~~~^^^^^
  File "/Users/sergeizeliabovskii/Documents/python_ptojects/DjangoProject/.venv/lib/python3.13/site-packages/django/db/backends/base/base.py", line 367, in _savepoint
    cursor.execute(self.ops.savepoint_create_sql(sid))
    ~~~~~~~~~~~~~~^^^^^^^^^^^^^^^^^^^^^^^^^^^^^^^^^^^^
  File "/Users/sergeizeliabovskii/Documents/python_ptojects/DjangoProject/.venv/lib/python3.13/site-packages/django/db/backends/utils.py", line 79, in execute
    return self._execute_with_wrappers(
           ~~~~~~~~~~~~~~~~~~~~~~~~~~~^
        sql, params, many=False, executor=self._execute
        ^^^^^^^^^^^^^^^^^^^^^^^^^^^^^^^^^^^^^^^^^^^^^^^
    )
    ^
  File "/Users/sergeizeliabovskii/Documents/python_ptojects/DjangoProject/.venv/lib/python3.13/site-packages/django/db/backends/utils.py", line 92, in _execute_with_wrappers
    return executor(sql, params, many, context)
  File "/Users/sergeizeliabovskii/Documents/python_ptojects/DjangoProject/.venv/lib/python3.13/site-packages/django/db/backends/utils.py", line 100, in _execute
    with self.db.wrap_database_errors:
         ^^^^^^^^^^^^^^^^^^^^^^^^^^^^
  File "/Users/sergeizeliabovskii/Documents/python_ptojects/DjangoProject/.venv/lib/python3.13/site-packages/django/db/utils.py", line 91, in __exit__
    raise dj_exc_value.with_traceback(traceback) from exc_value
  File "/Users/sergeizeliabovskii/Documents/python_ptojects/DjangoProject/.venv/lib/python3.13/site-packages/django/db/backends/utils.py", line 103, in _execute
    return self.cursor.execute(sql)
           ~~~~~~~~~~~~~~~~~~~^^^^^
django.db.utils.InternalError: SAVEPOINT can only be used in transaction blocks

ERROR 2025-05-19 17:17:27,917 log Internal Server Error: /api/v1/edit_userinfo/1/
Traceback (most recent call last):
  File "/Users/sergeizeliabovskii/Documents/python_ptojects/DjangoProject/.venv/lib/python3.13/site-packages/django/core/handlers/exception.py", line 55, in inner
    response = get_response(request)
  File "/Users/sergeizeliabovskii/Documents/python_ptojects/DjangoProject/.venv/lib/python3.13/site-packages/django/core/handlers/base.py", line 197, in _get_response
    response = wrapped_callback(request, *callback_args, **callback_kwargs)
  File "/Users/sergeizeliabovskii/Documents/python_ptojects/DjangoProject/.venv/lib/python3.13/site-packages/django/views/decorators/csrf.py", line 65, in _view_wrapper
    return view_func(request, *args, **kwargs)
  File "/Users/sergeizeliabovskii/Documents/python_ptojects/DjangoProject/.venv/lib/python3.13/site-packages/django/views/generic/base.py", line 104, in view
    return self.dispatch(request, *args, **kwargs)
           ~~~~~~~~~~~~~^^^^^^^^^^^^^^^^^^^^^^^^^^
  File "/Users/sergeizeliabovskii/Documents/python_ptojects/DjangoProject/.venv/lib/python3.13/site-packages/rest_framework/views.py", line 515, in dispatch
    response = self.handle_exception(exc)
  File "/Users/sergeizeliabovskii/Documents/python_ptojects/DjangoProject/.venv/lib/python3.13/site-packages/rest_framework/views.py", line 475, in handle_exception
    self.raise_uncaught_exception(exc)
    ~~~~~~~~~~~~~~~~~~~~~~~~~~~~~^^^^^
  File "/Users/sergeizeliabovskii/Documents/python_ptojects/DjangoProject/.venv/lib/python3.13/site-packages/rest_framework/views.py", line 486, in raise_uncaught_exception
    raise exc
  File "/Users/sergeizeliabovskii/Documents/python_ptojects/DjangoProject/.venv/lib/python3.13/site-packages/rest_framework/views.py", line 512, in dispatch
    response = handler(request, *args, **kwargs)
  File "/Users/sergeizeliabovskii/Documents/python_ptojects/DjangoProject/.venv/lib/python3.13/site-packages/rest_framework/decorators.py", line 50, in handler
    return func(*args, **kwargs)
  File "/Library/Frameworks/Python.framework/Versions/3.13/lib/python3.13/contextlib.py", line 85, in inner
    return func(*args, **kwds)
TypeError: edit_userinfo() got an unexpected keyword argument 'user_id'
ERROR 2025-05-20 17:24:20,253 log Internal Server Error: /api/v1/login
Traceback (most recent call last):
  File "/Users/sergeizeliabovskii/Documents/python_ptojects/DjangoProject/.venv/lib/python3.13/site-packages/django/core/handlers/exception.py", line 55, in inner
    response = get_response(request)
  File "/Users/sergeizeliabovskii/Documents/python_ptojects/DjangoProject/.venv/lib/python3.13/site-packages/django/utils/deprecation.py", line 122, in __call__
    response = self.process_response(request, response)
  File "/Users/sergeizeliabovskii/Documents/python_ptojects/DjangoProject/.venv/lib/python3.13/site-packages/django/middleware/common.py", line 108, in process_response
    return self.response_redirect_class(self.get_full_path_with_slash(request))
                                        ~~~~~~~~~~~~~~~~~~~~~~~~~~~~~^^^^^^^^^
  File "/Users/sergeizeliabovskii/Documents/python_ptojects/DjangoProject/.venv/lib/python3.13/site-packages/django/middleware/common.py", line 87, in get_full_path_with_slash
    raise RuntimeError(
    ...<9 lines>...
    )
RuntimeError: You called this URL via POST, but the URL doesn't end in a slash and you have APPEND_SLASH set. Django can't redirect to the slash URL while maintaining POST data. Change your form to point to 127.0.0.1:8000/api/v1/login/ (note the trailing slash), or set APPEND_SLASH=False in your Django settings.
ERROR 2025-05-20 17:24:20,258 basehttp "POST /api/v1/login HTTP/1.1" 500 65622
